Workbook

Sheet 헤몬팜
A1: . | R1: 192
C2: 9/29~9/30 | D2: 이윤율 | E2: 마진율 | F2: 광고비율 | G2: 전환율 | H2: 판매수 | I2: 일판매 | J2: 순판매개수 | K2: 취소개수 | L2: 가구매 | M2: 매출 | N2: 가구매금액 | O2: 순매출 | P2: 판매가 | Q2: 입고가 | R2: 입고판매가 | S2: 광고비1.1 | T2: 광고비 | U2: 가구매비용 | V2: 반품회수비 | W2: 수수료 | X2: 택배비 | Y2: 판매수수료 | Z2: 수수료 | AA2: 부가세 | AB2: 판매마진 | AC2: 순이익 | AD2: 노출수 | AE2: 클릭수
C3: 쉐이버 | D3: =AC3/O3 -> 0.18064455 | E3: =AB3/O3 -> 0.42342161 | F3: =(S3+U3)/O3 -> 0.24277706 | G3: =H3/AG3 -> #DIV/0! | H3: =SUMIF(헤몬팜일일!$C$1:$C$40,$C3,헤몬팜일일!O$1:O$40) -> 282 | I3: =H3/7 -> 40.285714 | J3: =SUMIF(헤몬팜일일!$C$1:$C$40,$C3,헤몬팜일일!P$1:P$40) -> 282 | K3: =SUMIF(헤몬팜일일!$C$1:$C$40,$C3,헤몬팜일일!Q$1:Q$40) -> 27 | L3: =SUMIF(헤몬팜일일!$C$1:$C$40,$C3,헤몬팜일일!S$1:S$40) -> 0 | M3: =SUMIF(헤몬팜일일!$C$1:$C$40,$C3,헤몬팜일일!T$1:T$40) -> 7882000 | N3: =SUMIF(헤몬팜일일!$C$1:$C$40,$C3,헤몬팜일일!U$1:U$40) -> 0 | O3: =SUMIF(헤몬팜일일!$C$1:$C$40,$C3,헤몬팜일일!V$1:V$40) -> 7882000 | P3: =O3/J3 -> 27950.355 | Q3: =SUMIF(헤몬팜일일!$C$1:$C$40,$C3,헤몬팜일일!X$1:X$40) -> 17701.72 | R3: =SUMIF(헤몬팜일일!$C$1:$C$40,$C3,헤몬팜일일!Y$1:Y$40) -> 2607107.4 | S3: =SUMIF(헤몬팜일일!$C$1:$C$40,$C3,헤몬팜일일!Z$1:Z$40) -> 1913568.8 | T3: =SUMIF(헤몬팜일일!$C$1:$C$40,$C3,헤몬팜일일!AA$1:AA$40) -> 1739608 | U3: =SUMIF(헤몬팜일일!$C$1:$C$40,$C3,헤몬팜일일!AB$1:AB$40) -> 0 | V3: =SUMIF(헤몬팜일일!$C$1:$C$40,$C3,헤몬팜일일!AC$1:AC$40) -> 58644 | W3: 0.1 | X3: =SUMIF(헤몬팜일일!$C$1:$C$40,$C3,헤몬팜일일!AE$1:AE$40) -> 860100 | Y3: =W3+(X3/O3) -> 0.20912205 | Z3: =SUMIF(헤몬팜일일!$C$1:$C$40,$C3,헤몬팜일일!AG$1:AG$40) -> 1648300.1 | AA3: =SUMIF(헤몬팜일일!$C$1:$C$40,$C3,헤몬팜일일!AH$1:AH$40) -> 289183.44 | AB3: =SUMIF(헤몬팜일일!$C$1:$C$40,$C3,헤몬팜일일!AJ$1:AK$40) -> 3337409.1 | AC3: =SUMIF(헤몬팜일일!$C$1:$C$40,$C3,헤몬팜일일!AK$1:AK$40) -> 1423840.3 | AD3: =SUMIF(헤몬팜일일!$C$1:$C$40,$C3,헤몬팜일일!AK$1:AK$40) -> 1423840.3 | AE3: =SUMIF(헤몬팜일일!$C$1:$C$40,$C3,헤몬팜일일!AL$1:AL$40) -> 129.168
C4: 일자면도기 | D4: =AC4/O4 -> -0.019440465 | E4: =AB4/O4 -> 0.40985028 | F4: =(S4+U4)/O4 -> 0.42929075 | G4: =H4/AG4 -> #DIV/0! | H4: =SUMIF(헤몬팜일일!$C$1:$C$40,$C4,헤몬팜일일!O$1:O$40) -> 1 | I4: =H4/7 -> 0.14285714 | J4: =SUMIF(헤몬팜일일!$C$1:$C$40,$C4,헤몬팜일일!P$1:P$40) -> 1 | K4: =SUMIF(헤몬팜일일!$C$1:$C$40,$C4,헤몬팜일일!Q$1:Q$40) -> 0 | L4: =SUMIF(헤몬팜일일!$C$1:$C$40,$C4,헤몬팜일일!S$1:S$40) -> 0 | M4: =SUMIF(헤몬팜일일!$C$1:$C$40,$C4,헤몬팜일일!T$1:T$40) -> 22700 | N4: =SUMIF(헤몬팜일일!$C$1:$C$40,$C4,헤몬팜일일!U$1:U$40) -> 0 | O4: =SUMIF(헤몬팜일일!$C$1:$C$40,$C4,헤몬팜일일!V$1:V$40) -> 22700 | P4: =O4/J4 -> 22700 | Q4: =SUMIF(헤몬팜일일!$C$1:$C$40,$C4,헤몬팜일일!X$1:X$40) -> 14161.376 | R4: =SUMIF(헤몬팜일일!$C$1:$C$40,$C4,헤몬팜일일!Y$1:Y$40) -> 7377.328 | S4: =SUMIF(헤몬팜일일!$C$1:$C$40,$C4,헤몬팜일일!Z$1:Z$40) -> 9744.9 | T4: =SUMIF(헤몬팜일일!$C$1:$C$40,$C4,헤몬팜일일!AA$1:AA$40) -> 8859 | U4: =SUMIF(헤몬팜일일!$C$1:$C$40,$C4,헤몬팜일일!AB$1:AB$40) -> 0 | V4: =SUMIF(헤몬팜일일!$C$1:$C$40,$C4,헤몬팜일일!AC$1:AC$40) -> 0 | W4: 0.1 | X4: =SUMIF(헤몬팜일일!$C$1:$C$40,$C4,헤몬팜일일!AE$1:AE$40) -> 2950 | Y4: =W4+(X4/O4) -> 0.22995595 | Z4: =SUMIF(헤몬팜일일!$C$1:$C$40,$C4,헤몬팜일일!AG$1:AG$40) -> 5220.03 | AA4: =SUMIF(헤몬팜일일!$C$1:$C$40,$C4,헤몬팜일일!AH$1:AH$40) -> 799.04056 | AB4: =SUMIF(헤몬팜일일!$C$1:$C$40,$C4,헤몬팜일일!AJ$1:AK$40) -> 9303.6014 | AC4: =SUMIF(헤몬팜일일!$C$1:$C$40,$C4,헤몬팜일일!AK$1:AK$40) -> -441.29856 | AD4: =SUMIF(헤몬팜일일!$C$1:$C$40,$C4,헤몬팜일일!AK$1:AK$40) -> -441.29856 | AE4: =SUMIF(헤몬팜일일!$C$1:$C$40,$C4,헤몬팜일일!AL$1:AL$40) -> 97.2
C5: 프라임 1개 | D5: =AC5/O5 -> #REF! | E5: =AB5/O5 -> #REF! | F5: =(S5+U5)/O5 -> 0.16581059 | G5: =H5/AG5 -> #DIV/0! | H5: =SUMIF(헤몬팜일일!$C$1:$C$40,$C5,헤몬팜일일!O$1:O$40) -> 4 | I5: =H5/7 -> 0.57142857 | J5: =SUMIF(헤몬팜일일!$C$1:$C$40,$C5,헤몬팜일일!P$1:P$40) -> 4 | K5: =SUMIF(헤몬팜일일!$C$1:$C$40,$C5,헤몬팜일일!Q$1:Q$40) -> 1 | L5: =SUMIF(헤몬팜일일!$C$1:$C$40,$C5,헤몬팜일일!S$1:S$40) -> 0 | M5: =SUMIF(헤몬팜일일!$C$1:$C$40,$C5,헤몬팜일일!T$1:T$40) -> 183200 | N5: =SUMIF(헤몬팜일일!$C$1:$C$40,$C5,헤몬팜일일!U$1:U$40) -> 0 | O5: =SUMIF(헤몬팜일일!$C$1:$C$40,$C5,헤몬팜일일!V$1:V$40) -> 183200 | P5: =O5/J5 -> 45800 | Q5: =SUMIF(헤몬팜일일!$C$1:$C$40,$C5,헤몬팜일일!X$1:X$40) -> 19980.816 | R5: =SUMIF(헤몬팜일일!$C$1:$C$40,$C5,헤몬팜일일!Y$1:Y$40) -> #REF! | S5: =SUMIF(헤몬팜일일!$C$1:$C$40,$C5,헤몬팜일일!Z$1:Z$40) -> 30376.5 | T5: =SUMIF(헤몬팜일일!$C$1:$C$40,$C5,헤몬팜일일!AA$1:AA$40) -> 27615 | U5: =SUMIF(헤몬팜일일!$C$1:$C$40,$C5,헤몬팜일일!AB$1:AB$40) -> 0 | V5: =SUMIF(헤몬팜일일!$C$1:$C$40,$C5,헤몬팜일일!AC$1:AC$40) -> 2310 | W5: 0.1 | X5: =SUMIF(헤몬팜일일!$C$1:$C$40,$C5,헤몬팜일일!AE$1:AE$40) -> 16600 | Y5: =W5+(X5/O5) -> 0.19061135 | Z5: =SUMIF(헤몬팜일일!$C$1:$C$40,$C5,헤몬팜일일!AG$1:AG$40) -> 36752.06 | AA5: =SUMIF(헤몬팜일일!$C$1:$C$40,$C5,헤몬팜일일!AH$1:AH$40) -> #REF! | AB5: =SUMIF(헤몬팜일일!$C$1:$C$40,$C5,헤몬팜일일!AJ$1:AK$40) -> #REF! | AC5: =SUMIF(헤몬팜일일!$C$1:$C$40,$C5,헤몬팜일일!AK$1:AK$40) -> #REF! | AD5: =SUMIF(헤몬팜일일!$C$1:$C$40,$C5,헤몬팜일일!AK$1:AK$40) -> #REF! | AE5: =SUMIF(헤몬팜일일!$C$1:$C$40,$C5,헤몬팜일일!AL$1:AL$40) -> 324
C6: 프라임 2개 | D6: =AC6/O6 -> #REF! | E6: =AB6/O6 -> #REF! | F6: =(S6+U6)/O6 -> 0.43974145 | G6: =H6/AG6 -> #DIV/0! | H6: =SUMIF(헤몬팜일일!$C$1:$C$40,$C6,헤몬팜일일!O$1:O$40) -> 10 | I6: =H6/7 -> 1.4285714 | J6: =SUMIF(헤몬팜일일!$C$1:$C$40,$C6,헤몬팜일일!P$1:P$40) -> 10 | K6: =SUMIF(헤몬팜일일!$C$1:$C$40,$C6,헤몬팜일일!Q$1:Q$40) -> 3 | L6: =SUMIF(헤몬팜일일!$C$1:$C$40,$C6,헤몬팜일일!S$1:S$40) -> 0 | M6: =SUMIF(헤몬팜일일!$C$1:$C$40,$C6,헤몬팜일일!T$1:T$40) -> 468000 | N6: =SUMIF(헤몬팜일일!$C$1:$C$40,$C6,헤몬팜일일!U$1:U$40) -> 0 | O6: =SUMIF(헤몬팜일일!$C$1:$C$40,$C6,헤몬팜일일!V$1:V$40) -> 468000 | P6: =O6/J6 -> 46800 | Q6: =SUMIF(헤몬팜일일!$C$1:$C$40,$C6,헤몬팜일일!X$1:X$40) -> 19980.816 | R6: =SUMIF(헤몬팜일일!$C$1:$C$40,$C6,헤몬팜일일!Y$1:Y$40) -> #REF! | S6: =SUMIF(헤몬팜일일!$C$1:$C$40,$C6,헤몬팜일일!Z$1:Z$40) -> 205799 | T6: =SUMIF(헤몬팜일일!$C$1:$C$40,$C6,헤몬팜일일!AA$1:AA$40) -> 187090 | U6: =SUMIF(헤몬팜일일!$C$1:$C$40,$C6,헤몬팜일일!AB$1:AB$40) -> 0 | V6: =SUMIF(헤몬팜일일!$C$1:$C$40,$C6,헤몬팜일일!AC$1:AC$40) -> 6930 | W6: 0.1 | X6: =SUMIF(헤몬팜일일!$C$1:$C$40,$C6,헤몬팜일일!AE$1:AE$40) -> 41500 | Y6: =W6+(X6/O6) -> 0.18867521 | Z6: =SUMIF(헤몬팜일일!$C$1:$C$40,$C6,헤몬팜일일!AG$1:AG$40) -> 92980.06 | AA6: =SUMIF(헤몬팜일일!$C$1:$C$40,$C6,헤몬팜일일!AH$1:AH$40) -> #REF! | AB6: =SUMIF(헤몬팜일일!$C$1:$C$40,$C6,헤몬팜일일!AJ$1:AK$40) -> #REF! | AC6: =SUMIF(헤몬팜일일!$C$1:$C$40,$C6,헤몬팜일일!AK$1:AK$40) -> #REF! | AD6: =SUMIF(헤몬팜일일!$C$1:$C$40,$C6,헤몬팜일일!AK$1:AK$40) -> #REF! | AE6: =SUMIF(헤몬팜일일!$C$1:$C$40,$C6,헤몬팜일일!AL$1:AL$40) -> 324
C7: 다밴다 1개 | D7: =AC7/O7 -> #REF! | E7: =AB7/O7 -> #REF! | F7: =(S7+U7)/O7 -> 0.27204766 | G7: =H7/AG7 -> #DIV/0! | H7: =SUMIF(헤몬팜일일!$C$1:$C$40,$C7,헤몬팜일일!O$1:O$40) -> 4 | I7: =H7/7 -> 0.57142857 | J7: =SUMIF(헤몬팜일일!$C$1:$C$40,$C7,헤몬팜일일!P$1:P$40) -> 4 | K7: =SUMIF(헤몬팜일일!$C$1:$C$40,$C7,헤몬팜일일!Q$1:Q$40) -> 0 | L7: =SUMIF(헤몬팜일일!$C$1:$C$40,$C7,헤몬팜일일!S$1:S$40) -> 0 | M7: =SUMIF(헤몬팜일일!$C$1:$C$40,$C7,헤몬팜일일!T$1:T$40) -> 239200 | N7: =SUMIF(헤몬팜일일!$C$1:$C$40,$C7,헤몬팜일일!U$1:U$40) -> 0 | O7: =SUMIF(헤몬팜일일!$C$1:$C$40,$C7,헤몬팜일일!V$1:V$40) -> 239200 | P7: =O7/J7 -> 59800 | Q7: =SUMIF(헤몬팜일일!$C$1:$C$40,$C7,헤몬팜일일!X$1:X$40) -> 26552.58 | R7: =SUMIF(헤몬팜일일!$C$1:$C$40,$C7,헤몬팜일일!Y$1:Y$40) -> #REF! | S7: =SUMIF(헤몬팜일일!$C$1:$C$40,$C7,헤몬팜일일!Z$1:Z$40) -> 65073.8 | T7: =SUMIF(헤몬팜일일!$C$1:$C$40,$C7,헤몬팜일일!AA$1:AA$40) -> 59158 | U7: =SUMIF(헤몬팜일일!$C$1:$C$40,$C7,헤몬팜일일!AB$1:AB$40) -> 0 | V7: =SUMIF(헤몬팜일일!$C$1:$C$40,$C7,헤몬팜일일!AC$1:AC$40) -> 0 | W7: 0.1 | X7: =SUMIF(헤몬팜일일!$C$1:$C$40,$C7,헤몬팜일일!AE$1:AE$40) -> 19300 | Y7: =W7+(X7/O7) -> 0.18068562 | Z7: =SUMIF(헤몬팜일일!$C$1:$C$40,$C7,헤몬팜일일!AG$1:AG$40) -> 45133.66 | AA7: =SUMIF(헤몬팜일일!$C$1:$C$40,$C7,헤몬팜일일!AH$1:AH$40) -> #REF! | AB7: =SUMIF(헤몬팜일일!$C$1:$C$40,$C7,헤몬팜일일!AJ$1:AK$40) -> #REF! | AC7: =SUMIF(헤몬팜일일!$C$1:$C$40,$C7,헤몬팜일일!AK$1:AK$40) -> #REF! | AD7: =SUMIF(헤몬팜일일!$C$1:$C$40,$C7,헤몬팜일일!AK$1:AK$40) -> #REF! | AE7: =SUMIF(헤몬팜일일!$C$1:$C$40,$C7,헤몬팜일일!AL$1:AL$40) -> 743.04
C8: 다벤다 2개 | D8: =AC8/O8 -> #REF! | E8: =AB8/O8 -> #REF! | F8: =(S8+U8)/O8 -> 0.20002565 | G8: =H8/AG8 -> #DIV/0! | H8: =SUMIF(헤몬팜일일!$C$1:$C$40,$C8,헤몬팜일일!O$1:O$40) -> 10 | I8: =H8/7 -> 1.4285714 | J8: =SUMIF(헤몬팜일일!$C$1:$C$40,$C8,헤몬팜일일!P$1:P$40) -> 10 | K8: =SUMIF(헤몬팜일일!$C$1:$C$40,$C8,헤몬팜일일!Q$1:Q$40) -> 0 | L8: =SUMIF(헤몬팜일일!$C$1:$C$40,$C8,헤몬팜일일!S$1:S$40) -> 0 | M8: =SUMIF(헤몬팜일일!$C$1:$C$40,$C8,헤몬팜일일!T$1:T$40) -> 697800 | N8: =SUMIF(헤몬팜일일!$C$1:$C$40,$C8,헤몬팜일일!U$1:U$40) -> 0 | O8: =SUMIF(헤몬팜일일!$C$1:$C$40,$C8,헤몬팜일일!V$1:V$40) -> 697800 | P8: =O8/J8 -> 69780 | Q8: =SUMIF(헤몬팜일일!$C$1:$C$40,$C8,헤몬팜일일!X$1:X$40) -> 26552.58 | R8: =SUMIF(헤몬팜일일!$C$1:$C$40,$C8,헤몬팜일일!Y$1:Y$40) -> #REF! | S8: =SUMIF(헤몬팜일일!$C$1:$C$40,$C8,헤몬팜일일!Z$1:Z$40) -> 139577.9 | T8: =SUMIF(헤몬팜일일!$C$1:$C$40,$C8,헤몬팜일일!AA$1:AA$40) -> 126889 | U8: =SUMIF(헤몬팜일일!$C$1:$C$40,$C8,헤몬팜일일!AB$1:AB$40) -> 0 | V8: =SUMIF(헤몬팜일일!$C$1:$C$40,$C8,헤몬팜일일!AC$1:AC$40) -> 0 | W8: 0.1 | X8: =SUMIF(헤몬팜일일!$C$1:$C$40,$C8,헤몬팜일일!AE$1:AE$40) -> 48250 | Y8: =W8+(X8/O8) -> 0.16914589 | Z8: =SUMIF(헤몬팜일일!$C$1:$C$40,$C8,헤몬팜일일!AG$1:AG$40) -> 123612.46 | AA8: =SUMIF(헤몬팜일일!$C$1:$C$40,$C8,헤몬팜일일!AH$1:AH$40) -> #REF! | AB8: =SUMIF(헤몬팜일일!$C$1:$C$40,$C8,헤몬팜일일!AJ$1:AK$40) -> #REF! | AC8: =SUMIF(헤몬팜일일!$C$1:$C$40,$C8,헤몬팜일일!AK$1:AK$40) -> #REF! | AD8: =SUMIF(헤몬팜일일!$C$1:$C$40,$C8,헤몬팜일일!AK$1:AK$40) -> #REF! | AE8: =SUMIF(헤몬팜일일!$C$1:$C$40,$C8,헤몬팜일일!AL$1:AL$40) -> 743.04
C9: 시거잭 | D9: =AC9/O9 -> -0.67714419 | E9: =AB9/O9 -> 0.42153214 | F9: =(S9+U9)/O9 -> 1.0986763 | G9: =H9/AG9 -> #DIV/0! | H9: =SUMIF(헤몬팜일일!$C$1:$C$40,$C9,헤몬팜일일!O$1:O$40) -> 22 | I9: =H9/7 -> 3.1428571 | J9: =SUMIF(헤몬팜일일!$C$1:$C$40,$C9,헤몬팜일일!P$1:P$40) -> 12 | K9: =SUMIF(헤몬팜일일!$C$1:$C$40,$C9,헤몬팜일일!Q$1:Q$40) -> 2 | L9: =SUMIF(헤몬팜일일!$C$1:$C$40,$C9,헤몬팜일일!S$1:S$40) -> 10 | M9: =SUMIF(헤몬팜일일!$C$1:$C$40,$C9,헤몬팜일일!T$1:T$40) -> 377780 | N9: =SUMIF(헤몬팜일일!$C$1:$C$40,$C9,헤몬팜일일!U$1:U$40) -> 170100 | O9: =SUMIF(헤몬팜일일!$C$1:$C$40,$C9,헤몬팜일일!V$1:V$40) -> 207680 | P9: =O9/J9 -> 17306.667 | Q9: =SUMIF(헤몬팜일일!$C$1:$C$40,$C9,헤몬팜일일!X$1:X$40) -> 10178.489 | R9: =SUMIF(헤몬팜일일!$C$1:$C$40,$C9,헤몬팜일일!Y$1:Y$40) -> 61515.894 | S9: =SUMIF(헤몬팜일일!$C$1:$C$40,$C9,헤몬팜일일!Z$1:Z$40) -> 129498.6 | T9: =SUMIF(헤몬팜일일!$C$1:$C$40,$C9,헤몬팜일일!AA$1:AA$40) -> 117726 | U9: =SUMIF(헤몬팜일일!$C$1:$C$40,$C9,헤몬팜일일!AB$1:AB$40) -> 98674.5 | V9: =SUMIF(헤몬팜일일!$C$1:$C$40,$C9,헤몬팜일일!AC$1:AC$40) -> 4620 | W9: 0.1 | X9: =SUMIF(헤몬팜일일!$C$1:$C$40,$C9,헤몬팜일일!AE$1:AE$40) -> 34800 | Y9: =W9+(X9/O9) -> 0.26756549 | Z9: =SUMIF(헤몬팜일일!$C$1:$C$40,$C9,헤몬팜일일!AG$1:AG$40) -> 50999.1 | AA9: =SUMIF(헤몬팜일일!$C$1:$C$40,$C9,헤몬팜일일!AH$1:AH$40) -> 7621.2106 | AB9: =SUMIF(헤몬팜일일!$C$1:$C$40,$C9,헤몬팜일일!AJ$1:AK$40) -> 87543.795 | AC9: =SUMIF(헤몬팜일일!$C$1:$C$40,$C9,헤몬팜일일!AK$1:AK$40) -> -140629.3 | AD9: =SUMIF(헤몬팜일일!$C$1:$C$40,$C9,헤몬팜일일!AK$1:AK$40) -> -140629.3 | AE9: =SUMIF(헤몬팜일일!$C$1:$C$40,$C9,헤몬팜일일!AL$1:AL$40) -> 12.15
C10: 뉴 고압세척기 배터리 1개 | D10: =AC10/O10 -> #REF! | E10: =AB10/O10 -> #REF! | F10: =(S10+U10)/O10 -> 0.14649162 | G10: =H10/AG10 -> #DIV/0! | H10: =SUMIF(헤몬팜일일!$C$1:$C$40,$C10,헤몬팜일일!O$1:O$40) -> 15 | I10: =H10/7 -> 2.1428571 | J10: =SUMIF(헤몬팜일일!$C$1:$C$40,$C10,헤몬팜일일!P$1:P$40) -> 15 | K10: =SUMIF(헤몬팜일일!$C$1:$C$40,$C10,헤몬팜일일!Q$1:Q$40) -> 1 | L10: =SUMIF(헤몬팜일일!$C$1:$C$40,$C10,헤몬팜일일!S$1:S$40) -> 0 | M10: =SUMIF(헤몬팜일일!$C$1:$C$40,$C10,헤몬팜일일!T$1:T$40) -> 597000 | N10: =SUMIF(헤몬팜일일!$C$1:$C$40,$C10,헤몬팜일일!U$1:U$40) -> 0 | O10: =SUMIF(헤몬팜일일!$C$1:$C$40,$C10,헤몬팜일일!V$1:V$40) -> 597000 | P10: =O10/J10 -> 39800 | Q10: =SUMIF(헤몬팜일일!$C$1:$C$40,$C10,헤몬팜일일!X$1:X$40) -> 15710.276 | R10: =SUMIF(헤몬팜일일!$C$1:$C$40,$C10,헤몬팜일일!Y$1:Y$40) -> #REF! | S10: =SUMIF(헤몬팜일일!$C$1:$C$40,$C10,헤몬팜일일!Z$1:Z$40) -> 87455.5 | T10: =SUMIF(헤몬팜일일!$C$1:$C$40,$C10,헤몬팜일일!AA$1:AA$40) -> 79505 | U10: =SUMIF(헤몬팜일일!$C$1:$C$40,$C10,헤몬팜일일!AB$1:AB$40) -> 0 | V10: =SUMIF(헤몬팜일일!$C$1:$C$40,$C10,헤몬팜일일!AC$1:AC$40) -> 2310 | W10: 0.1 | X10: =SUMIF(헤몬팜일일!$C$1:$C$40,$C10,헤몬팜일일!AE$1:AE$40) -> 62250 | Y10: =W10+(X10/O10) -> 0.20427136 | Z10: =SUMIF(헤몬팜일일!$C$1:$C$40,$C10,헤몬팜일일!AG$1:AG$40) -> 110010.06 | AA10: =SUMIF(헤몬팜일일!$C$1:$C$40,$C10,헤몬팜일일!AH$1:AH$40) -> #REF! | AB10: =SUMIF(헤몬팜일일!$C$1:$C$40,$C10,헤몬팜일일!AJ$1:AK$40) -> #REF! | AC10: =SUMIF(헤몬팜일일!$C$1:$C$40,$C10,헤몬팜일일!AK$1:AK$40) -> #REF! | AD10: =SUMIF(헤몬팜일일!$C$1:$C$40,$C10,헤몬팜일일!AK$1:AK$40) -> #REF! | AE10: =SUMIF(헤몬팜일일!$C$1:$C$40,$C10,헤몬팜일일!AL$1:AL$40) -> 352.836
C11: 뉴 고압세척기 | D11: =AC11/O11 -> #REF! | E11: =AB11/O11 -> #REF! | F11: =(S11+U11)/O11 -> 0.19664957 | G11: =H11/AG11 -> #DIV/0! | H11: =SUMIF(헤몬팜일일!$C$1:$C$40,$C11,헤몬팜일일!O$1:O$40) -> 3 | I11: =H11/7 -> 0.42857143 | J11: =SUMIF(헤몬팜일일!$C$1:$C$40,$C11,헤몬팜일일!P$1:P$40) -> 3 | K11: =SUMIF(헤몬팜일일!$C$1:$C$40,$C11,헤몬팜일일!Q$1:Q$40) -> 0 | L11: =SUMIF(헤몬팜일일!$C$1:$C$40,$C11,헤몬팜일일!S$1:S$40) -> 0 | M11: =SUMIF(헤몬팜일일!$C$1:$C$40,$C11,헤몬팜일일!T$1:T$40) -> 128700 | N11: =SUMIF(헤몬팜일일!$C$1:$C$40,$C11,헤몬팜일일!U$1:U$40) -> 0 | O11: =SUMIF(헤몬팜일일!$C$1:$C$40,$C11,헤몬팜일일!V$1:V$40) -> 128700 | P11: =O11/J11 -> 42900 | Q11: =SUMIF(헤몬팜일일!$C$1:$C$40,$C11,헤몬팜일일!X$1:X$40) -> 15710.276 | R11: =SUMIF(헤몬팜일일!$C$1:$C$40,$C11,헤몬팜일일!Y$1:Y$40) -> #REF! | S11: =SUMIF(헤몬팜일일!$C$1:$C$40,$C11,헤몬팜일일!Z$1:Z$40) -> 25308.8 | T11: =SUMIF(헤몬팜일일!$C$1:$C$40,$C11,헤몬팜일일!AA$1:AA$40) -> 23008 | U11: =SUMIF(헤몬팜일일!$C$1:$C$40,$C11,헤몬팜일일!AB$1:AB$40) -> 0 | V11: =SUMIF(헤몬팜일일!$C$1:$C$40,$C11,헤몬팜일일!AC$1:AC$40) -> 0 | W11: 0.1 | X11: =SUMIF(헤몬팜일일!$C$1:$C$40,$C11,헤몬팜일일!AE$1:AE$40) -> 5700 | Y11: =W11+(X11/O11) -> 0.14428904 | Z11: =SUMIF(헤몬팜일일!$C$1:$C$40,$C11,헤몬팜일일!AG$1:AG$40) -> 15738.63 | AA11: =SUMIF(헤몬팜일일!$C$1:$C$40,$C11,헤몬팜일일!AH$1:AH$40) -> #REF! | AB11: =SUMIF(헤몬팜일일!$C$1:$C$40,$C11,헤몬팜일일!AJ$1:AK$40) -> #REF! | AC11: =SUMIF(헤몬팜일일!$C$1:$C$40,$C11,헤몬팜일일!AK$1:AK$40) -> #REF! | AD11: =SUMIF(헤몬팜일일!$C$1:$C$40,$C11,헤몬팜일일!AK$1:AK$40) -> #REF! | AE11: =SUMIF(헤몬팜일일!$C$1:$C$40,$C11,헤몬팜일일!AL$1:AL$40) -> 352.836
C12: 모기지옥 | D12: =AC12/O12 -> 0.3206072 | E12: =AB12/O12 -> 0.36298871 | F12: =(S12+U12)/O12 -> 0.04238151 | G12: =H12/AG12 -> #DIV/0! | H12: =SUMIF(헤몬팜일일!$C$1:$C$40,$C12,헤몬팜일일!O$1:O$40) -> 12 | I12: =H12/7 -> 1.7142857 | J12: =SUMIF(헤몬팜일일!$C$1:$C$40,$C12,헤몬팜일일!P$1:P$40) -> 12 | K12: =SUMIF(헤몬팜일일!$C$1:$C$40,$C12,헤몬팜일일!Q$1:Q$40) -> 0 | L12: =SUMIF(헤몬팜일일!$C$1:$C$40,$C12,헤몬팜일일!S$1:S$40) -> 0 | M12: =SUMIF(헤몬팜일일!$C$1:$C$40,$C12,헤몬팜일일!T$1:T$40) -> 230400 | N12: =SUMIF(헤몬팜일일!$C$1:$C$40,$C12,헤몬팜일일!U$1:U$40) -> 0 | O12: =SUMIF(헤몬팜일일!$C$1:$C$40,$C12,헤몬팜일일!V$1:V$40) -> 230400 | P12: =O12/J12 -> 19200 | Q12: =SUMIF(헤몬팜일일!$C$1:$C$40,$C12,헤몬팜일일!X$1:X$40) -> 12745.238 | R12: =SUMIF(헤몬팜일일!$C$1:$C$40,$C12,헤몬팜일일!Y$1:Y$40) -> 81257.222 | S12: =SUMIF(헤몬팜일일!$C$1:$C$40,$C12,헤몬팜일일!Z$1:Z$40) -> 9764.7 | T12: =SUMIF(헤몬팜일일!$C$1:$C$40,$C12,헤몬팜일일!AA$1:AA$40) -> 8877 | U12: =SUMIF(헤몬팜일일!$C$1:$C$40,$C12,헤몬팜일일!AB$1:AB$40) -> 0 | V12: =SUMIF(헤몬팜일일!$C$1:$C$40,$C12,헤몬팜일일!AC$1:AC$40) -> 0 | W12: 0.1 | X12: =SUMIF(헤몬팜일일!$C$1:$C$40,$C12,헤몬팜일일!AE$1:AE$40) -> 40200 | Y12: =W12+(X12/O12) -> 0.27447917 | Z12: =SUMIF(헤몬팜일일!$C$1:$C$40,$C12,헤몬팜일일!AG$1:AG$40) -> 58632.06 | AA12: =SUMIF(헤몬팜일일!$C$1:$C$40,$C12,헤몬팜일일!AH$1:AH$40) -> 6878.1183 | AB12: =SUMIF(헤몬팜일일!$C$1:$C$40,$C12,헤몬팜일일!AJ$1:AK$40) -> 83632.599 | AC12: =SUMIF(헤몬팜일일!$C$1:$C$40,$C12,헤몬팜일일!AK$1:AK$40) -> 73867.899 | AD12: =SUMIF(헤몬팜일일!$C$1:$C$40,$C12,헤몬팜일일!AK$1:AK$40) -> 73867.899 | AE12: =SUMIF(헤몬팜일일!$C$1:$C$40,$C12,헤몬팜일일!AL$1:AL$40) -> 130.68
C13: 컷소 배터리 1개 | D13: =AC13/O13 -> #REF! | E13: =AB13/O13 -> #REF! | F13: =(S13+U13)/O13 -> #DIV/0! | G13: =H13/AG13 -> #DIV/0! | H13: =SUMIF(헤몬팜일일!$C$1:$C$40,$C13,헤몬팜일일!O$1:O$40) -> 0 | I13: =H13/7 -> 0 | J13: =SUMIF(헤몬팜일일!$C$1:$C$40,$C13,헤몬팜일일!P$1:P$40) -> 0 | K13: =SUMIF(헤몬팜일일!$C$1:$C$40,$C13,헤몬팜일일!Q$1:Q$40) -> 1 | L13: =SUMIF(헤몬팜일일!$C$1:$C$40,$C13,헤몬팜일일!S$1:S$40) -> 0 | M13: =SUMIF(헤몬팜일일!$C$1:$C$40,$C13,헤몬팜일일!T$1:T$40) -> 0 | N13: =SUMIF(헤몬팜일일!$C$1:$C$40,$C13,헤몬팜일일!U$1:U$40) -> 0 | O13: =SUMIF(헤몬팜일일!$C$1:$C$40,$C13,헤몬팜일일!V$1:V$40) -> 0 | P13: =O13/J13 -> #DIV/0! | Q13: =SUMIF(헤몬팜일일!$C$1:$C$40,$C13,헤몬팜일일!X$1:X$40) -> 24339.865 | R13: =SUMIF(헤몬팜일일!$C$1:$C$40,$C13,헤몬팜일일!Y$1:Y$40) -> #REF! | S13: =SUMIF(헤몬팜일일!$C$1:$C$40,$C13,헤몬팜일일!Z$1:Z$40) -> 69991.9 | T13: =SUMIF(헤몬팜일일!$C$1:$C$40,$C13,헤몬팜일일!AA$1:AA$40) -> 63629 | U13: =SUMIF(헤몬팜일일!$C$1:$C$40,$C13,헤몬팜일일!AB$1:AB$40) -> 0 | V13: =SUMIF(헤몬팜일일!$C$1:$C$40,$C13,헤몬팜일일!AC$1:AC$40) -> 2310 | W13: 0.1 | X13: =SUMIF(헤몬팜일일!$C$1:$C$40,$C13,헤몬팜일일!AE$1:AE$40) -> 0 | Y13: =W13+(X13/O13) -> #DIV/0! | Z13: =SUMIF(헤몬팜일일!$C$1:$C$40,$C13,헤몬팜일일!AG$1:AG$40) -> 0 | AA13: =SUMIF(헤몬팜일일!$C$1:$C$40,$C13,헤몬팜일일!AH$1:AH$40) -> #REF! | AB13: =SUMIF(헤몬팜일일!$C$1:$C$40,$C13,헤몬팜일일!AJ$1:AK$40) -> #REF! | AC13: =SUMIF(헤몬팜일일!$C$1:$C$40,$C13,헤몬팜일일!AK$1:AK$40) -> #REF! | AD13: =SUMIF(헤몬팜일일!$C$1:$C$40,$C13,헤몬팜일일!AK$1:AK$40) -> #REF! | AE13: =SUMIF(헤몬팜일일!$C$1:$C$40,$C13,헤몬팜일일!AL$1:AL$40) -> 362.88
C14: 컷소 배터리 2개 | D14: =AC14/O14 -> #REF! | E14: =AB14/O14 -> #REF! | F14: =(S14+U14)/O14 -> 0.21803949 | G14: =H14/AG14 -> #DIV/0! | H14: =SUMIF(헤몬팜일일!$C$1:$C$40,$C14,헤몬팜일일!O$1:O$40) -> 6 | I14: =H14/7 -> 0.85714286 | J14: =SUMIF(헤몬팜일일!$C$1:$C$40,$C14,헤몬팜일일!P$1:P$40) -> 6 | K14: =SUMIF(헤몬팜일일!$C$1:$C$40,$C14,헤몬팜일일!Q$1:Q$40) -> 2 | L14: =SUMIF(헤몬팜일일!$C$1:$C$40,$C14,헤몬팜일일!S$1:S$40) -> 0 | M14: =SUMIF(헤몬팜일일!$C$1:$C$40,$C14,헤몬팜일일!T$1:T$40) -> 379290 | N14: =SUMIF(헤몬팜일일!$C$1:$C$40,$C14,헤몬팜일일!U$1:U$40) -> 0 | O14: =SUMIF(헤몬팜일일!$C$1:$C$40,$C14,헤몬팜일일!V$1:V$40) -> 379290 | P14: =O14/J14 -> 63215 | Q14: =SUMIF(헤몬팜일일!$C$1:$C$40,$C14,헤몬팜일일!X$1:X$40) -> 24339.865 | R14: =SUMIF(헤몬팜일일!$C$1:$C$40,$C14,헤몬팜일일!Y$1:Y$40) -> #REF! | S14: =SUMIF(헤몬팜일일!$C$1:$C$40,$C14,헤몬팜일일!Z$1:Z$40) -> 82700.2 | T14: =SUMIF(헤몬팜일일!$C$1:$C$40,$C14,헤몬팜일일!AA$1:AA$40) -> 75182 | U14: =SUMIF(헤몬팜일일!$C$1:$C$40,$C14,헤몬팜일일!AB$1:AB$40) -> 0 | V14: =SUMIF(헤몬팜일일!$C$1:$C$40,$C14,헤몬팜일일!AC$1:AC$40) -> 4620 | W14: 0.1 | X14: =SUMIF(헤몬팜일일!$C$1:$C$40,$C14,헤몬팜일일!AE$1:AE$40) -> 28950 | Y14: =W14+(X14/O14) -> 0.17632682 | Z14: =SUMIF(헤몬팜일일!$C$1:$C$40,$C14,헤몬팜일일!AG$1:AG$40) -> 58534.68 | AA14: =SUMIF(헤몬팜일일!$C$1:$C$40,$C14,헤몬팜일일!AH$1:AH$40) -> #REF! | AB14: =SUMIF(헤몬팜일일!$C$1:$C$40,$C14,헤몬팜일일!AJ$1:AK$40) -> #REF! | AC14: =SUMIF(헤몬팜일일!$C$1:$C$40,$C14,헤몬팜일일!AK$1:AK$40) -> #REF! | AD14: =SUMIF(헤몬팜일일!$C$1:$C$40,$C14,헤몬팜일일!AK$1:AK$40) -> #REF! | AE14: =SUMIF(헤몬팜일일!$C$1:$C$40,$C14,헤몬팜일일!AL$1:AL$40) -> 362.88
... C19: 강아지바리깡 2개 | D19: =AC19/O19 -> 2.204507 | E19: =AB19/O19 -> 0.4135393 | F19: =(S19+U19)/O19 -> -1.7909677 | G19: =H19/AG19 -> #DIV/0! | H19: =SUMIF(헤몬팜일일!$C$1:$C$40,$C19,헤몬팜일일!O$1:O$40) -> -1 | I19: =H19/7 -> -0.14285714 | J19: =SUMIF(헤몬팜일일!$C$1:$C$40,$C19,헤몬팜일일!P$1:P$40) -> -1 | K19: =SUMIF(헤몬팜일일!$C$1:$C$40,$C19,헤몬팜일일!Q$1:Q$40) -> 1 | L19: =SUMIF(헤몬팜일일!$C$1:$C$40,$C19,헤몬팜일일!S$1:S$40) -> 0 | M19: =SUMIF(헤몬팜일일!$C$1:$C$40,$C19,헤몬팜일일!T$1:T$40) -> -39890 | N19: =SUMIF(헤몬팜일일!$C$1:$C$40,$C19,헤몬팜일일!U$1:U$40) -> 0 | O19: =SUMIF(헤몬팜일일!$C$1:$C$40,$C19,헤몬팜일일!V$1:V$40) -> -39890 | P19: =O19/J19 -> 39890 | Q19: =SUMIF(헤몬팜일일!$C$1:$C$40,$C19,헤몬팜일일!X$1:X$40) -> 27437.666 | R19: =SUMIF(헤몬팜일일!$C$1:$C$40,$C19,헤몬팜일일!Y$1:Y$40) -> -14113.035 | S19: =SUMIF(헤몬팜일일!$C$1:$C$40,$C19,헤몬팜일일!Z$1:Z$40) -> 71441.7 | T19: =SUMIF(헤몬팜일일!$C$1:$C$40,$C19,헤몬팜일일!AA$1:AA$40) -> 64947 | U19: =SUMIF(헤몬팜일일!$C$1:$C$40,$C19,헤몬팜일일!AB$1:AB$40) -> 0 | V19: =SUMIF(헤몬팜일일!$C$1:$C$40,$C19,헤몬팜일일!AC$1:AC$40) -> 2310 | W19: 0.1 | X19: =SUMIF(헤몬팜일일!$C$1:$C$40,$C19,헤몬팜일일!AE$1:AE$40) -> -3550 | Y19: =W19+(X19/O19) -> 0.18899474 | Z19: =SUMIF(헤몬팜일일!$C$1:$C$40,$C19,헤몬팜일일!AG$1:AG$40) -> -7858.09 | AA19: =SUMIF(헤몬팜일일!$C$1:$C$40,$C19,헤몬팜일일!AH$1:AH$40) -> -1422.7928 | AB19: =SUMIF(헤몬팜일일!$C$1:$C$40,$C19,헤몬팜일일!AJ$1:AK$40) -> -16496.083 | AC19: =SUMIF(헤몬팜일일!$C$1:$C$40,$C19,헤몬팜일일!AK$1:AK$40) -> -87937.783 | AD19: =SUMIF(헤몬팜일일!$C$1:$C$40,$C19,헤몬팜일일!AK$1:AK$40) -> -87937.783 | AE19: =SUMIF(헤몬팜일일!$C$1:$C$40,$C19,헤몬팜일일!AL$1:AL$40) -> 129.168
D20: =AC20/P20 -> #REF! | E20: =AB20/P20 -> #REF! | F20: =T20/P20 -> #DIV/0! | H20: =SUM(H3:H19) -> 456 | I20: =SUM(I3:I19) -> 65.142857 | J20: =SUM(J3:J19) -> 436 | K20: =SUM(K3:K19) -> 53 | L20: =SUM(L3:L19) -> 20 | M20: =SUM(M3:M19) -> 13138690 | N20: =SUM(N3:N19) -> 379100 | O20: 12759590 | Q20: =SUM(Q3:Q19) -> 307169.1 | R20: =SUM(R3:R19) -> #REF! | S20: =SUM(S3:S19) -> 3230157.7 | T20: =SUM(T3:T19) -> 2936507 | U20: =SUM(U3:U19) -> 224486.5 | V20: =SUM(V3:V19) -> 118704 | W20: 0.09 | X20: =SUM(X3:X19) -> 1361500 | Z20: =SUM(Z3:Z19) -> 2613808.9 | AA20: =SUM(AA3:AA19) -> #REF! | AB20: =SUM(AB3:AB19) -> #REF! | AC20: =SUM(AC3:AC19) -> #REF!
X21: 552344 | Y21: 926423 | Z21: =X21+Y21 -> 1478767
C22: 9/29~10/5 | D22: 이윤율 | E22: 마진율 | F22: 광고비율 | G22: 전환율 | H22: 판매수 | I22: 일판매 | J22: 순판매개수 | K22: 취소개수 | L22: 가구매 | M22: 매출 | N22: 가구매금액 | O22: 순매출 | P22: 판매가 | Q22: 입고가 | R22: 입고판매가 | S22: 광고비1.1 | T22: 광고비 | U22: 가구매비용 | V22: 반품회수비 | W22: 수수료 | X22: 택배비 | Y22: 판매수수료 | Z22: 수수료 | AA22: 부가세 | AB22: 판매마진 | AC22: 순이익 | AD22: 노출수 | AE22: 클릭수
C23: 쉐이버 | D23: =AC23/O23 -> 0.1684566 | E23: =AB23/O23 -> 0.42290675 | F23: =(S23+U23)/O23 -> 0.25445014 | G23: =H23/AG23 -> #DIV/0! | H23: =SUMIF(헤몬팜일일!$C$1:$C$140,$C23,헤몬팜일일!O$1:O$140) -> 1012 | I23: =H23/7 -> 144.57143 | J23: =SUMIF(헤몬팜일일!$C$1:$C$140,$C23,헤몬팜일일!P$1:P$140) -> 1012 | K23: =SUMIF(헤몬팜일일!$C$1:$C$140,$C23,헤몬팜일일!Q$1:Q$140) -> 85 | L23: =SUMIF(헤몬팜일일!$C$1:$C$140,$C23,헤몬팜일일!S$1:S$140) -> 0 | M23: =SUMIF(헤몬팜일일!$C$1:$C$140,$C23,헤몬팜일일!T$1:T$140) -> 28249000 | N23: =SUMIF(헤몬팜일일!$C$1:$C$140,$C23,헤몬팜일일!U$1:U$140) -> 0 | O23: =SUMIF(헤몬팜일일!$C$1:$C$140,$C23,헤몬팜일일!V$1:V$140) -> 28249000 | P23: =O23/J23 -> 27914.032 | Q23: =R23/J23 -> 9245.0616 | R23: =SUMIF(헤몬팜일일!$C$1:$C$140,$C23,헤몬팜일일!Y$1:Y$140) -> 9356002.3 | S23: =SUMIF(헤몬팜일일!$C$1:$C$140,$C23,헤몬팜일일!Z$1:Z$140) -> 7187962.1 | T23: =SUMIF(헤몬팜일일!$C$1:$C$140,$C23,헤몬팜일일!AA$1:AA$140) -> 6534511 | U23: =SUMIF(헤몬팜일일!$C$1:$C$140,$C23,헤몬팜일일!AB$1:AB$140) -> 0 | V23: =SUMIF(헤몬팜일일!$C$1:$C$140,$C23,헤몬팜일일!AC$1:AC$140) -> 184620 | W23: 0.1 | X23: =SUMIF(헤몬팜일일!$C$1:$C$140,$C23,헤몬팜일일!AE$1:AE$140) -> 3086600 | Y23: =W23+(X23/O23) -> 0.20926404 | Z23: =SUMIF(헤몬팜일일!$C$1:$C$140,$C23,헤몬팜일일!AG$1:AG$140) -> 5911500.2 | AA23: =SUMIF(헤몬팜일일!$C$1:$C$140,$C23,헤몬팜일일!AH$1:AH$140) -> 1034804.8 | AB23: =SUMIF(헤몬팜일일!$C$1:$C$140,$C23,헤몬팜일일!AJ$1:AJ$140) -> 11946693 | AC23: =SUMIF(헤몬팜일일!$C$1:$C$140,$C23,헤몬팜일일!AK$1:AK$140) -> 4758730.6 | AD23: =SUMIF(헤몬팜일일!$C$1:$C$140,$C23,헤몬팜일일!AK$1:AK$140) -> 4758730.6 | AE23: =SUMIF(헤몬팜일일!$C$1:$C$140,$C23,헤몬팜일일!AL$1:AL$140) -> 452.088
C24: 일자면도기 | D24: =AC24/O24 -> 0.12485845 | E24: =AB24/O24 -> 0.40985052 | F24: =(S24+U24)/O24 -> 0.28499207 | G24: =H24/AG24 -> #DIV/0! | H24: =SUMIF(헤몬팜일일!$C$1:$C$140,$C24,헤몬팜일일!O$1:O$140) -> 5 | I24: =H24/7 -> 0.71428571 | J24: =SUMIF(헤몬팜일일!$C$1:$C$140,$C24,헤몬팜일일!P$1:P$140) -> 5 | K24: =SUMIF(헤몬팜일일!$C$1:$C$140,$C24,헤몬팜일일!Q$1:Q$140) -> 0 | L24: =SUMIF(헤몬팜일일!$C$1:$C$140,$C24,헤몬팜일일!S$1:S$140) -> 0 | M24: =SUMIF(헤몬팜일일!$C$1:$C$140,$C24,헤몬팜일일!T$1:T$140) -> 113500 | N24: =SUMIF(헤몬팜일일!$C$1:$C$140,$C24,헤몬팜일일!U$1:U$140) -> 0 | O24: =SUMIF(헤몬팜일일!$C$1:$C$140,$C24,헤몬팜일일!V$1:V$140) -> 113500 | P24: =O24/J24 -> 22700 | Q24: =R24/J24 -> 7377.328 | R24: =SUMIF(헤몬팜일일!$C$1:$C$140,$C24,헤몬팜일일!Y$1:Y$140) -> 36886.64 | S24: =SUMIF(헤몬팜일일!$C$1:$C$140,$C24,헤몬팜일일!Z$1:Z$140) -> 32346.6 | T24: =SUMIF(헤몬팜일일!$C$1:$C$140,$C24,헤몬팜일일!AA$1:AA$140) -> 29406 | U24: =SUMIF(헤몬팜일일!$C$1:$C$140,$C24,헤몬팜일일!AB$1:AB$140) -> 0 | V24: =SUMIF(헤몬팜일일!$C$1:$C$140,$C24,헤몬팜일일!AC$1:AC$140) -> 0 | W24: 0.1 | X24: =SUMIF(헤몬팜일일!$C$1:$C$140,$C24,헤몬팜일일!AE$1:AE$140) -> 14750 | Y24: =W24+(X24/O24) -> 0.22995595 | Z24: =SUMIF(헤몬팜일일!$C$1:$C$140,$C24,헤몬팜일일!AG$1:AG$140) -> 26100.12 | AA24: =SUMIF(헤몬팜일일!$C$1:$C$140,$C24,헤몬팜일일!AH$1:AH$140) -> 3995.2058 | AB24: =SUMIF(헤몬팜일일!$C$1:$C$140,$C24,헤몬팜일일!AJ$1:AJ$140) -> 46518.034 | AC24: =SUMIF(헤몬팜일일!$C$1:$C$140,$C24,헤몬팜일일!AK$1:AK$140) -> 14171.434 | AD24: =SUMIF(헤몬팜일일!$C$1:$C$140,$C24,헤몬팜일일!AK$1:AK$140) -> 14171.434 | AE24: =SUMIF(헤몬팜일일!$C$1:$C$140,$C24,헤몬팜일일!AL$1:AL$140) -> 340.2
C25: 프라임 1개 | D25: =AC25/O25 -> #REF! | E25: =AB25/O25 -> #REF! | F25: =(S25+U25)/O25 -> 0.36720573 | G25: =H25/AG25 -> #DIV/0! | H25: =SUMIF(헤몬팜일일!$C$1:$C$140,$C25,헤몬팜일일!O$1:O$140) -> 9 | I25: =H25/7 -> 1.2857143 | J25: =SUMIF(헤몬팜일일!$C$1:$C$140,$C25,헤몬팜일일!P$1:P$140) -> 9 | K25: =SUMIF(헤몬팜일일!$C$1:$C$140,$C25,헤몬팜일일!Q$1:Q$140) -> 1 | L25: =SUMIF(헤몬팜일일!$C$1:$C$140,$C25,헤몬팜일일!S$1:S$140) -> 0 | M25: =SUMIF(헤몬팜일일!$C$1:$C$140,$C25,헤몬팜일일!T$1:T$140) -> 412200 | N25: =SUMIF(헤몬팜일일!$C$1:$C$140,$C25,헤몬팜일일!U$1:U$140) -> 0 | O25: =SUMIF(헤몬팜일일!$C$1:$C$140,$C25,헤몬팜일일!V$1:V$140) -> 412200 | P25: =O25/J25 -> 45800 | Q25: =R25/J25 -> #REF! | R25: =SUMIF(헤몬팜일일!$C$1:$C$140,$C25,헤몬팜일일!Y$1:Y$140) -> #REF! | S25: =SUMIF(헤몬팜일일!$C$1:$C$140,$C25,헤몬팜일일!Z$1:Z$140) -> 151362.2 | T25: =SUMIF(헤몬팜일일!$C$1:$C$140,$C25,헤몬팜일일!AA$1:AA$140) -> 137602 | U25: =SUMIF(헤몬팜일일!$C$1:$C$140,$C25,헤몬팜일일!AB$1:AB$140) -> 0 | V25: =SUMIF(헤몬팜일일!$C$1:$C$140,$C25,헤몬팜일일!AC$1:AC$140) -> 2310 | W25: 0.1 | X25: =SUMIF(헤몬팜일일!$C$1:$C$140,$C25,헤몬팜일일!AE$1:AE$140) -> 37350 | Y25: =W25+(X25/O25) -> 0.19061135 | Z25: =SUMIF(헤몬팜일일!$C$1:$C$140,$C25,헤몬팜일일!AG$1:AG$140) -> 82692.18 | AA25: =SUMIF(헤몬팜일일!$C$1:$C$140,$C25,헤몬팜일일!AH$1:AH$140) -> #REF! | AB25: =SUMIF(헤몬팜일일!$C$1:$C$140,$C25,헤몬팜일일!AJ$1:AJ$140) -> #REF! | AC25: =SUMIF(헤몬팜일일!$C$1:$C$140,$C25,헤몬팜일일!AK$1:AK$140) -> #REF! | AD25: =SUMIF(헤몬팜일일!$C$1:$C$140,$C25,헤몬팜일일!AK$1:AK$140) -> #REF! | AE25: =SUMIF(헤몬팜일일!$C$1:$C$140,$C25,헤몬팜일일!AL$1:AL$140) -> 1134
C26: 프라임 2개 | D26: =AC26/O26 -> #REF! | E26: =AB26/O26 -> #REF! | F26: =(S26+U26)/O26 -> 0.41999038 | G26: =H26/AG26 -> #DIV/0! | H26: =SUMIF(헤몬팜일일!$C$1:$C$140,$C26,헤몬팜일일!O$1:O$140) -> 22 | I26: =H26/7 -> 3.1428571 | J26: =SUMIF(헤몬팜일일!$C$1:$C$140,$C26,헤몬팜일일!P$1:P$140) -> 22 | K26: =SUMIF(헤몬팜일일!$C$1:$C$140,$C26,헤몬팜일일!Q$1:Q$140) -> 8 | L26: =SUMIF(헤몬팜일일!$C$1:$C$140,$C26,헤몬팜일일!S$1:S$140) -> 0 | M26: =SUMIF(헤몬팜일일!$C$1:$C$140,$C26,헤몬팜일일!T$1:T$140) -> 1029600 | N26: =SUMIF(헤몬팜일일!$C$1:$C$140,$C26,헤몬팜일일!U$1:U$140) -> 0 | O26: =SUMIF(헤몬팜일일!$C$1:$C$140,$C26,헤몬팜일일!V$1:V$140) -> 1029600 | P26: =O26/J26 -> 46800 | Q26: =R26/J26 -> #REF! | R26: =SUMIF(헤몬팜일일!$C$1:$C$140,$C26,헤몬팜일일!Y$1:Y$140) -> #REF! | S26: =SUMIF(헤몬팜일일!$C$1:$C$140,$C26,헤몬팜일일!Z$1:Z$140) -> 432422.1 | T26: =SUMIF(헤몬팜일일!$C$1:$C$140,$C26,헤몬팜일일!AA$1:AA$140) -> 393111 | U26: =SUMIF(헤몬팜일일!$C$1:$C$140,$C26,헤몬팜일일!AB$1:AB$140) -> 0 | V26: =SUMIF(헤몬팜일일!$C$1:$C$140,$C26,헤몬팜일일!AC$1:AC$140) -> 18480 | W26: 0.1 | X26: =SUMIF(헤몬팜일일!$C$1:$C$140,$C26,헤몬팜일일!AE$1:AE$140) -> 91300 | Y26: =W26+(X26/O26) -> 0.18867521 | Z26: =SUMIF(헤몬팜일일!$C$1:$C$140,$C26,헤몬팜일일!AG$1:AG$140) -> 204556.18 | AA26: =SUMIF(헤몬팜일일!$C$1:$C$140,$C26,헤몬팜일일!AH$1:AH$140) -> #REF! | AB26: =SUMIF(헤몬팜일일!$C$1:$C$140,$C26,헤몬팜일일!AJ$1:AJ$140) -> #REF! | AC26: =SUMIF(헤몬팜일일!$C$1:$C$140,$C26,헤몬팜일일!AK$1:AK$140) -> #REF! | AD26: =SUMIF(헤몬팜일일!$C$1:$C$140,$C26,헤몬팜일일!AK$1:AK$140) -> #REF! | AE26: =SUMIF(헤몬팜일일!$C$1:$C$140,$C26,헤몬팜일일!AL$1:AL$140) -> 1134
C27: 다밴다 1개 | D27: =AC27/O27 -> #REF! | E27: =AB27/O27 -> #REF! | F27: =(S27+U27)/O27 -> 0.42336204 | G27: =H27/AG27 -> #DIV/0! | H27: =SUMIF(헤몬팜일일!$C$1:$C$140,$C27,헤몬팜일일!O$1:O$140) -> 6 | I27: =H27/7 -> 0.85714286 | J27: =SUMIF(헤몬팜일일!$C$1:$C$140,$C27,헤몬팜일일!P$1:P$140) -> 6 | K27: =SUMIF(헤몬팜일일!$C$1:$C$140,$C27,헤몬팜일일!Q$1:Q$140) -> 1 | L27: =SUMIF(헤몬팜일일!$C$1:$C$140,$C27,헤몬팜일일!S$1:S$140) -> 0 | M27: =SUMIF(헤몬팜일일!$C$1:$C$140,$C27,헤몬팜일일!T$1:T$140) -> 358800 | N27: =SUMIF(헤몬팜일일!$C$1:$C$140,$C27,헤몬팜일일!U$1:U$140) -> 0 | O27: =SUMIF(헤몬팜일일!$C$1:$C$140,$C27,헤몬팜일일!V$1:V$140) -> 358800 | P27: =O27/J27 -> 59800 | Q27: =R27/J27 -> #REF! | R27: =SUMIF(헤몬팜일일!$C$1:$C$140,$C27,헤몬팜일일!Y$1:Y$140) -> #REF! | S27: =SUMIF(헤몬팜일일!$C$1:$C$140,$C27,헤몬팜일일!Z$1:Z$140) -> 151902.3 | T27: =SUMIF(헤몬팜일일!$C$1:$C$140,$C27,헤몬팜일일!AA$1:AA$140) -> 138093 | U27: =SUMIF(헤몬팜일일!$C$1:$C$140,$C27,헤몬팜일일!AB$1:AB$140) -> 0 | V27: =SUMIF(헤몬팜일일!$C$1:$C$140,$C27,헤몬팜일일!AC$1:AC$140) -> 2310 | W27: 0.1 | X27: =SUMIF(헤몬팜일일!$C$1:$C$140,$C27,헤몬팜일일!AE$1:AE$140) -> 28950 | Y27: =W27+(X27/O27) -> 0.18068562 | Z27: =SUMIF(헤몬팜일일!$C$1:$C$140,$C27,헤몬팜일일!AG$1:AG$140) -> 67700.49 | AA27: =SUMIF(헤몬팜일일!$C$1:$C$140,$C27,헤몬팜일일!AH$1:AH$140) -> #REF! | AB27: =SUMIF(헤몬팜일일!$C$1:$C$140,$C27,헤몬팜일일!AJ$1:AJ$140) -> #REF! | AC27: =SUMIF(헤몬팜일일!$C$1:$C$140,$C27,헤몬팜일일!AK$1:AK$140) -> #REF! | AD27: =SUMIF(헤몬팜일일!$C$1:$C$140,$C27,헤몬팜일일!AK$1:AK$140) -> #REF! | AE27: =SUMIF(헤몬팜일일!$C$1:$C$140,$C27,헤몬팜일일!AL$1:AL$140) -> 2600.64
C28: 다벤다 2개 | D28: =AC28/O28 -> #REF! | E28: =AB28/O28 -> #REF! | F28: =(S28+U28)/O28 -> 0.3514595 | G28: =H28/AG28 -> #DIV/0! | H28: =SUMIF(헤몬팜일일!$C$1:$C$140,$C28,헤몬팜일일!O$1:O$140) -> 16 | I28: =H28/7 -> 2.2857143 | J28: =SUMIF(헤몬팜일일!$C$1:$C$140,$C28,헤몬팜일일!P$1:P$140) -> 16 | K28: =SUMIF(헤몬팜일일!$C$1:$C$140,$C28,헤몬팜일일!Q$1:Q$140) -> 4 | L28: =SUMIF(헤몬팜일일!$C$1:$C$140,$C28,헤몬팜일일!S$1:S$140) -> 0 | M28: =SUMIF(헤몬팜일일!$C$1:$C$140,$C28,헤몬팜일일!T$1:T$140) -> 1116480 | N28: =SUMIF(헤몬팜일일!$C$1:$C$140,$C28,헤몬팜일일!U$1:U$140) -> 0 | O28: =SUMIF(헤몬팜일일!$C$1:$C$140,$C28,헤몬팜일일!V$1:V$140) -> 1116480 | P28: =O28/J28 -> 69780 | Q28: =R28/J28 -> #REF! | R28: =SUMIF(헤몬팜일일!$C$1:$C$140,$C28,헤몬팜일일!Y$1:Y$140) -> #REF! | S28: =SUMIF(헤몬팜일일!$C$1:$C$140,$C28,헤몬팜일일!Z$1:Z$140) -> 392397.5 | T28: =SUMIF(헤몬팜일일!$C$1:$C$140,$C28,헤몬팜일일!AA$1:AA$140) -> 356725 | U28: =SUMIF(헤몬팜일일!$C$1:$C$140,$C28,헤몬팜일일!AB$1:AB$140) -> 0 | V28: =SUMIF(헤몬팜일일!$C$1:$C$140,$C28,헤몬팜일일!AC$1:AC$140) -> 9240 | W28: 0.1 | X28: =SUMIF(헤몬팜일일!$C$1:$C$140,$C28,헤몬팜일일!AE$1:AE$140) -> 77200 | Y28: =W28+(X28/O28) -> 0.16914589 | Z28: =SUMIF(헤몬팜일일!$C$1:$C$140,$C28,헤몬팜일일!AG$1:AG$140) -> 197780.02 | AA28: =SUMIF(헤몬팜일일!$C$1:$C$140,$C28,헤몬팜일일!AH$1:AH$140) -> #REF! | AB28: =SUMIF(헤몬팜일일!$C$1:$C$140,$C28,헤몬팜일일!AJ$1:AJ$140) -> #REF! | AC28: =SUMIF(헤몬팜일일!$C$1:$C$140,$C28,헤몬팜일일!AK$1:AK$140) -> #REF! | AD28: =SUMIF(헤몬팜일일!$C$1:$C$140,$C28,헤몬팜일일!AK$1:AK$140) -> #REF! | AE28: =SUMIF(헤몬팜일일!$C$1:$C$140,$C28,헤몬팜일일!AL$1:AL$140) -> 2600.64
C29: 시거잭 | D29: =AC29/O29 -> -0.43335976 | E29: =AB29/O29 -> 0.39776706 | F29: =(S29+U29)/O29 -> 0.83112682 | G29: =H29/AG29 -> #DIV/0! | H29: =SUMIF(헤몬팜일일!$C$1:$C$140,$C29,헤몬팜일일!O$1:O$140) -> 91 | I29: =H29/7 -> 13 | J29: =SUMIF(헤몬팜일일!$C$1:$C$140,$C29,헤몬팜일일!P$1:P$140) -> 56 | K29: =SUMIF(헤몬팜일일!$C$1:$C$140,$C29,헤몬팜일일!Q$1:Q$140) -> 6 | L29: =SUMIF(헤몬팜일일!$C$1:$C$140,$C29,헤몬팜일일!S$1:S$140) -> 35 | M29: =SUMIF(헤몬팜일일!$C$1:$C$140,$C29,헤몬팜일일!T$1:T$140) -> 1490060 | N29: =SUMIF(헤몬팜일일!$C$1:$C$140,$C29,헤몬팜일일!U$1:U$140) -> 573100 | O29: =SUMIF(헤몬팜일일!$C$1:$C$140,$C29,헤몬팜일일!V$1:V$140) -> 916960 | P29: =O29/J29 -> 16374.286 | Q29: =R29/J29 -> 5126.3245 | R29: =SUMIF(헤몬팜일일!$C$1:$C$140,$C29,헤몬팜일일!Y$1:Y$140) -> 287074.17 | S29: =SUMIF(헤몬팜일일!$C$1:$C$140,$C29,헤몬팜일일!Z$1:Z$140) -> 416749.3 | T29: =SUMIF(헤몬팜일일!$C$1:$C$140,$C29,헤몬팜일일!AA$1:AA$140) -> 378863 | U29: =SUMIF(헤몬팜일일!$C$1:$C$140,$C29,헤몬팜일일!AB$1:AB$140) -> 345360.75 | V29: =SUMIF(헤몬팜일일!$C$1:$C$140,$C29,헤몬팜일일!AC$1:AC$140) -> 13860 | W29: 0.1 | X29: =SUMIF(헤몬팜일일!$C$1:$C$140,$C29,헤몬팜일일!AE$1:AE$140) -> 162400 | Y29: =W29+(X29/O29) -> 0.27710696 | Z29: =SUMIF(헤몬팜일일!$C$1:$C$140,$C29,헤몬팜일일!AG$1:AG$140) -> 233923.09 | AA29: =SUMIF(헤몬팜일일!$C$1:$C$140,$C29,헤몬팜일일!AH$1:AH$140) -> 31226.254 | AB29: =SUMIF(헤몬팜일일!$C$1:$C$140,$C29,헤몬팜일일!AJ$1:AJ$140) -> 364736.48 | AC29: =SUMIF(헤몬팜일일!$C$1:$C$140,$C29,헤몬팜일일!AK$1:AK$140) -> -397373.57 | AD29: =SUMIF(헤몬팜일일!$C$1:$C$140,$C29,헤몬팜일일!AK$1:AK$140) -> -397373.57 | AE29: =SUMIF(헤몬팜일일!$C$1:$C$140,$C29,헤몬팜일일!AL$1:AL$140) -> 42.525
C30: 뉴 고압세척기 배터리 1개 | D30: =AC30/O30 -> #REF! | E30: =AB30/O30 -> #REF! | F30: =(S30+U30)/O30 -> 0.25633333 | G30: =H30/AG30 -> #DIV/0! | H30: =SUMIF(헤몬팜일일!$C$1:$C$140,$C30,헤몬팜일일!O$1:O$140) -> 33 | I30: =H30/7 -> 4.7142857 | J30: =SUMIF(헤몬팜일일!$C$1:$C$140,$C30,헤몬팜일일!P$1:P$140) -> 33 | K30: =SUMIF(헤몬팜일일!$C$1:$C$140,$C30,헤몬팜일일!Q$1:Q$140) -> 3 | L30: =SUMIF(헤몬팜일일!$C$1:$C$140,$C30,헤몬팜일일!S$1:S$140) -> 0 | M30: =SUMIF(헤몬팜일일!$C$1:$C$140,$C30,헤몬팜일일!T$1:T$140) -> 1313400 | N30: =SUMIF(헤몬팜일일!$C$1:$C$140,$C30,헤몬팜일일!U$1:U$140) -> 0 | O30: =SUMIF(헤몬팜일일!$C$1:$C$140,$C30,헤몬팜일일!V$1:V$140) -> 1313400 | P30: =O30/J30 -> 39800 | Q30: =R30/J30 -> #REF! | R30: =SUMIF(헤몬팜일일!$C$1:$C$140,$C30,헤몬팜일일!Y$1:Y$140) -> #REF! | S30: =SUMIF(헤몬팜일일!$C$1:$C$140,$C30,헤몬팜일일!Z$1:Z$140) -> 336668.2 | T30: =SUMIF(헤몬팜일일!$C$1:$C$140,$C30,헤몬팜일일!AA$1:AA$140) -> 306062 | U30: =SUMIF(헤몬팜일일!$C$1:$C$140,$C30,헤몬팜일일!AB$1:AB$140) -> 0 | V30: =SUMIF(헤몬팜일일!$C$1:$C$140,$C30,헤몬팜일일!AC$1:AC$140) -> 6930 | W30: 0.1 | X30: =SUMIF(헤몬팜일일!$C$1:$C$140,$C30,헤몬팜일일!AE$1:AE$140) -> 136950 | Y30: =W30+(X30/O30) -> 0.20427136 | Z30: =SUMIF(헤몬팜일일!$C$1:$C$140,$C30,헤몬팜일일!AG$1:AG$140) -> 242022.21 | AA30: =SUMIF(헤몬팜일일!$C$1:$C$140,$C30,헤몬팜일일!AH$1:AH$140) -> #REF! | AB30: =SUMIF(헤몬팜일일!$C$1:$C$140,$C30,헤몬팜일일!AJ$1:AJ$140) -> #REF! | AC30: =SUMIF(헤몬팜일일!$C$1:$C$140,$C30,헤몬팜일일!AK$1:AK$140) -> #REF! | AD30: =SUMIF(헤몬팜일일!$C$1:$C$140,$C30,헤몬팜일일!AK$1:AK$140) -> #REF! | AE30: =SUMIF(헤몬팜일일!$C$1:$C$140,$C30,헤몬팜일일!AL$1:AL$140) -> 1234.926
C31: 뉴 고압세척기 | D31: =AC31/O31 -> #REF! | E31: =AB31/O31 -> #REF! | F31: =(S31+U31)/O31 -> 0.33643956 | G31: =H31/AG31 -> #DIV/0! | H31: =SUMIF(헤몬팜일일!$C$1:$C$140,$C31,헤몬팜일일!O$1:O$140) -> 7 | I31: =H31/7 -> 1 | J31: =SUMIF(헤몬팜일일!$C$1:$C$140,$C31,헤몬팜일일!P$1:P$140) -> 7 | K31: =SUMIF(헤몬팜일일!$C$1:$C$140,$C31,헤몬팜일일!Q$1:Q$140) -> 2 | L31: =SUMIF(헤몬팜일일!$C$1:$C$140,$C31,헤몬팜일일!S$1:S$140) -> 0 | M31: =SUMIF(헤몬팜일일!$C$1:$C$140,$C31,헤몬팜일일!T$1:T$140) -> 300300 | N31: =SUMIF(헤몬팜일일!$C$1:$C$140,$C31,헤몬팜일일!U$1:U$140) -> 0 | O31: =SUMIF(헤몬팜일일!$C$1:$C$140,$C31,헤몬팜일일!V$1:V$140) -> 300300 | P31: =O31/J31 -> 42900 | Q31: =R31/J31 -> #REF! | R31: =SUMIF(헤몬팜일일!$C$1:$C$140,$C31,헤몬팜일일!Y$1:Y$140) -> #REF! | S31: =SUMIF(헤몬팜일일!$C$1:$C$140,$C31,헤몬팜일일!Z$1:Z$140) -> 101032.8 | T31: =SUMIF(헤몬팜일일!$C$1:$C$140,$C31,헤몬팜일일!AA$1:AA$140) -> 91848 | U31: =SUMIF(헤몬팜일일!$C$1:$C$140,$C31,헤몬팜일일!AB$1:AB$140) -> 0 | V31: =SUMIF(헤몬팜일일!$C$1:$C$140,$C31,헤몬팜일일!AC$1:AC$140) -> 4620 | W31: 0.1 | X31: =SUMIF(헤몬팜일일!$C$1:$C$140,$C31,헤몬팜일일!AE$1:AE$140) -> 13300 | Y31: =W31+(X31/O31) -> 0.14428904 | Z31: =SUMIF(헤몬팜일일!$C$1:$C$140,$C31,헤몬팜일일!AG$1:AG$140) -> 36723.49 | AA31: =SUMIF(헤몬팜일일!$C$1:$C$140,$C31,헤몬팜일일!AH$1:AH$140) -> #REF! | AB31: =SUMIF(헤몬팜일일!$C$1:$C$140,$C31,헤몬팜일일!AJ$1:AJ$140) -> #REF! | AC31: =SUMIF(헤몬팜일일!$C$1:$C$140,$C31,헤몬팜일일!AK$1:AK$140) -> #REF! | AD31: =SUMIF(헤몬팜일일!$C$1:$C$140,$C31,헤몬팜일일!AK$1:AK$140) -> #REF! | AE31: =SUMIF(헤몬팜일일!$C$1:$C$140,$C31,헤몬팜일일!AL$1:AL$140) -> 1234.926
C32: 모기지옥 | D32: =AC32/O32 -> 0.32140589 | E32: =AB32/O32 -> 0.36298878 | F32: =(S32+U32)/O32 -> 0.041582884 | G32: =H32/AG32 -> #DIV/0! | H32: =SUMIF(헤몬팜일일!$C$1:$C$140,$C32,헤몬팜일일!O$1:O$140) -> 58 | I32: =H32/7 -> 8.2857143 | J32: =SUMIF(헤몬팜일일!$C$1:$C$140,$C32,헤몬팜일일!P$1:P$140) -> 58 | K32: =SUMIF(헤몬팜일일!$C$1:$C$140,$C32,헤몬팜일일!Q$1:Q$140) -> 5 | L32: =SUMIF(헤몬팜일일!$C$1:$C$140,$C32,헤몬팜일일!S$1:S$140) -> 0 | M32: =SUMIF(헤몬팜일일!$C$1:$C$140,$C32,헤몬팜일일!T$1:T$140) -> 1113600 | N32: =SUMIF(헤몬팜일일!$C$1:$C$140,$C32,헤몬팜일일!U$1:U$140) -> 0 | O32: =SUMIF(헤몬팜일일!$C$1:$C$140,$C32,헤몬팜일일!V$1:V$140) -> 1113600 | P32: =O32/J32 -> 19200 | Q32: =R32/J32 -> 6771.4352 | R32: =SUMIF(헤몬팜일일!$C$1:$C$140,$C32,헤몬팜일일!Y$1:Y$140) -> 392743.24 | S32: =SUMIF(헤몬팜일일!$C$1:$C$140,$C32,헤몬팜일일!Z$1:Z$140) -> 46306.7 | T32: =SUMIF(헤몬팜일일!$C$1:$C$140,$C32,헤몬팜일일!AA$1:AA$140) -> 42097 | U32: =SUMIF(헤몬팜일일!$C$1:$C$140,$C32,헤몬팜일일!AB$1:AB$140) -> 0 | V32: =SUMIF(헤몬팜일일!$C$1:$C$140,$C32,헤몬팜일일!AC$1:AC$140) -> 11550 | W32: 0.1 | X32: =SUMIF(헤몬팜일일!$C$1:$C$140,$C32,헤몬팜일일!AE$1:AE$140) -> 194300 | Y32: =W32+(X32/O32) -> 0.27447917 | Z32: =SUMIF(헤몬팜일일!$C$1:$C$140,$C32,헤몬팜일일!AG$1:AG$140) -> 283388.21 | AA32: =SUMIF(헤몬팜일일!$C$1:$C$140,$C32,헤몬팜일일!AH$1:AH$140) -> 33244.246 | AB32: =SUMIF(헤몬팜일일!$C$1:$C$140,$C32,헤몬팜일일!AJ$1:AJ$140) -> 404224.3 | AC32: =SUMIF(헤몬팜일일!$C$1:$C$140,$C32,헤몬팜일일!AK$1:AK$140) -> 357917.6 | AD32: =SUMIF(헤몬팜일일!$C$1:$C$140,$C32,헤몬팜일일!AK$1:AK$140) -> 357917.6 | AE32: =SUMIF(헤몬팜일일!$C$1:$C$140,$C32,헤몬팜일일!AL$1:AL$140) -> 457.38
C33: 컷소 배터리 1개 | D33: =AC33/O33 -> #REF! | E33: =AB33/O33 -> #REF! | F33: =(S33+U33)/O33 -> 0.46436694 | G33: =H33/AG33 -> #DIV/0! | H33: =SUMIF(헤몬팜일일!$C$1:$C$140,$C33,헤몬팜일일!O$1:O$140) -> 12 | I33: =H33/7 -> 1.7142857 | J33: =SUMIF(헤몬팜일일!$C$1:$C$140,$C33,헤몬팜일일!P$1:P$140) -> 12 | K33: =SUMIF(헤몬팜일일!$C$1:$C$140,$C33,헤몬팜일일!Q$1:Q$140) -> 4 | L33: =SUMIF(헤몬팜일일!$C$1:$C$140,$C33,헤몬팜일일!S$1:S$140) -> 0 | M33: =SUMIF(헤몬팜일일!$C$1:$C$140,$C33,헤몬팜일일!T$1:T$140) -> 657600 | N33: =SUMIF(헤몬팜일일!$C$1:$C$140,$C33,헤몬팜일일!U$1:U$140) -> 0 | O33: =SUMIF(헤몬팜일일!$C$1:$C$140,$C33,헤몬팜일일!V$1:V$140) -> 657600 | P33: =O33/J33 -> 54800 | Q33: =R33/J33 -> #REF! | R33: =SUMIF(헤몬팜일일!$C$1:$C$140,$C33,헤몬팜일일!Y$1:Y$140) -> #REF! | S33: =SUMIF(헤몬팜일일!$C$1:$C$140,$C33,헤몬팜일일!Z$1:Z$140) -> 305367.7 | T33: =SUMIF(헤몬팜일일!$C$1:$C$140,$C33,헤몬팜일일!AA$1:AA$140) -> 277607 | U33: =SUMIF(헤몬팜일일!$C$1:$C$140,$C33,헤몬팜일일!AB$1:AB$140) -> 0 | V33: =SUMIF(헤몬팜일일!$C$1:$C$140,$C33,헤몬팜일일!AC$1:AC$140) -> 9240 | W33: 0.1 | X33: =SUMIF(헤몬팜일일!$C$1:$C$140,$C33,헤몬팜일일!AE$1:AE$140) -> 57900 | Y33: =W33+(X33/O33) -> 0.18804745 | Z33: =SUMIF(헤몬팜일일!$C$1:$C$140,$C33,헤몬팜일일!AG$1:AG$140) -> 109192.92 | AA33: =SUMIF(헤몬팜일일!$C$1:$C$140,$C33,헤몬팜일일!AH$1:AH$140) -> #REF! | AB33: =SUMIF(헤몬팜일일!$C$1:$C$140,$C33,헤몬팜일일!AJ$1:AJ$140) -> #REF! | AC33: =SUMIF(헤몬팜일일!$C$1:$C$140,$C33,헤몬팜일일!AK$1:AK$140) -> #REF! | AD33: =SUMIF(헤몬팜일일!$C$1:$C$140,$C33,헤몬팜일일!AK$1:AK$140) -> #REF! | AE33: =SUMIF(헤몬팜일일!$C$1:$C$140,$C33,헤몬팜일일!AL$1:AL$140) -> 1270.08
C34: 컷소 배터리 2개 | D34: =AC34/O34 -> #REF! | E34: =AB34/O34 -> #REF! | F34: =(S34+U34)/O34 -> 0.20648078 | G34: =H34/AG34 -> #DIV/0! | H34: =SUMIF(헤몬팜일일!$C$1:$C$140,$C34,헤몬팜일일!O$1:O$140) -> 28 | I34: =H34/7 -> 4 | J34: =SUMIF(헤몬팜일일!$C$1:$C$140,$C34,헤몬팜일일!P$1:P$140) -> 28 | K34: =SUMIF(헤몬팜일일!$C$1:$C$140,$C34,헤몬팜일일!Q$1:Q$140) -> 3 | L34: =SUMIF(헤몬팜일일!$C$1:$C$140,$C34,헤몬팜일일!S$1:S$140) -> 0 | M34: =SUMIF(헤몬팜일일!$C$1:$C$140,$C34,헤몬팜일일!T$1:T$140) -> 1733170 | N34: =SUMIF(헤몬팜일일!$C$1:$C$140,$C34,헤몬팜일일!U$1:U$140) -> 0 | O34: =SUMIF(헤몬팜일일!$C$1:$C$140,$C34,헤몬팜일일!V$1:V$140) -> 1733170 | P34: =O34/J34 -> 61898.929 | Q34: =R34/J34 -> #REF! | R34: =SUMIF(헤몬팜일일!$C$1:$C$140,$C34,헤몬팜일일!Y$1:Y$140) -> #REF! | S34: =SUMIF(헤몬팜일일!$C$1:$C$140,$C34,헤몬팜일일!Z$1:Z$140) -> 357866.3 | T34: =SUMIF(헤몬팜일일!$C$1:$C$140,$C34,헤몬팜일일!AA$1:AA$140) -> 325333 | U34: =SUMIF(헤몬팜일일!$C$1:$C$140,$C34,헤몬팜일일!AB$1:AB$140) -> 0 | V34: =SUMIF(헤몬팜일일!$C$1:$C$140,$C34,헤몬팜일일!AC$1:AC$140) -> 6930 | W34: 0.1 | X34: =SUMIF(헤몬팜일일!$C$1:$C$140,$C34,헤몬팜일일!AE$1:AE$140) -> 135100 | Y34: =W34+(X34/O34) -> 0.17794965 | Z34: =SUMIF(헤몬팜일일!$C$1:$C$140,$C34,헤몬팜일일!AG$1:AG$140) -> 270287.44 | AA34: =SUMIF(헤몬팜일일!$C$1:$C$140,$C34,헤몬팜일일!AH$1:AH$140) -> #REF! | AB34: =SUMIF(헤몬팜일일!$C$1:$C$140,$C34,헤몬팜일일!AJ$1:AJ$140) -> #REF! | AC34: =SUMIF(헤몬팜일일!$C$1:$C$140,$C34,헤몬팜일일!AK$1:AK$140) -> #REF! | AD34: =SUMIF(헤몬팜일일!$C$1:$C$140,$C34,헤몬팜일일!AK$1:AK$140) -> #REF! | AE34: =SUMIF(헤몬팜일일!$C$1:$C$140,$C34,헤몬팜일일!AL$1:AL$140) -> 1270.08
... C39: 강아지바리깡 2개 | D39: =AC39/O39 -> -3.6761922 | E39: =AB39/O39 -> 0.41173023 | F39: =(S39+U39)/O39 -> 4.0879224 | G39: =H39/AG39 -> #DIV/0! | H39: =SUMIF(헤몬팜일일!$C$1:$C$140,$C39,헤몬팜일일!O$1:O$140) -> 1 | I39: =H39/7 -> 0.14285714 | J39: =SUMIF(헤몬팜일일!$C$1:$C$140,$C39,헤몬팜일일!P$1:P$140) -> 1 | K39: =SUMIF(헤몬팜일일!$C$1:$C$140,$C39,헤몬팜일일!Q$1:Q$140) -> 4 | L39: =SUMIF(헤몬팜일일!$C$1:$C$140,$C39,헤몬팜일일!S$1:S$140) -> 0 | M39: =SUMIF(헤몬팜일일!$C$1:$C$140,$C39,헤몬팜일일!T$1:T$140) -> 39710 | N39: =SUMIF(헤몬팜일일!$C$1:$C$140,$C39,헤몬팜일일!U$1:U$140) -> 0 | O39: =SUMIF(헤몬팜일일!$C$1:$C$140,$C39,헤몬팜일일!V$1:V$140) -> 39710 | P39: =O39/J39 -> 39710 | Q39: =R39/J39 -> 14113.035 | R39: =SUMIF(헤몬팜일일!$C$1:$C$140,$C39,헤몬팜일일!Y$1:Y$140) -> 14113.035 | S39: =SUMIF(헤몬팜일일!$C$1:$C$140,$C39,헤몬팜일일!Z$1:Z$140) -> 162331.4 | T39: =SUMIF(헤몬팜일일!$C$1:$C$140,$C39,헤몬팜일일!AA$1:AA$140) -> 147574 | U39: =SUMIF(헤몬팜일일!$C$1:$C$140,$C39,헤몬팜일일!AB$1:AB$140) -> 0 | V39: =SUMIF(헤몬팜일일!$C$1:$C$140,$C39,헤몬팜일일!AC$1:AC$140) -> 9240 | W39: 0.1 | X39: =SUMIF(헤몬팜일일!$C$1:$C$140,$C39,헤몬팜일일!AE$1:AE$140) -> 3550 | Y39: =W39+(X39/O39) -> 0.18939814 | Z39: =SUMIF(헤몬팜일일!$C$1:$C$140,$C39,헤몬팜일일!AG$1:AG$140) -> 7838.8 | AA39: =SUMIF(헤몬팜일일!$C$1:$C$140,$C39,헤몬팜일일!AH$1:AH$140) -> 1408.3581 | AB39: =SUMIF(헤몬팜일일!$C$1:$C$140,$C39,헤몬팜일일!AJ$1:AJ$140) -> 16349.807 | AC39: =SUMIF(헤몬팜일일!$C$1:$C$140,$C39,헤몬팜일일!AK$1:AK$140) -> -145981.59 | AD39: =SUMIF(헤몬팜일일!$C$1:$C$140,$C39,헤몬팜일일!AK$1:AK$140) -> -145981.59 | AE39: =SUMIF(헤몬팜일일!$C$1:$C$140,$C39,헤몬팜일일!AL$1:AL$140) -> 452.088
D40: =AC40/P40 -> #REF! | E40: =AB40/P40 -> #REF! | F40: =T40/P40 -> #DIV/0! | H40: =SUM(H23:H39) -> 1770 | I40: =SUM(I23:I39) -> 252.85714 | J40: =SUM(J23:J39) -> 1723 | K40: =SUM(K23:K39) -> 189 | L40: =SUM(L23:L39) -> 47 | M40: =SUM(M23:M39) -> 47945280 | N40: =SUM(N23:N39) -> 823900 | O40: =SUM(O23:O39) -> 47121380 | Q40: =SUM(Q23:Q39) -> #REF! | R40: =SUM(R23:R39) -> #REF! | S40: =SUM(S23:S39) -> 11994522 | T40: =SUM(T23:T39) -> 10904111 | U40: =SUM(U23:U39) -> 555048.75 | V40: =SUM(V23:V39) -> 424860 | W40: 0.09 | X40: =SUM(X23:X39) -> 5220350 | Z40: =SUM(Z23:Z39) -> 9762589.9 | AA40: =SUM(AA23:AA39) -> #REF! | AB40: =SUM(AB23:AB39) -> #REF! | AC40: =SUM(AC23:AC39) -> #REF!
C42: 10/6~10/12 | D42: 이윤율 | E42: 마진율 | F42: 광고비율 | G42: 전환율 | H42: 판매수 | I42: 일판매 | J42: 순판매개수 | K42: 취소개수 | L42: 가구매 | M42: 매출 | N42: 가구매금액 | O42: 순매출 | P42: 판매가 | Q42: 입고가 | R42: 입고판매가 | S42: 광고비1.1 | T42: 광고비 | U42: 가구매비용 | V42: 반품회수비 | W42: 수수료 | X42: 택배비 | Y42: 판매수수료 | Z42: 수수료 | AA42: 부가세 | AB42: 판매마진 | AC42: 순이익 | AD42: 노출수 | AE42: 클릭수
C43: 쉐이버 | D43: =AC43/O43 -> 0.2213428 | E43: =AB43/O43 -> 0.4227075 | F43: =(S43+U43)/O43 -> 0.2013647 | G43: =H43/AG43 -> #DIV/0! | H43: =SUMIF(헤몬팜일일!$C$142:$C$240,$C43,헤몬팜일일!O$142:O$240) -> 1311 | I43: =H43/7 -> 187.28571 | J43: =SUMIF(헤몬팜일일!$C$142:$C$240,$C43,헤몬팜일일!P$142:P$240) -> 1311 | K43: =SUMIF(헤몬팜일일!$C$142:$C$240,$C43,헤몬팜일일!Q$142:Q$240) -> 107 | L43: =SUMIF(헤몬팜일일!$C$142:$C$240,$C43,헤몬팜일일!S$142:S$240) -> 0 | M43: =SUMIF(헤몬팜일일!$C$142:$C$240,$C43,헤몬팜일일!T$142:T$240) -> 36576900 | N43: =SUMIF(헤몬팜일일!$C$142:$C$240,$C43,헤몬팜일일!U$142:U$240) -> 0 | O43: =SUMIF(헤몬팜일일!$C$142:$C$240,$C43,헤몬팜일일!V$142:V$240) -> 36576900 | P43: =O43/J43 -> 27900 | Q43: =R43/J43 -> 9245.0616 | R43: =SUMIF(헤몬팜일일!$C$142:$C$240,$C43,헤몬팜일일!Y$142:Y$240) -> 12120276 | S43: =SUMIF(헤몬팜일일!$C$142:$C$240,$C43,헤몬팜일일!Z$142:Z$240) -> 7365296.4 | T43: =SUMIF(헤몬팜일일!$C$142:$C$240,$C43,헤몬팜일일!AA$142:AA$240) -> 6695724 | U43: =SUMIF(헤몬팜일일!$C$142:$C$240,$C43,헤몬팜일일!AB$142:AB$240) -> 0 | V43: =SUMIF(헤몬팜일일!$C$142:$C$240,$C43,헤몬팜일일!AC$142:AC$240) -> 232404 | W43: 0.1 | X43: =SUMIF(헤몬팜일일!$C$142:$C$240,$C43,헤몬팜일일!AE$142:AE$240) -> 3998550 | Y43: =W43+(X43/O43) -> 0.209319 | Z43: =SUMIF(헤몬팜일일!$C$142:$C$240,$C43,헤몬팜일일!AG$142:AG$240) -> 7656240.2 | AA43: =SUMIF(헤몬팜일일!$C$142:$C$240,$C43,헤몬팜일일!AH$142:AH$240) -> 1339054.2 | AB43: =SUMIF(헤몬팜일일!$C$142:$C$240,$C43,헤몬팜일일!AJ$142:AJ$240) -> 15461330 | AC43: =SUMIF(헤몬팜일일!$C$142:$C$240,$C43,헤몬팜일일!AK$142:AK$240) -> 8096033.5 | AD43: =SUMIF(헤몬팜일일!$C$1:$C$140,$C43,헤몬팜일일!AK$1:AK$140) -> 4758730.6 | AE43: =SUMIF(헤몬팜일일!$C$1:$C$140,$C43,헤몬팜일일!AL$1:AL$140) -> 452.088
C44: 일자면도기 | D44: =AC44/O44 -> 0.22436758 | E44: =AB44/O44 -> 0.40985112 | F44: =(S44+U44)/O44 -> 0.18548354 | G44: =H44/AG44 -> #DIV/0! | H44: =SUMIF(헤몬팜일일!$C$142:$C$240,$C44,헤몬팜일일!O$142:O$240) -> 17 | I44: =H44/7 -> 2.4285714 | J44: =SUMIF(헤몬팜일일!$C$142:$C$240,$C44,헤몬팜일일!P$142:P$240) -> 17 | K44: =SUMIF(헤몬팜일일!$C$142:$C$240,$C44,헤몬팜일일!Q$142:Q$240) -> 1 | L44: =SUMIF(헤몬팜일일!$C$142:$C$240,$C44,헤몬팜일일!S$142:S$240) -> 0 | M44: =SUMIF(헤몬팜일일!$C$142:$C$240,$C44,헤몬팜일일!T$142:T$240) -> 385900 | N44: =SUMIF(헤몬팜일일!$C$142:$C$240,$C44,헤몬팜일일!U$142:U$240) -> 0 | O44: =SUMIF(헤몬팜일일!$C$142:$C$240,$C44,헤몬팜일일!V$142:V$240) -> 385900 | P44: =O44/J44 -> 22700 | Q44: =R44/J44 -> 7377.328 | R44: =SUMIF(헤몬팜일일!$C$142:$C$240,$C44,헤몬팜일일!Y$142:Y$240) -> 125414.58 | S44: =SUMIF(헤몬팜일일!$C$142:$C$240,$C44,헤몬팜일일!Z$142:Z$240) -> 71578.1 | T44: =SUMIF(헤몬팜일일!$C$142:$C$240,$C44,헤몬팜일일!AA$142:AA$240) -> 65071 | U44: =SUMIF(헤몬팜일일!$C$142:$C$240,$C44,헤몬팜일일!AB$142:AB$240) -> 0 | V44: =SUMIF(헤몬팜일일!$C$142:$C$240,$C44,헤몬팜일일!AC$142:AC$240) -> 2172 | W44: 0.1 | X44: =SUMIF(헤몬팜일일!$C$142:$C$240,$C44,헤몬팜일일!AE$142:AE$240) -> 50150 | Y44: =W44+(X44/O44) -> 0.22995595 | Z44: =SUMIF(헤몬팜일일!$C$142:$C$240,$C44,헤몬팜일일!AG$142:AG$240) -> 88740.15 | AA44: =SUMIF(헤몬팜일일!$C$142:$C$240,$C44,헤몬팜일일!AH$142:AH$240) -> 13583.726 | AB44: =SUMIF(헤몬팜일일!$C$142:$C$240,$C44,헤몬팜일일!AJ$142:AJ$240) -> 158161.55 | AC44: =SUMIF(헤몬팜일일!$C$142:$C$240,$C44,헤몬팜일일!AK$142:AK$240) -> 86583.448 | AD44: =SUMIF(헤몬팜일일!$C$1:$C$140,$C44,헤몬팜일일!AK$1:AK$140) -> 14171.434 | AE44: =SUMIF(헤몬팜일일!$C$1:$C$140,$C44,헤몬팜일일!AL$1:AL$140) -> 340.2
C45: 프라임 1개 | D45: =AC45/O45 -> #REF! | E45: =AB45/O45 -> #REF! | F45: =(S45+U45)/O45 -> 0.32792896 | G45: =H45/AG45 -> #DIV/0! | H45: =SUMIF(헤몬팜일일!$C$142:$C$240,$C45,헤몬팜일일!O$142:O$240) -> 26 | I45: =H45/7 -> 3.7142857 | J45: =SUMIF(헤몬팜일일!$C$142:$C$240,$C45,헤몬팜일일!P$142:P$240) -> 26 | K45: =SUMIF(헤몬팜일일!$C$142:$C$240,$C45,헤몬팜일일!Q$142:Q$240) -> 3 | L45: =SUMIF(헤몬팜일일!$C$142:$C$240,$C45,헤몬팜일일!S$142:S$240) -> 0 | M45: =SUMIF(헤몬팜일일!$C$142:$C$240,$C45,헤몬팜일일!T$142:T$240) -> 1190800 | N45: =SUMIF(헤몬팜일일!$C$142:$C$240,$C45,헤몬팜일일!U$142:U$240) -> 0 | O45: =SUMIF(헤몬팜일일!$C$142:$C$240,$C45,헤몬팜일일!V$142:V$240) -> 1190800 | P45: =O45/J45 -> 45800 | Q45: =R45/J45 -> #REF! | R45: =SUMIF(헤몬팜일일!$C$142:$C$240,$C45,헤몬팜일일!Y$142:Y$240) -> #REF! | S45: =SUMIF(헤몬팜일일!$C$142:$C$240,$C45,헤몬팜일일!Z$142:Z$240) -> 390497.8 | T45: =SUMIF(헤몬팜일일!$C$142:$C$240,$C45,헤몬팜일일!AA$142:AA$240) -> 354998 | U45: =SUMIF(헤몬팜일일!$C$142:$C$240,$C45,헤몬팜일일!AB$142:AB$240) -> 0 | V45: =SUMIF(헤몬팜일일!$C$142:$C$240,$C45,헤몬팜일일!AC$142:AC$240) -> 6930 | W45: 0.1 | X45: =SUMIF(헤몬팜일일!$C$142:$C$240,$C45,헤몬팜일일!AE$142:AE$240) -> 107900 | Y45: =W45+(X45/O45) -> 0.19061135 | Z45: =SUMIF(헤몬팜일일!$C$142:$C$240,$C45,헤몬팜일일!AG$142:AG$240) -> 238888.15 | AA45: =SUMIF(헤몬팜일일!$C$142:$C$240,$C45,헤몬팜일일!AH$142:AH$240) -> #REF! | AB45: =SUMIF(헤몬팜일일!$C$142:$C$240,$C45,헤몬팜일일!AJ$142:AJ$240) -> #REF! | AC45: =SUMIF(헤몬팜일일!$C$142:$C$240,$C45,헤몬팜일일!AK$142:AK$240) -> #REF! | AD45: =SUMIF(헤몬팜일일!$C$1:$C$140,$C45,헤몬팜일일!AK$1:AK$140) -> #REF! | AE45: =SUMIF(헤몬팜일일!$C$1:$C$140,$C45,헤몬팜일일!AL$1:AL$140) -> 1134
C46: 프라임 2개 | D46: =AC46/O46 -> #REF! | E46: =AB46/O46 -> #REF! | F46: =(S46+U46)/O46 -> 0.25075198 | G46: =H46/AG46 -> #DIV/0! | H46: =SUMIF(헤몬팜일일!$C$142:$C$240,$C46,헤몬팜일일!O$142:O$240) -> 14 | I46: =H46/7 -> 2 | J46: =SUMIF(헤몬팜일일!$C$142:$C$240,$C46,헤몬팜일일!P$142:P$240) -> 14 | K46: =SUMIF(헤몬팜일일!$C$142:$C$240,$C46,헤몬팜일일!Q$142:Q$240) -> 3 | L46: =SUMIF(헤몬팜일일!$C$142:$C$240,$C46,헤몬팜일일!S$142:S$240) -> 0 | M46: =SUMIF(헤몬팜일일!$C$142:$C$240,$C46,헤몬팜일일!T$142:T$240) -> 655200 | N46: =SUMIF(헤몬팜일일!$C$142:$C$240,$C46,헤몬팜일일!U$142:U$240) -> 0 | O46: =SUMIF(헤몬팜일일!$C$142:$C$240,$C46,헤몬팜일일!V$142:V$240) -> 655200 | P46: =O46/J46 -> 46800 | Q46: =R46/J46 -> #REF! | R46: =SUMIF(헤몬팜일일!$C$142:$C$240,$C46,헤몬팜일일!Y$142:Y$240) -> #REF! | S46: =SUMIF(헤몬팜일일!$C$142:$C$240,$C46,헤몬팜일일!Z$142:Z$240) -> 164292.7 | T46: =SUMIF(헤몬팜일일!$C$142:$C$240,$C46,헤몬팜일일!AA$142:AA$240) -> 149357 | U46: =SUMIF(헤몬팜일일!$C$142:$C$240,$C46,헤몬팜일일!AB$142:AB$240) -> 0 | V46: =SUMIF(헤몬팜일일!$C$142:$C$240,$C46,헤몬팜일일!AC$142:AC$240) -> 6930 | W46: 0.1 | X46: =SUMIF(헤몬팜일일!$C$142:$C$240,$C46,헤몬팜일일!AE$142:AE$240) -> 58100 | Y46: =W46+(X46/O46) -> 0.18867521 | Z46: =SUMIF(헤몬팜일일!$C$142:$C$240,$C46,헤몬팜일일!AG$142:AG$240) -> 130172.15 | AA46: =SUMIF(헤몬팜일일!$C$142:$C$240,$C46,헤몬팜일일!AH$142:AH$240) -> #REF! | AB46: =SUMIF(헤몬팜일일!$C$142:$C$240,$C46,헤몬팜일일!AJ$142:AJ$240) -> #REF! | AC46: =SUMIF(헤몬팜일일!$C$142:$C$240,$C46,헤몬팜일일!AK$142:AK$240) -> #REF! | AD46: =SUMIF(헤몬팜일일!$C$1:$C$140,$C46,헤몬팜일일!AK$1:AK$140) -> #REF! | AE46: =SUMIF(헤몬팜일일!$C$1:$C$140,$C46,헤몬팜일일!AL$1:AL$140) -> 1134
C47: 다밴다 1개 | D47: =AC47/O47 -> #REF! | E47: =AB47/O47 -> #REF! | F47: =(S47+U47)/O47 -> #DIV/0! | G47: =H47/AG47 -> #DIV/0! | H47: =SUMIF(헤몬팜일일!$C$142:$C$240,$C47,헤몬팜일일!O$142:O$240) -> 0 | I47: =H47/7 -> 0 | J47: =SUMIF(헤몬팜일일!$C$142:$C$240,$C47,헤몬팜일일!P$142:P$240) -> 0 | K47: =SUMIF(헤몬팜일일!$C$142:$C$240,$C47,헤몬팜일일!Q$142:Q$240) -> 0 | L47: =SUMIF(헤몬팜일일!$C$142:$C$240,$C47,헤몬팜일일!S$142:S$240) -> 0 | M47: =SUMIF(헤몬팜일일!$C$142:$C$240,$C47,헤몬팜일일!T$142:T$240) -> 0 | N47: =SUMIF(헤몬팜일일!$C$142:$C$240,$C47,헤몬팜일일!U$142:U$240) -> 0 | O47: =SUMIF(헤몬팜일일!$C$142:$C$240,$C47,헤몬팜일일!V$142:V$240) -> 0 | P47: =O47/J47 -> #DIV/0! | Q47: =R47/J47 -> #REF! | R47: =SUMIF(헤몬팜일일!$C$142:$C$240,$C47,헤몬팜일일!Y$142:Y$240) -> #REF! | S47: =SUMIF(헤몬팜일일!$C$142:$C$240,$C47,헤몬팜일일!Z$142:Z$240) -> 123216.5 | T47: =SUMIF(헤몬팜일일!$C$142:$C$240,$C47,헤몬팜일일!AA$142:AA$240) -> 112015 | U47: =SUMIF(헤몬팜일일!$C$142:$C$240,$C47,헤몬팜일일!AB$142:AB$240) -> 0 | V47: =SUMIF(헤몬팜일일!$C$142:$C$240,$C47,헤몬팜일일!AC$142:AC$240) -> 0 | W47: 0.1 | X47: =SUMIF(헤몬팜일일!$C$142:$C$240,$C47,헤몬팜일일!AE$142:AE$240) -> 0 | Y47: =W47+(X47/O47) -> #DIV/0! | Z47: =SUMIF(헤몬팜일일!$C$142:$C$240,$C47,헤몬팜일일!AG$142:AG$240) -> 0.06 | AA47: =SUMIF(헤몬팜일일!$C$142:$C$240,$C47,헤몬팜일일!AH$142:AH$240) -> #REF! | AB47: =SUMIF(헤몬팜일일!$C$142:$C$240,$C47,헤몬팜일일!AJ$142:AJ$240) -> #REF! | AC47: =SUMIF(헤몬팜일일!$C$142:$C$240,$C47,헤몬팜일일!AK$142:AK$240) -> #REF! | AD47: =SUMIF(헤몬팜일일!$C$1:$C$140,$C47,헤몬팜일일!AK$1:AK$140) -> #REF! | AE47: =SUMIF(헤몬팜일일!$C$1:$C$140,$C47,헤몬팜일일!AL$1:AL$140) -> 2600.64
C48: 다벤다 2개 | D48: =AC48/O48 -> #REF! | E48: =AB48/O48 -> #REF! | F48: =(S48+U48)/O48 -> 0.62449285 | G48: =H48/AG48 -> #DIV/0! | H48: =SUMIF(헤몬팜일일!$C$142:$C$240,$C48,헤몬팜일일!O$142:O$240) -> 9 | I48: =H48/7 -> 1.2857143 | J48: =SUMIF(헤몬팜일일!$C$142:$C$240,$C48,헤몬팜일일!P$142:P$240) -> 9 | K48: =SUMIF(헤몬팜일일!$C$142:$C$240,$C48,헤몬팜일일!Q$142:Q$240) -> 3 | L48: =SUMIF(헤몬팜일일!$C$142:$C$240,$C48,헤몬팜일일!S$142:S$240) -> 0 | M48: =SUMIF(헤몬팜일일!$C$142:$C$240,$C48,헤몬팜일일!T$142:T$240) -> 628020 | N48: =SUMIF(헤몬팜일일!$C$142:$C$240,$C48,헤몬팜일일!U$142:U$240) -> 0 | O48: =SUMIF(헤몬팜일일!$C$142:$C$240,$C48,헤몬팜일일!V$142:V$240) -> 628020 | P48: =O48/J48 -> 69780 | Q48: =R48/J48 -> #REF! | R48: =SUMIF(헤몬팜일일!$C$142:$C$240,$C48,헤몬팜일일!Y$142:Y$240) -> #REF! | S48: =SUMIF(헤몬팜일일!$C$142:$C$240,$C48,헤몬팜일일!Z$142:Z$240) -> 392194 | T48: =SUMIF(헤몬팜일일!$C$142:$C$240,$C48,헤몬팜일일!AA$142:AA$240) -> 356540 | U48: =SUMIF(헤몬팜일일!$C$142:$C$240,$C48,헤몬팜일일!AB$142:AB$240) -> 0 | V48: =SUMIF(헤몬팜일일!$C$142:$C$240,$C48,헤몬팜일일!AC$142:AC$240) -> 6930 | W48: 0.1 | X48: =SUMIF(헤몬팜일일!$C$142:$C$240,$C48,헤몬팜일일!AE$142:AE$240) -> 43425 | Y48: =W48+(X48/O48) -> 0.16914589 | Z48: =SUMIF(헤몬팜일일!$C$142:$C$240,$C48,헤몬팜일일!AG$142:AG$240) -> 111251.25 | AA48: =SUMIF(헤몬팜일일!$C$142:$C$240,$C48,헤몬팜일일!AH$142:AH$240) -> #REF! | AB48: =SUMIF(헤몬팜일일!$C$142:$C$240,$C48,헤몬팜일일!AJ$142:AJ$240) -> #REF! | AC48: =SUMIF(헤몬팜일일!$C$142:$C$240,$C48,헤몬팜일일!AK$142:AK$240) -> #REF! | AD48: =SUMIF(헤몬팜일일!$C$1:$C$140,$C48,헤몬팜일일!AK$1:AK$140) -> #REF! | AE48: =SUMIF(헤몬팜일일!$C$1:$C$140,$C48,헤몬팜일일!AL$1:AL$140) -> 2600.64
C49: 시거잭 | D49: =AC49/O49 -> -0.99445323 | E49: =AB49/O49 -> 0.3908083 | F49: =(S49+U49)/O49 -> 1.3852615 | G49: =H49/AG49 -> #DIV/0! | H49: =SUMIF(헤몬팜일일!$C$142:$C$240,$C49,헤몬팜일일!O$142:O$240) -> 39 | I49: =H49/7 -> 5.5714286 | J49: =SUMIF(헤몬팜일일!$C$142:$C$240,$C49,헤몬팜일일!P$142:P$240) -> 19 | K49: =SUMIF(헤몬팜일일!$C$142:$C$240,$C49,헤몬팜일일!Q$142:Q$240) -> 3 | L49: =SUMIF(헤몬팜일일!$C$142:$C$240,$C49,헤몬팜일일!S$142:S$240) -> 20 | M49: =SUMIF(헤몬팜일일!$C$142:$C$240,$C49,헤몬팜일일!T$142:T$240) -> 628680 | N49: =SUMIF(헤몬팜일일!$C$142:$C$240,$C49,헤몬팜일일!U$142:U$240) -> 322400 | O49: =SUMIF(헤몬팜일일!$C$142:$C$240,$C49,헤몬팜일일!V$142:V$240) -> 306280 | P49: =O49/J49 -> 16120 | Q49: =R49/J49 -> 5126.3245 | R49: =SUMIF(헤몬팜일일!$C$142:$C$240,$C49,헤몬팜일일!Y$142:Y$240) -> 97400.166 | S49: =SUMIF(헤몬팜일일!$C$142:$C$240,$C49,헤몬팜일일!Z$142:Z$240) -> 226928.9 | T49: =SUMIF(헤몬팜일일!$C$142:$C$240,$C49,헤몬팜일일!AA$142:AA$240) -> 206299 | U49: =SUMIF(헤몬팜일일!$C$142:$C$240,$C49,헤몬팜일일!AB$142:AB$240) -> 197349 | V49: =SUMIF(헤몬팜일일!$C$142:$C$240,$C49,헤몬팜일일!AC$142:AC$240) -> 6930 | W49: 0.1 | X49: =SUMIF(헤몬팜일일!$C$142:$C$240,$C49,헤몬팜일일!AE$142:AE$240) -> 55100 | Y49: =W49+(X49/O49) -> 0.27990074 | Z49: =SUMIF(헤몬팜일일!$C$142:$C$240,$C49,헤몬팜일일!AG$142:AG$240) -> 78989.99 | AA49: =SUMIF(헤몬팜일일!$C$142:$C$240,$C49,헤몬팜일일!AH$142:AH$240) -> 10193.078 | AB49: =SUMIF(헤몬팜일일!$C$142:$C$240,$C49,헤몬팜일일!AJ$142:AJ$240) -> 119696.77 | AC49: =SUMIF(헤몬팜일일!$C$142:$C$240,$C49,헤몬팜일일!AK$142:AK$240) -> -304581.13 | AD49: =SUMIF(헤몬팜일일!$C$1:$C$140,$C49,헤몬팜일일!AK$1:AK$140) -> -397373.57 | AE49: =SUMIF(헤몬팜일일!$C$1:$C$140,$C49,헤몬팜일일!AL$1:AL$140) -> 42.525
...

Sheet 헤몬팜일일
A1: 192
C2: 45929 | D2: 이윤율 | E2: 마진율 | F2: 광고비율 | G2: 전환율 | H2: 발주남은수량 | I2: 창고안전 | J2: 쿠팡안전 | K2: 가용재고 | L2: 창고재고 | M2: 쿠팡재고 | N2: 목표판매량 | O2: 판매수 | P2: 순판매개수 | Q2: 취소개수 | R2: 광고전환 | S2: 가구매 | T2: 매출 | U2: 가구매금액 | V2: 순매출 | W2: 판매가 | X2: 입고가 | Y2: 입고판매가 | Z2: 광고비1.1 | AA2: 광고비 | AB2: 가구매비용 | AC2: 반품회수비 | AD2: 수수료 | AE2: 택배비 | AF2: 판매수수료 | AG2: 수수료 | AH2: 부가세 | AI2: 도매가 | AJ2: 판매마진 | AK2: 순이익 | AL2: 1개당 한국 운임 물류비(KRW) | AM2: 1개당 물류비 (KRW) | AN2: 부자재값 | AO2: 노출수 | AP2: 클릭수
C3: 쉐이버 | D3: =AK3/V3 -> 0.1824153 | E3: =AJ3/V3 -> 0.42412315 | F3: =(Z3+AB3)/V3 -> 0.24170785 | G3: =R3/AP3 -> 0.069058903 | H3: 7410 | I3: =N3*7 -> 1400 | J3: =N3*14 -> 2800 | L3: 768 | M3: =2023+1320 -> 3343 | N3: 200 | O3: 142 | P3: =O3-S3 -> 142 | Q3: 12 | R3: 102 | T3: =W3*O3 -> 3976000 | U3: =W3*S3 -> 0 | V3: =T3-U3 -> 3976000 | W3: 28000 | X3: =SUMIF(헤몬팜마진!$B$7:$B$32,$C3,헤몬팜마진!$R$7:$R$32) -> 8850.86 | Y3: =AI3*P3 -> 1312798.7 | Z3: =AA3*1.1 -> 961030.4 | AA3: 873664 | AC3: =(1072+1100)*Q3 -> 26064 | AD3: 0.1 | AE3: =3050*(P3) -> 433100 | AF3: =AD3+(AE3/V3) -> 0.20892857 | AG3: =IFERROR(V3*AF3+3%,0) -> 830700.03 | AH3: =V3/1.1*10%-((AI3*P3)+AG3+(AN3*P3)+(AL3*P3))*10% -> 146187.57 | AI3: =SUMIF(헤몬팜마진!$B$7:$B$32,$C3,헤몬팜마진!$V$7:$V$32) -> 9245.0616 | AJ3: =V3-(Y3+AG3+AH3+(AN3*P3)) -> 1686313.6 | AK3: =AJ3-Z3-AB3 -> 725283.25 | AL3: =SUMIF(헤몬팜마진!$B$7:$B$32,$C3,헤몬팜마진!$T$7:$T$32) -> 64.584 | AM3: =SUMIF(헤몬팜마진!$B$7:$B$32,$C3,헤몬팜마진!$U$7:$U$32) -> 329.6176 | AO3: 524770 | AP3: 1477
C4: 일자면도기 | D4: =AK4/V4 -> #DIV/0! | E4: =AJ4/V4 -> #DIV/0! | F4: =(Z4+AB4)/V4 -> #DIV/0! | G4: =R4/AP4 -> 0 | H4: 1460 | I4: =N4*7 -> 140 | J4: =N4*14 -> 280 | L4: 325 | M4: 0 | N4: 20 | O4: 0 | P4: =O4-S4 -> 0 | Q4: 0 | R4: 0 | T4: =W4*O4 -> 0 | U4: =W4*S4 -> 0 | V4: =T4-U4 -> 0 | W4: 22700 | X4: =SUMIF(헤몬팜마진!$B$7:$B$32,$C4,헤몬팜마진!$R$7:$R$32) -> 7080.688 | Y4: =AI4*P4 -> 0 | Z4: =AA4*1.1 -> 4500.1 | AA4: 4091 | AC4: =(1072+1100)*Q4 -> 0 | AD4: 0.1 | AE4: =2950*(P4) -> 0 | AF4: =AD4+(AE4/V4) -> #DIV/0! | AG4: =IFERROR(V4*AF4+3%,0) -> 0 | AH4: =V4/1.1*10%-((AI4*P4)+AG4+(AN4*P4)+(AL4*P4))*10% -> 0 | AI4: =SUMIF(헤몬팜마진!$B$7:$B$32,$C4,헤몬팜마진!$V$7:$V$32) -> 7377.328 | AJ4: =V4-(Y4+AG4+AH4+(AN4*P4)) -> 0 | AK4: =AJ4-Z4-AB4 -> -4500.1 | AL4: =SUMIF(헤몬팜마진!$B$7:$B$32,$C4,헤몬팜마진!$T$7:$T$32) -> 48.6 | AM4: =SUMIF(헤몬팜마진!$B$7:$B$32,$C4,헤몬팜마진!$U$7:$U$32) -> 248.04 | AO4: 27292 | AP4: 12
C5: 프라임 1개 | D5: =AK5/V5 -> #REF! | E5: =AJ5/V5 -> #REF! | F5: =(Z5+AB5)/V5 -> 0.17656041 | G5: =R5/AP5 -> 0.041666667 | H5: 0 | I5: =N5*7 -> 105 | J5: =N5*14 -> 210 | L5: 430 | M5: =40+3+3 -> 46 | N5: 15 | O5: 3 | P5: =O5-S5 -> 3 | Q5: 1 | R5: 2 | T5: =W5*O5 -> 137400 | U5: =W5*S5 -> 0 | V5: =T5-U5 -> 137400 | W5: 45800 | X5: =SUMIF(헤몬팜마진!$B$7:$B$32,$C5,헤몬팜마진!$R$7:$R$32) -> 9990.4082 | Y5: =AI5*P5 -> #REF! | Z5: =AA5*1.1 -> 24259.4 | AA5: 22054 | AC5: =(1210+1100)*Q5 -> 2310 | AD5: 0.11 | AE5: =4150*(P5) -> 12450 | AF5: =AD5+(AE5/V5) -> 0.20061135 | AG5: =IFERROR(V5*AF5+3%,0) -> 27564.03 | AH5: =V5/1.1*10%-((AI5*P5)+AG5+(AN5*P5)+(AL5*P5))*10% -> #REF! | AI5: =SUMIF(헤몬팜마진!$B$7:$B$32,$C5,헤몬팜마진!$V$7:$V$32) -> #REF! | AJ5: =V5-(Y5+AG5+AH5+(AN5*P5)) -> #REF! | AK5: =AJ5-Z5-AB5 -> #REF! | AL5: =SUMIF(헤몬팜마진!$B$7:$B$32,$C5,헤몬팜마진!$T$7:$T$32) -> 162 | AM5: =SUMIF(헤몬팜마진!$B$7:$B$32,$C5,헤몬팜마진!$U$7:$U$32) -> 826.8 | AO5: 20297 | AP5: 48
C6: 프라임 2개 | D6: =AK6/V6 -> #REF! | E6: =AJ6/V6 -> #REF! | F6: =(Z6+AB6)/V6 -> 0.35419177 | G6: =R6/AP6 -> 0.057377049 | H6: 0 | I6: =N6*7 -> 105 | J6: =N6*14 -> 210 | M6: =20+2 -> 22 | N6: 15 | O6: 8 | P6: =O6-S6 -> 8 | Q6: 1 | R6: 7 | T6: =W6*O6 -> 374400 | U6: =W6*S6 -> 0 | V6: =T6-U6 -> 374400 | W6: 46800 | X6: =SUMIF(헤몬팜마진!$B$7:$B$32,$C6,헤몬팜마진!$R$7:$R$32) -> 9990.4082 | Y6: =AI6*P6 -> #REF! | Z6: =AA6*1.1 -> 132609.4 | AA6: 120554 | AC6: =(1210+1100)*Q6 -> 2310 | AD6: 0.11 | AE6: =4150*(P6) -> 33200 | AF6: =AD6+(AE6/V6) -> 0.19867521 | AG6: =IFERROR(V6*AF6+3%,0) -> 74384.03 | AH6: =V6/1.1*10%-((AI6*P6)+AG6+(AN6*P6)+(AL6*P6))*10% -> #REF! | AI6: =SUMIF(헤몬팜마진!$B$7:$B$32,$C6,헤몬팜마진!$V$7:$V$32) -> #REF! | AJ6: =V6-(Y6+AG6+AH6+(AN6*P6)) -> #REF! | AK6: =AJ6-Z6-AB6 -> #REF! | AL6: =SUMIF(헤몬팜마진!$B$7:$B$32,$C6,헤몬팜마진!$T$7:$T$32) -> 162 | AM6: =SUMIF(헤몬팜마진!$B$7:$B$32,$C6,헤몬팜마진!$U$7:$U$32) -> 826.8 | AO6: 83500 | AP6: 122
C7: 다밴다 1개 | D7: =AK7/V7 -> #REF! | E7: =AJ7/V7 -> #REF! | F7: =(Z7+AB7)/V7 -> 0.44699916 | G7: =R7/AP7 -> 0.010869565 | H7: 3504 | I7: =N7*7 -> 210 | J7: =N7*14 -> 420 | L7: 626 | M7: =30+13+6 -> 49 | N7: 30 | O7: 2 | P7: =O7-S7 -> 2 | Q7: 0 | R7: 1 | T7: =W7*O7 -> 119600 | U7: =W7*S7 -> 0 | V7: =T7-U7 -> 119600 | W7: 59800 | X7: =SUMIF(헤몬팜마진!$B$7:$B$32,$C7,헤몬팜마진!$R$7:$R$32) -> 13276.29 | Y7: =AI7*P7 -> #REF! | Z7: =AA7*1.1 -> 53461.1 | AA7: 48601 | AC7: =(1210+1100)*Q7 -> 0 | AD7: 0.108 | AE7: =4825*(P7) -> 9650 | AF7: =AD7+(AE7/V7) -> 0.18868562 | AG7: =IFERROR(V7*AF7+3%,0) -> 22566.83 | AH7: =V7/1.1*10%-((AI7*P7)+AG7+(AN7*P7)+(AL7*P7))*10% -> #REF! | AI7: =SUMIF(헤몬팜마진!$B$7:$B$32,$C7,헤몬팜마진!$V$7:$V$32) -> #REF! | AJ7: =V7-(Y7+AG7+AH7+(AN7*P7)) -> #REF! | AK7: =AJ7-Z7-AB7 -> #REF! | AL7: =SUMIF(헤몬팜마진!$B$7:$B$32,$C7,헤몬팜마진!$T$7:$T$32) -> 371.52 | AM7: =SUMIF(헤몬팜마진!$B$7:$B$32,$C7,헤몬팜마진!$U$7:$U$32) -> 1896.128 | AO7: 41677 | AP7: 92
C8: 다벤다 2개 | D8: =AK8/V8 -> #REF! | E8: =AJ8/V8 -> #REF! | F8: =(Z8+AB8)/V8 -> 0.33173008 | G8: =R8/AP8 -> 0.022222222 | H8: 0 | I8: =N8*7 -> 210 | J8: =N8*14 -> 420 | M8: =4+11+18+38+129 -> 200 | N8: 30 | O8: 4 | P8: =O8-S8 -> 4 | Q8: 0 | R8: 3 | T8: =W8*O8 -> 279120 | U8: =W8*S8 -> 0 | V8: =T8-U8 -> 279120 | W8: 69780 | X8: =SUMIF(헤몬팜마진!$B$7:$B$32,$C8,헤몬팜마진!$R$7:$R$32) -> 13276.29 | Y8: =AI8*P8 -> #REF! | Z8: =AA8*1.1 -> 92592.5 | AA8: 84175 | AC8: =(1210+1100)*Q8 -> 0 | AD8: 0.108 | AE8: =4825*(P8) -> 19300 | AF8: =AD8+(AE8/V8) -> 0.17714589 | AG8: =IFERROR(V8*AF8+3%,0) -> 49444.99 | AH8: =V8/1.1*10%-((AI8*P8)+AG8+(AN8*P8)+(AL8*P8))*10% -> #REF! | AI8: =SUMIF(헤몬팜마진!$B$7:$B$32,$C8,헤몬팜마진!$V$7:$V$32) -> #REF! | AJ8: =V8-(Y8+AG8+AH8+(AN8*P8)) -> #REF! | AK8: =AJ8-Z8-AB8 -> #REF! | AL8: =SUMIF(헤몬팜마진!$B$7:$B$32,$C8,헤몬팜마진!$T$7:$T$32) -> 371.52 | AM8: =SUMIF(헤몬팜마진!$B$7:$B$32,$C8,헤몬팜마진!$U$7:$U$32) -> 1896.128 | AO8: 83142 | AP8: 135
C9: 시거잭 | D9: =AK9/V9 -> -0.36675821 | E9: =AJ9/V9 -> 0.43536644 | F9: =(Z9+AB9)/V9 -> 0.80212465 | G9: =R9/AP9 -> 0.041958042 | H9: 500 | I9: =N9*7 -> 105 | J9: =N9*14 -> 210 | L9: 777 | M9: =115+100+1 -> 216 | N9: 15 | O9: 13 | P9: =O9-S9 -> 8 | Q9: 1 | R9: 6 | S9: 5 | T9: =W9*O9 -> 232700 | U9: =W9*S9 -> 89500 | V9: =T9-U9 -> 143200 | W9: 17900 | X9: =SUMIF(헤몬팜마진!$B$7:$B$32,$C9,헤몬팜마진!$R$7:$R$32) -> 5089.2445 | Y9: =AI9*P9 -> 41010.596 | Z9: =AA9*1.1 -> 65527 | AA9: 59570 | AB9: =((17890*0.015)+(17890*0.19)+2100+2200+1900)*5 -> 49337.25 | AC9: =(1210+1100)*Q9 -> 2310 | AD9: 0.078 | AE9: =2900*(P9) -> 23200 | AF9: =AD9+(AE9/V9) -> 0.24001117 | AG9: =IFERROR(V9*AF9+3%,0) -> 34369.63 | AH9: =V9/1.1*10%-((AI9*P9)+AG9+(AN9*P9)+(AL9*P9))*10% -> 5475.2992 | AI9: =SUMIF(헤몬팜마진!$B$7:$B$32,$C9,헤몬팜마진!$V$7:$V$32) -> 5126.3245 | AJ9: =V9-(Y9+AG9+AH9+(AN9*P9)) -> 62344.475 | AK9: =AJ9-Z9-AB9 -> -52519.775 | AL9: =SUMIF(헤몬팜마진!$B$7:$B$32,$C9,헤몬팜마진!$T$7:$T$32) -> 6.075 | AM9: =SUMIF(헤몬팜마진!$B$7:$B$32,$C9,헤몬팜마진!$U$7:$U$32) -> 31.005 | AO9: 42879 | AP9: 143
C10: 뉴 고압세척기 배터리 1개 | D10: =AK10/V10 -> #REF! | E10: =AJ10/V10 -> #REF! | F10: =(Z10+AB10)/V10 -> 0.12914264 | G10: =R10/AP10 -> 0.070588235 | H10: 0 | I10: =N10*7 -> 140 | J10: =N10*14 -> 280 | L10: 340 | M10: =101+42+48+31+19+10 -> 251 | N10: 20 | O10: 13 | P10: =O10-S10 -> 13 | Q10: 0 | R10: 12 | T10: =W10*O10 -> 517400 | U10: =W10*S10 -> 0 | V10: =T10-U10 -> 517400 | W10: 39800 | X10: =SUMIF(헤몬팜마진!$B$7:$B$32,$C10,헤몬팜마진!$R$7:$R$32) -> 7855.1382 | Y10: =AI10*P10 -> #REF! | Z10: =AA10*1.1 -> 66818.4 | AA10: 60744 | AC10: =(1210+1100)*Q10 -> 0 | AD10: 0.08 | AE10: =4150*(P10) -> 53950 | AF10: =AD10+(AE10/V10) -> 0.18427136 | AG10: =IFERROR(V10*AF10+3%,0) -> 95342.03 | AH10: =V10/1.1*10%-((AI10*P10)+AG10+(AN10*P10)+(AL10*P10))*10% -> #REF! | AI10: =SUMIF(헤몬팜마진!$B$7:$B$32,$C10,헤몬팜마진!$V$7:$V$32) -> #REF! | AJ10: =V10-(Y10+AG10+AH10+(AN10*P10)) -> #REF! | AK10: =AJ10-Z10-AB10 -> #REF! | AL10: =SUMIF(헤몬팜마진!$B$7:$B$32,$C10,헤몬팜마진!$T$7:$T$32) -> 176.418 | AM10: =SUMIF(헤몬팜마진!$B$7:$B$32,$C10,헤몬팜마진!$U$7:$U$32) -> 900.3852 | AO10: 66685 | AP10: 170
