Workbook

Sheet Sheet1
C1: 45945 | D1: 이윤율 | E1: 마진율 | F1: 광고비율 | G1: 전환율 | H1: 발주남은수량 | I1: 창고안전 | J1: 쿠팡안전 | K1: 창고재고 | L1: 쿠팡재고 | M1: 미포장분 | N1: 목표판매량 | O1: 판매수 | P1: 순판매개수 | Q1: 취소개수 | R1: 광고전환 | S1: 가구매 | T1: 매출 | U1: 가구매금액 | V1: 순매출 | W1: 판매가 | X1: 입고가 | Y1: 입고판매가 | Z1: 광고비1.1 | AA1: 광고비 | AB1: 가구매비용 | AC1: 반품회수비 | AD1: 수수료 | AE1: 택배비 | AF1: 판매수수료 | AG1: 수수료 | AH1: 부가세 | AI1: 도매가 | AJ1: 판매마진 | AK1: 순이익 | AL1: 1개당 한국 운임 물류비(KRW) | AM1: 1개당 물류비 (KRW) | AN1: 부자재값 | AO1: 노출수 | AP1: 클릭수
A2: ACC-SHA-BRD-001-BK | C2: 쉐이버 | D2: =AK2/V2 -> 0.20272171 | E2: =AJ2/V2 -> 0.42271098 | F2: =(Z2+AB2)/V2 -> 0.21998927 | G2: =R2/AP2 -> 0.070772555 | H2: 7410 | I2: =N2*7 -> 1400 | J2: =N2*14 -> 2800 | K2: 76 | L2: =1906+1320 -> 3226 | N2: 200 | O2: 169 | P2: =O2-S2 -> 169 | Q2: 16 | R2: 131 | T2: =W2*O2 -> 4715100 | U2: =W2*S2 -> 0 | V2: =T2-U2 -> 4715100 | W2: 27900 | X2: =SUMIF([1]헤몬팜마진!$B$7:$B$32,$C2,[1]헤몬팜마진!$R$7:$R$32) -> 8851 | Y2: =AI2*P2 -> 1562405 | Z2: =AA2*1.1 -> 1037271.4 | AA2: 942974 | AC2: =(1072+1100)*Q2 -> 34752 | AD2: 0.1 | AE2: =3050*(P2) -> 515450 | AF2: =AD2+(AE2/V2) -> 0.209319 | AG2: =IFERROR(V2*AF2+3%,0) -> 986960.03 | AH2: =V2/1.1*10%-((AI2*P2)+AG2+(AN2*P2)+(AL2*P2))*10% -> 172610.45 | AI2: =SUMIF([1]헤몬팜마진!$B$7:$B$32,$C2,[1]헤몬팜마진!$V$7:$V$32) -> 9245 | AJ2: =V2-(Y2+AG2+AH2+(AN2*P2)) -> 1993124.5 | AK2: =AJ2-Z2-AB2 -> 955853.12 | AL2: =SUMIF([1]헤몬팜마진!$B$7:$B$32,$C2,[1]헤몬팜마진!$T$7:$T$32) -> 65 | AM2: =SUMIF([1]헤몬팜마진!$B$7:$B$32,$C2,[1]헤몬팜마진!$U$7:$U$32) -> 330 | AO2: 364057 | AP2: 1851
A3: ACC-SHA-BRD-004-BK | C3: 일자면도기 | D3: =AK3/V3 -> #DIV/0! | E3: =AJ3/V3 -> #DIV/0! | F3: =(Z3+AB3)/V3 -> #DIV/0! | G3: =R3/AP3 -> 0 | H3: 1460 | I3: =N3*7 -> 140 | J3: =N3*14 -> 280 | K3: 325 | L3: 0 | N3: 20 | P3: =O3-S3 -> 0 | T3: =W3*O3 -> 0 | U3: =W3*S3 -> 0 | V3: =T3-U3 -> 0 | W3: 22700 | X3: =SUMIF([1]헤몬팜마진!$B$7:$B$32,$C3,[1]헤몬팜마진!$R$7:$R$32) -> 7081 | Y3: =AI3*P3 -> 0 | Z3: =AA3*1.1 -> 3245 | AA3: 2950 | AC3: =(1072+1100)*Q3 -> 0 | AD3: 0.1 | AE3: =2950*(P3) -> 0 | AF3: =AD3+(AE3/V3) -> #DIV/0! | AG3: =IFERROR(V3*AF3+3%,0) -> 0 | AH3: =V3/1.1*10%-((AI3*P3)+AG3+(AN3*P3)+(AL3*P3))*10% -> 0 | AI3: =SUMIF([1]헤몬팜마진!$B$7:$B$32,$C3,[1]헤몬팜마진!$V$7:$V$32) -> 7377 | AJ3: =V3-(Y3+AG3+AH3+(AN3*P3)) -> 0 | AK3: =AJ3-Z3-AB3 -> -3245 | AL3: =SUMIF([1]헤몬팜마진!$B$7:$B$32,$C3,[1]헤몬팜마진!$T$7:$T$32) -> 49 | AM3: =SUMIF([1]헤몬팜마진!$B$7:$B$32,$C3,[1]헤몬팜마진!$U$7:$U$32) -> 248 | AO3: 30840 | AP3: 9
A4: ACC-TOL-DRI-012-BL | C4: 프라임 1개 | D4: =AK4/V4 -> 0.30234253 | E4: =AJ4/V4 -> 0.38830905 | F4: =(Z4+AB4)/V4 -> 0.085966521 | G4: =R4/AP4 -> 0 | H4: 0 | I4: =N4*7 -> 105 | J4: =N4*14 -> 210 | K4: 430 | L4: =40+3+3 -> 46 | N4: 15 | O4: 3 | P4: =O4-S4 -> 3 | T4: =W4*O4 -> 137400 | U4: =W4*S4 -> 0 | V4: =T4-U4 -> 137400 | W4: 45800 | X4: =SUMIF([1]헤몬팜마진!$B$7:$B$32,$C4,[1]헤몬팜마진!$R$7:$R$32) -> 9990 | Y4: =AI4*P4 -> 51996 | Z4: =AA4*1.1 -> 11811.8 | AA4: 10738 | AC4: =(1210+1100)*Q4 -> 0 | AD4: 0.11 | AE4: =4150*(P4) -> 12450 | AF4: =AD4+(AE4/V4) -> 0.20061135 | AG4: =IFERROR(V4*AF4+3%,0) -> 27564.03 | AH4: =V4/1.1*10%-((AI4*P4)+AG4+(AN4*P4)+(AL4*P4))*10% -> 4486.3061 | AI4: =SUMIF([1]헤몬팜마진!$B$7:$B$32,$C4,[1]헤몬팜마진!$V$7:$V$32) -> 17332 | AJ4: =V4-(Y4+AG4+AH4+(AN4*P4)) -> 53353.664 | AK4: =AJ4-Z4-AB4 -> 41541.864 | AL4: =SUMIF([1]헤몬팜마진!$B$7:$B$32,$C4,[1]헤몬팜마진!$T$7:$T$32) -> 162 | AM4: =SUMIF([1]헤몬팜마진!$B$7:$B$32,$C4,[1]헤몬팜마진!$U$7:$U$32) -> 827 | AO4: 16111 | AP4: 85
C5: 프라임 2개 | D5: =AK5/V5 -> 0.080604313 | E5: =AJ5/V5 -> 0.31462931 | F5: =(Z5+AB5)/V5 -> 0.234025 | G5: =R5/AP5 -> 0.035294118 | H5: 0 | I5: =N5*7 -> 105 | J5: =N5*14 -> 210 | L5: =13+2 -> 15 | N5: 15 | O5: 10 | P5: =O5-S5 -> 10 | Q5: 1 | R5: 9 | T5: =W5*O5 -> 468000 | U5: =W5*S5 -> 0 | V5: =T5-U5 -> 468000 | W5: 46800 | X5: =SUMIF([1]헤몬팜마진!$B$7:$B$32,$C5,[1]헤몬팜마진!$R$7:$R$32) -> 9990 | Y5: =AI5*P5 -> 216320 | Z5: =AA5*1.1 -> 109523.7 | AA5: 99567 | AC5: =(1210+1100)*Q5 -> 2310 | AD5: 0.11 | AE5: =4150*(P5) -> 41500 | AF5: =AD5+(AE5/V5) -> 0.19867521 | AG5: =IFERROR(V5*AF5+3%,0) -> 92980.03 | AH5: =V5/1.1*10%-((AI5*P5)+AG5+(AN5*P5)+(AL5*P5))*10% -> 11453.452 | AI5: =SUMIF([1]헤몬팜마진!$B$7:$B$32,$C5,[1]헤몬팜마진!$V$7:$V$32) -> 21632 | AJ5: =V5-(Y5+AG5+AH5+(AN5*P5)) -> 147246.52 | AK5: =AJ5-Z5-AB5 -> 37722.818 | AL5: =SUMIF([1]헤몬팜마진!$B$7:$B$32,$C5,[1]헤몬팜마진!$T$7:$T$32) -> 162 | AM5: =SUMIF([1]헤몬팜마진!$B$7:$B$32,$C5,[1]헤몬팜마진!$U$7:$U$32) -> 827 | AO5: 93394 | AP5: 255
A6: ACC-TOL-MOW-001-BL | C6: 다밴다 1개 | D6: =AK6/V6 -> #DIV/0! | E6: =AJ6/V6 -> #DIV/0! | F6: =(Z6+AB6)/V6 -> #DIV/0! | G6: =R6/AP6 -> 0 | H6: 3504 | I6: =N6*7 -> 210 | J6: =N6*14 -> 420 | K6: 626 | L6: =30+13+6 -> 49 | N6: 30 | P6: =O6-S6 -> 0 | T6: =W6*O6 -> 0 | U6: =W6*S6 -> 0 | V6: =T6-U6 -> 0 | W6: 59800 | X6: =SUMIF([1]헤몬팜마진!$B$7:$B$32,$C6,[1]헤몬팜마진!$R$7:$R$32) -> 13276 | Y6: =AI6*P6 -> 0 | Z6: =AA6*1.1 -> 5242.6 | AA6: 4766 | AC6: =(1210+1100)*Q6 -> 0 | AD6: 0.108 | AE6: =4825*(P6) -> 0 | AF6: =AD6+(AE6/V6) -> #DIV/0! | AG6: =IFERROR(V6*AF6+3%,0) -> 0 | AH6: =V6/1.1*10%-((AI6*P6)+AG6+(AN6*P6)+(AL6*P6))*10% -> 0 | AI6: =SUMIF([1]헤몬팜마진!$B$7:$B$32,$C6,[1]헤몬팜마진!$V$7:$V$32) -> 21956 | AJ6: =V6-(Y6+AG6+AH6+(AN6*P6)) -> 0 | AK6: =AJ6-Z6-AB6 -> -5242.6 | AL6: =SUMIF([1]헤몬팜마진!$B$7:$B$32,$C6,[1]헤몬팜마진!$T$7:$T$32) -> 372 | AM6: =SUMIF([1]헤몬팜마진!$B$7:$B$32,$C6,[1]헤몬팜마진!$U$7:$U$32) -> 1896 | AO6: 14379 | AP6: 8
A7: ACC-TOL-MOW-001-BL | C7: 다벤다 2개 | D7: =AK7/V7 -> 0.41153824 | E7: =AJ7/V7 -> 0.41153824 | F7: =(Z7+AB7)/V7 -> 0 | G7: =R7/AP7 -> 0.057142857 | H7: 0 | I7: =N7*7 -> 210 | J7: =N7*14 -> 420 | L7: =4+11+18+38+129 -> 200 | N7: 30 | O7: 3 | P7: =O7-S7 -> 3 | R7: 2 | T7: =W7*O7 -> 209340 | U7: =W7*S7 -> 0 | V7: =T7-U7 -> 209340 | W7: 69780 | X7: =SUMIF([1]헤몬팜마진!$B$7:$B$32,$C7,[1]헤몬팜마진!$R$7:$R$32) -> 13276 | Y7: =AI7*P7 -> 78771 | Z7: =AA7*1.1 -> 0 | AC7: =(1210+1100)*Q7 -> 0 | AD7: 0.108 | AE7: =4825*(P7) -> 14475 | AF7: =AD7+(AE7/V7) -> 0.17714589 | AG7: =IFERROR(V7*AF7+3%,0) -> 37083.75 | AH7: =V7/1.1*10%-((AI7*P7)+AG7+(AN7*P7)+(AL7*P7))*10% -> 7333.8341 | AI7: =SUMIF([1]헤몬팜마진!$B$7:$B$32,$C7,[1]헤몬팜마진!$V$7:$V$32) -> 26257 | AJ7: =V7-(Y7+AG7+AH7+(AN7*P7)) -> 86151.416 | AK7: =AJ7-Z7-AB7 -> 86151.416 | AL7: =SUMIF([1]헤몬팜마진!$B$7:$B$32,$C7,[1]헤몬팜마진!$T$7:$T$32) -> 372 | AM7: =SUMIF([1]헤몬팜마진!$B$7:$B$32,$C7,[1]헤몬팜마진!$U$7:$U$32) -> 1896 | AO7: 24997 | AP7: 35
A8: ACC-CHA-CAR-002-BK | C8: 시거잭 | D8: =AK8/V8 -> -1.4659704 | E8: =AJ8/V8 -> 0.39082556 | F8: =(Z8+AB8)/V8 -> 1.8567959 | G8: =R8/AP8 -> 0.025210084 | H8: 500 | I8: =N8*7 -> 105 | J8: =N8*14 -> 210 | K8: 577 | L8: 211 | N8: 15 | O8: 2 | P8: =O8-S8 -> 2 | Q8: 2 | R8: 3 | T8: =W8*O8 -> 32240 | U8: =W8*S8 -> 0 | V8: =T8-U8 -> 32240 | W8: 16120 | X8: =SUMIF([1]헤몬팜마진!$B$7:$B$32,$C8,[1]헤몬팜마진!$R$7:$R$32) -> 5089 | Y8: =AI8*P8 -> 10252 | Z8: =AA8*1.1 -> 59863.1 | AA8: 54421 | AC8: =(1210+1100)*Q8 -> 4620 | AD8: 0.078 | AE8: =2900*(P8) -> 5800 | AF8: =AD8+(AE8/V8) -> 0.25790074 | AG8: =IFERROR(V8*AF8+3%,0) -> 8314.75 | AH8: =V8/1.1*10%-((AI8*P8)+AG8+(AN8*P8)+(AL8*P8))*10% -> 1073.0341 | AI8: =SUMIF([1]헤몬팜마진!$B$7:$B$32,$C8,[1]헤몬팜마진!$V$7:$V$32) -> 5126 | AJ8: =V8-(Y8+AG8+AH8+(AN8*P8)) -> 12600.216 | AK8: =AJ8-Z8-AB8 -> -47262.884 | AL8: =SUMIF([1]헤몬팜마진!$B$7:$B$32,$C8,[1]헤몬팜마진!$T$7:$T$32) -> 6 | AM8: =SUMIF([1]헤몬팜마진!$B$7:$B$32,$C8,[1]헤몬팜마진!$U$7:$U$32) -> 31 | AO8: 75052 | AP8: 119
A9: ACC-TOL-WAS-002-BK | C9: 뉴 고압세척기 배터리 1개 | D9: =AK9/V9 -> 0.12861701 | E9: =AJ9/V9 -> 0.40132699 | F9: =(Z9+AB9)/V9 -> 0.27270998 | G9: =R9/AP9 -> 0.024390244 | H9: 0 | I9: =N9*7 -> 140 | J9: =N9*14 -> 280 | K9: 343 | L9: =97+42+48+31+19+10 -> 247 | N9: 20 | O9: 7 | P9: =O9-S9 -> 7 | R9: 3 | T9: =W9*O9 -> 278600 | U9: =W9*S9 -> 0 | V9: =T9-U9 -> 278600 | W9: 39800 | X9: =SUMIF([1]헤몬팜마진!$B$7:$B$32,$C9,[1]헤몬팜마진!$R$7:$R$32) -> 7855 | Y9: =AI9*P9 -> 105980 | Z9: =AA9*1.1 -> 75977 | AA9: 69070 | AC9: =(1210+1100)*Q9 -> 0 | AD9: 0.08 | AE9: =4150*(P9) -> 29050 | AF9: =AD9+(AE9/V9) -> 0.18427136 | AG9: =IFERROR(V9*AF9+3%,0) -> 51338.03 | AH9: =V9/1.1*10%-((AI9*P9)+AG9+(AN9*P9)+(AL9*P9))*10% -> 9472.2697 | AI9: =SUMIF([1]헤몬팜마진!$B$7:$B$32,$C9,[1]헤몬팜마진!$V$7:$V$32) -> 15140 | AJ9: =V9-(Y9+AG9+AH9+(AN9*P9)) -> 111809.7 | AK9: =AJ9-Z9-AB9 -> 35832.7 | AL9: =SUMIF([1]헤몬팜마진!$B$7:$B$32,$C9,[1]헤몬팜마진!$T$7:$T$32) -> 176 | AM9: =SUMIF([1]헤몬팜마진!$B$7:$B$32,$C9,[1]헤몬팜마진!$U$7:$U$32) -> 900 | AO9: 52516 | AP9: 123
C10: 뉴 고압세척기 | D10: =AK10/V10 -> 0.053997821 | E10: =AJ10/V10 -> 0.39158756 | F10: =(Z10+AB10)/V10 -> 0.33758974 | G10: =R10/AP10 -> 0.01369863 | I10: =N10*7 -> 105 | J10: =N10*14 -> 210 | L10: =74+42+48+18+8+2 -> 192 | N10: 15 | O10: 2 | P10: =O10-S10 -> 2 | Q10: 1 | R10: 1 | T10: =W10*O10 -> 85800 | U10: =W10*S10 -> 0 | V10: =T10-U10 -> 85800 | W10: 42900 | X10: =SUMIF([1]헤몬팜마진!$B$7:$B$32,$C10,[1]헤몬팜마진!$R$7:$R$32) -> 7855 | Y10: =AI10*P10 -> 38882 | Z10: =AA10*1.1 -> 28965.2 | AA10: 26332 | AC10: =(1210+1100)*Q10 -> 2310 | AD10: 0.078 | AE10: =1900*(P10) -> 3800 | AF10: =AD10+(AE10/V10) -> 0.12228904 | AG10: =IFERROR(V10*AF10+3%,0) -> 10492.43 | AH10: =V10/1.1*10%-((AI10*P10)+AG10+(AN10*P10)+(AL10*P10))*10% -> 2827.357 | AI10: =SUMIF([1]헤몬팜마진!$B$7:$B$32,$C10,[1]헤몬팜마진!$V$7:$V$32) -> 19441 | AJ10: =V10-(Y10+AG10+AH10+(AN10*P10)) -> 33598.213 | AK10: =AJ10-Z10-AB10 -> 4633.013 | AL10: =SUMIF([1]헤몬팜마진!$B$7:$B$32,$C10,[1]헤몬팜마진!$T$7:$T$32) -> 176 | AM10: =SUMIF([1]헤몬팜마진!$B$7:$B$32,$C10,[1]헤몬팜마진!$U$7:$U$32) -> 900 | AO10: 23745 | AP10: 73
A11: ACC-MOS-RAC-004 | C11: 모기지옥 | D11: =AK11/V11 -> 0.060796464 | E11: =AJ11/V11 -> 0.36300751 | F11: =(Z11+AB11)/V11 -> 0.30221105 | G11: =R11/AP11 -> 0.1 | H11: 1750 | I11: =N11*7 -> 350 | J11: =N11*14 -> 700 | K11: 1449 | L11: 1217 | N11: 50 | O11: 23 | P11: =O11-S11 -> 23 | Q11: 3 | R11: 10 | T11: =W11*O11 -> 441600 | U11: =W11*S11 -> 0 | V11: =T11-U11 -> 441600 | W11: 19200 | X11: =SUMIF([1]헤몬팜마진!$B$7:$B$32,$C11,[1]헤몬팜마진!$R$7:$R$32) -> 6373 | Y11: =AI11*P11 -> 155733 | Z11: =AA11*1.1 -> 133456.4 | AA11: =100696+20628 -> 121324 | AC11: =(1210+1100)*Q11 -> 6930 | AD11: 0.08 | AE11: =3350*(P11) -> 77050 | AF11: =AD11+(AE11/V11) -> 0.25447917 | AG11: =IFERROR(V11*AF11+3%,0) -> 112378.03 | AH11: =V11/1.1*10%-((AI11*P11)+AG11+(AN11*P11)+(AL11*P11))*10% -> 13184.852 | AI11: =SUMIF([1]헤몬팜마진!$B$7:$B$32,$C11,[1]헤몬팜마진!$V$7:$V$32) -> 6771 | AJ11: =V11-(Y11+AG11+AH11+(AN11*P11)) -> 160304.12 | AK11: =AJ11-Z11-AB11 -> 26847.718 | AL11: =SUMIF([1]헤몬팜마진!$B$7:$B$32,$C11,[1]헤몬팜마진!$T$7:$T$32) -> 65 | AM11: =SUMIF([1]헤몬팜마진!$B$7:$B$32,$C11,[1]헤몬팜마진!$U$7:$U$32) -> 333 | AO11: 29984 | AP11: 100
A12: ACC-TOL-SAW-008-BL | C12: 컷소 배터리 1개 | D12: =AK12/V12 -> -0.11786437 | E12: =AJ12/V12 -> 0.41625975 | F12: =(Z12+AB12)/V12 -> 0.53412412 | G12: =R12/AP12 -> 0.016528926 | H12: 0 | I12: =N12*7 -> 70 | J12: =N12*14 -> 140 | K12: 494 | L12: 0 | N12: 10 | O12: 5 | P12: =O12-S12 -> 5 | R12: 2 | T12: =W12*O12 -> 248950 | U12: =W12*S12 -> 0 | V12: =T12-U12 -> 248950 | W12: 49790 | X12: =SUMIF([1]헤몬팜마진!$B$7:$B$32,$C12,[1]헤몬팜마진!$R$7:$R$32) -> 12170 | Y12: =AI12*P12 -> 92880 | Z12: =AA12*1.1 -> 132970.2 | AA12: 120882 | AC12: =(1210+1100)*Q12 -> 0 | AD12: 0.078 | AE12: =4825*(P12) -> 24125 | AF12: =AD12+(AE12/V12) -> 0.17490701 | AG12: =IFERROR(V12*AF12+3%,0) -> 43543.13 | AH12: =V12/1.1*10%-((AI12*P12)+AG12+(AN12*P12)+(AL12*P12))*10% -> 8899.0052 | AI12: =SUMIF([1]헤몬팜마진!$B$7:$B$32,$C12,[1]헤몬팜마진!$V$7:$V$32) -> 18576 | AJ12: =V12-(Y12+AG12+AH12+(AN12*P12)) -> 103627.86 | AK12: =AJ12-Z12-AB12 -> -29342.335 | AL12: =SUMIF([1]헤몬팜마진!$B$7:$B$32,$C12,[1]헤몬팜마진!$T$7:$T$32) -> 181 | AM12: =SUMIF([1]헤몬팜마진!$B$7:$B$32,$C12,[1]헤몬팜마진!$U$7:$U$32) -> 926 | AO12: 26984 | AP12: 121
C13: 컷소 배터리 2개 | D13: =AK13/V13 -> 0.18848194 | E13: =AJ13/V13 -> 0.40846927 | F13: =(Z13+AB13)/V13 -> 0.21998733 | G13: =R13/AP13 -> 0.026845638 | H13: 0 | I13: =N13*7 -> 70 | J13: =N13*14 -> 140 | L13: 1 | N13: 10 | O13: 6 | P13: =O13-S13 -> 6 | Q13: 1 | R13: 4 | T13: =W13*O13 -> 347280 | U13: =W13*S13 -> 0 | V13: =T13-U13 -> 347280 | W13: 57880 | X13: =SUMIF([1]헤몬팜마진!$B$7:$B$32,$C13,[1]헤몬팜마진!$R$7:$R$32) -> 12170 | Y13: =AI13*P13 -> 137256 | Z13: =AA13*1.1 -> 76397.2 | AA13: 69452 | AC13: =(1210+1100)*Q13 -> 2310 | AD13: 0.078 | AE13: =4825*(P13) -> 28950 | AF13: =AD13+(AE13/V13) -> 0.16136213 | AG13: =IFERROR(V13*AF13+3%,0) -> 56037.87 | AH13: =V13/1.1*10%-((AI13*P13)+AG13+(AN13*P13)+(AL13*P13))*10% -> 12132.922 | AI13: =SUMIF([1]헤몬팜마진!$B$7:$B$32,$C13,[1]헤몬팜마진!$V$7:$V$32) -> 22876 | AJ13: =V13-(Y13+AG13+AH13+(AN13*P13)) -> 141853.21 | AK13: =AJ13-Z13-AB13 -> 65456.008 | AL13: =SUMIF([1]헤몬팜마진!$B$7:$B$32,$C13,[1]헤몬팜마진!$T$7:$T$32) -> 181 | AM13: =SUMIF([1]헤몬팜마진!$B$7:$B$32,$C13,[1]헤몬팜마진!$U$7:$U$32) -> 926 | AO13: 27354 | AP13: 149
A14: ACC-BLE-POR-001 | C14: 믹서기 | D14: =AK14/V14 -> 0.3505979 | E14: =AJ14/V14 -> 0.4982771 | F14: =(Z14+AB14)/V14 -> 0.1476792 | G14: =R14/AP14 -> 0.052910053 | H14: 2000 | I14: =N14*7 -> 700 | J14: =N14*14 -> 1400 | K14: 2373 | L14: 3 | N14: 100 | O14: 23 | P14: =O14-S14 -> 23 | Q14: 5 | R14: 10 | T14: =W14*O14 -> 408480 | U14: =W14*S14 -> 0 | V14: =T14-U14 -> 408480 | W14: 17760 | X14: =SUMIF([1]헤몬팜마진!$B$7:$B$32,$C14,[1]헤몬팜마진!$R$7:$R$32) -> 3983 | Y14: =AI14*P14 -> 111251 | Z14: =AA14*1.1 -> 60324 | AA14: =30232+24608 -> 54840 | AC14: =(1210+1100)*Q14 -> 11550 | AD14: 0.078 | AE14: =1900*(P14) -> 43700 | AF14: =AD14+(AE14/V14) -> 0.18498198 | AG14: =IFERROR(V14*AF14+3%,0) -> 75561.47 | AH14: =V14/1.1*10%-((AI14*P14)+AG14+(AN14*P14)+(AL14*P14))*10% -> 18131.298 | AI14: =SUMIF([1]헤몬팜마진!$B$7:$B$32,$C14,[1]헤몬팜마진!$V$7:$V$32) -> 4837 | AJ14: =V14-(Y14+AG14+AH14+(AN14*P14)) -> 203536.23 | AK14: =AJ14-Z14-AB14 -> 143212.23 | AL14: =SUMIF([1]헤몬팜마진!$B$7:$B$32,$C14,[1]헤몬팜마진!$T$7:$T$32) -> 140 | AM14: =SUMIF([1]헤몬팜마진!$B$7:$B$32,$C14,[1]헤몬팜마진!$U$7:$U$32) -> 714 | AO14: 40480 | AP14: 189
A15: ACC-CAR-PUM-001-BK | C15: 공기압 주입기 | D15: =AK15/V15 -> 0.43888178 | E15: =AJ15/V15 -> 0.43888178 | F15: =(Z15+AB15)/V15 -> 0 | G15: =R15/AP15 -> 0 | H15: 0 | I15: =N15*7 -> 350 | J15: =N15*14 -> 700 | K15: 87 | L15: 0 | N15: 50 | O15: -2 | P15: =O15-S15 -> -2 | Q15: 2 | T15: =W15*O15 -> -49600 | U15: =W15*S15 -> 0 | V15: =T15-U15 -> -49600 | W15: 24800 | X15: =SUMIF([1]헤몬팜마진!$B$7:$B$32,$C15,[1]헤몬팜마진!$R$7:$R$32) -> 8408 | Y15: =AI15*P15 -> -17160 | Z15: =AA15*1.1 -> 0 | AC15: =(1210+1100)*Q15 -> 4620 | AD15: 0.1 | AE15: =1900*(P15) -> -3800 | AF15: =AD15+(AE15/V15) -> 0.1766129 | AG15: =IFERROR(V15*AF15+3%,0) -> -8759.97 | AH15: =V15/1.1*10%-((AI15*P15)+AG15+(AN15*P15)+(AL15*P15))*10% -> -1911.4939 | AI15: =SUMIF([1]헤몬팜마진!$B$7:$B$32,$C15,[1]헤몬팜마진!$V$7:$V$32) -> 8580 | AJ15: =V15-(Y15+AG15+AH15+(AN15*P15)) -> -21768.536 | AK15: =AJ15-Z15-AB15 -> -21768.536 | AL15: =SUMIF([1]헤몬팜마진!$B$7:$B$32,$C15,[1]헤몬팜마진!$T$7:$T$32) -> 28 | AM15: =SUMIF([1]헤몬팜마진!$B$7:$B$32,$C15,[1]헤몬팜마진!$U$7:$U$32) -> 143 | AO15: 75901 | AP15: 339
B16: 오픈이어 (신제품) | C16: 골전도이어폰 | D16: =AK16/V16 -> -0.13246597 | E16: =AJ16/V16 -> 0.37867671 | F16: =(Z16+AB16)/V16 -> 0.51114268 | G16: =R16/AP16 -> 0.058333333 | H16: 700 | I16: =N16*7 -> 210 | J16: =N16*14 -> 420 | K16: 954 | L16: 2 | N16: 30 | O16: 34 | P16: =O16-S16 -> 24 | Q16: 1 | R16: 21 | S16: 10 | T16: =W16*O16 -> 673200 | U16: =W16*S16 -> 198000 | V16: =T16-U16 -> 475200 | W16: 19800 | X16: =SUMIF([1]헤몬팜마진!$B$7:$B$32,$C16,[1]헤몬팜마진!$R$7:$R$32) -> 6638 | Y16: =AI16*P16 -> 160464 | Z16: =AA16*1.1 -> 138050 | AA16: 125500 | AB16: =((20900*0.015)+(20900*0.19)+2100+2200+1900)*10 -> 104845 | AC16: =(1210+1100)*Q16 -> 2310 | AD16: 0.08 | AE16: =3400*(P16) -> 81600 | AF16: =AD16+(AE16/V16) -> 0.25171717 | AG16: =IFERROR(V16*AF16+3%,0) -> 119616.03 | AH16: =V16/1.1*10%-((AI16*P16)+AG16+(AN16*P16)+(AL16*P16))*10% -> 15172.797 | AI16: =SUMIF([1]헤몬팜마진!$B$7:$B$32,$C16,[1]헤몬팜마진!$V$7:$V$32) -> 6686 | AJ16: =V16-(Y16+AG16+AH16+(AN16*P16)) -> 179947.17 | AK16: =AJ16-Z16-AB16 -> -62947.827 | AL16: =SUMIF([1]헤몬팜마진!$B$7:$B$32,$C16,[1]헤몬팜마진!$T$7:$T$32) -> 8 | AM16: =SUMIF([1]헤몬팜마진!$B$7:$B$32,$C16,[1]헤몬팜마진!$U$7:$U$32) -> 40 | AO16: 299288 | AP16: 360
A17: ACC-SHA-PET-002-WH | B17: 멀티클리퍼 (신제품) | C17: 강아지바리깡 | D17: =AK17/V17 -> 0.20957625 | E17: =AJ17/V17 -> 0.43443623 | F17: =(Z17+AB17)/V17 -> 0.22485998 | G17: =R17/AP17 -> 0.13402062 | H17: 2000 | I17: =N17*7 -> 280 | J17: =N17*14 -> 560 | K17: 1048 | L17: =311+240+1 -> 552 | N17: 40 | O17: 19 | P17: =O17-S17 -> 19 | Q17: 5 | R17: 13 | T17: =W17*O17 -> 471010 | U17: =W17*S17 -> 0 | V17: =T17-U17 -> 471010 | W17: 24790 | X17: =SUMIF([1]헤몬팜마진!$B$7:$B$32,$C17,[1]헤몬팜마진!$R$7:$R$32) -> 6859 | Y17: =AI17*P17 -> 137826 | Z17: =AA17*1.1 -> 105911.3 | AA17: 96283 | AC17: =(1210+1100)*Q17 -> 11550 | AD17: 0.108 | AE17: =3150*(P17) -> 59850 | AF17: =AD17+(AE17/V17) -> 0.23506737 | AG17: =IFERROR(V17*AF17+3%,0) -> 110719.11 | AH17: =V17/1.1*10%-((AI17*P17)+AG17+(AN17*P17)+(AL17*P17))*10% -> 17841.08 | AI17: =SUMIF([1]헤몬팜마진!$B$7:$B$32,$C17,[1]헤몬팜마진!$V$7:$V$32) -> 7254 | AJ17: =V17-(Y17+AG17+AH17+(AN17*P17)) -> 204623.81 | AK17: =AJ17-Z17-AB17 -> 98712.51 | AL17: =SUMIF([1]헤몬팜마진!$B$7:$B$32,$C17,[1]헤몬팜마진!$T$7:$T$32) -> 65 | AM17: =SUMIF([1]헤몬팜마진!$B$7:$B$32,$C17,[1]헤몬팜마진!$U$7:$U$32) -> 330 | AO17: 29145 | AP17: 97
B18: 신제품 | C18: 강아지바리깡 2개 | D18: =AK18/V18 -> 0.13222234 | E18: =AJ18/V18 -> 0.41263943 | F18: =(Z18+AB18)/V18 -> 0.28041709 | G18: =R18/AP18 -> 0.024793388 | H18: 0 | I18: =N18*7 -> 105 | J18: =N18*14 -> 210 | L18: =22+3 -> 25 | N18: 15 | O18: 3 | P18: =O18-S18 -> 3 | R18: 3 | T18: =W18*O18 -> 119400 | U18: =W18*S18 -> 0 | V18: =T18-U18 -> 119400 | W18: 39800 | X18: =SUMIF([1]헤몬팜마진!$B$7:$B$32,$C18,[1]헤몬팜마진!$R$7:$R$32) -> 13719 | Y18: =AI18*P18 -> 42339 | Z18: =AA18*1.1 -> 33481.8 | AA18: 30438 | AC18: =(1210+1100)*Q18 -> 0 | AD18: 0.108 | AE18: =3550*(P18) -> 10650 | AF18: =AD18+(AE18/V18) -> 0.19719598 | AG18: =IFERROR(V18*AF18+3%,0) -> 23545.23 | AH18: =V18/1.1*10%-((AI18*P18)+AG18+(AN18*P18)+(AL18*P18))*10% -> 4246.6225 | AI18: =SUMIF([1]헤몬팜마진!$B$7:$B$32,$C18,[1]헤몬팜마진!$V$7:$V$32) -> 14113 | AJ18: =V18-(Y18+AG18+AH18+(AN18*P18)) -> 49269.148 | AK18: =AJ18-Z18-AB18 -> 15787.348 | AL18: =SUMIF([1]헤몬팜마진!$B$7:$B$32,$C18,[1]헤몬팜마진!$T$7:$T$32) -> 65 | AM18: =SUMIF([1]헤몬팜마진!$B$7:$B$32,$C18,[1]헤몬팜마진!$U$7:$U$32) -> 330 | AO18: 34925 | AP18: 121
D19: =AK19/V19 -> 0.15996824 | E19: =AJ19/V19 -> 0.41236855 | F19: =(Z19+AB19)/V19 -> 0.25240031 | O19: =SUM(O2:O18) -> 307 | P19: =SUM(P2:P18) -> 297 | Q19: =SUM(Q2:Q18) -> 37 | R19: =SUM(R2:R18) -> 212 | S19: =SUM(S2:S18) -> 10 | T19: =SUM(T2:T18) -> 8586800 | U19: =SUM(U2:U18) -> 198000 | V19: =SUM(V2:V18) -> 8388800 | X19: =SUM(X2:X18) -> 153583 | Y19: =SUM(Y2:Y18) -> 2885195 | Z19: =SUM(Z2:Z18) -> 2012490.7 | AA19: =SUM(AA2:AA18) -> 1829537 | AB19: =SUM(AB2:AB18) -> 104845 | AC19: =SUM(AC2:AC18) -> 83262 | AD19: 0.09 | AE19: =SUM(AE2:AE18) -> 944650 | AF19: =AD19+(AE19/V19) -> 0.20260848 | AG19: =SUM(AG2:AG18) -> 1747374 | AH19: =SUM(AH2:AH18) -> 296953.79 | AI19: =SUM(AI2:AI18) -> 233199 | AJ19: =V19-(Y19+AG19+AH19+(AN19*P19)) -> 3459277.3 | AK19: =AJ19-Z19-AB19 -> 1341941.6 | AO19: =SUM(AO2:AO3) -> 394897 | AP19: =SUM(AP2:AP3) -> 1860
C21: 45946 | D21: 이윤율 | E21: 마진율 | F21: 광고비율 | G21: 전환율 | H21: 발주남은수량 | I21: 창고안전 | J21: 쿠팡안전 | K21: 창고재고 | L21: 쿠팡재고 | M21: 미포장분 | N21: 목표판매량 | O21: 판매수 | P21: 순판매개수 | Q21: 취소개수 | R21: 광고전환 | S21: 가구매 | T21: 매출 | U21: 가구매금액 | V21: 순매출 | W21: 판매가 | X21: 입고가 | Y21: 입고판매가 | Z21: 광고비1.1 | AA21: 광고비 | AB21: 가구매비용 | AC21: 반품회수비 | AD21: 수수료 | AE21: 택배비 | AF21: 판매수수료 | AG21: 수수료 | AH21: 부가세 | AI21: 도매가 | AJ21: 판매마진 | AK21: 순이익 | AL21: 1개당 한국 운임 물류비(KRW) | AM21: 1개당 물류비 (KRW) | AN21: 부자재값 | AO21: 노출수 | AP21: 클릭수
A22: ACC-SHA-BRD-001-BK | C22: 쉐이버 | D22: =AK22/V22 -> 0.18429177 | E22: =AJ22/V22 -> 0.42271098 | F22: =(Z22+AB22)/V22 -> 0.2384192 | G22: =R22/AP22 -> 0.071751129 | H22: 7410 | I22: =N22*7 -> 1400 | J22: =N22*14 -> 2800 | K22: 76 | L22: =1906+1320 -> 3226 | N22: 200 | O22: 191 | P22: =O22-S22 -> 191 | Q22: 10 | R22: 143 | T22: =W22*O22 -> 5328900 | U22: =W22*S22 -> 0 | V22: =T22-U22 -> 5328900 | W22: 27900 | X22: =SUMIF([1]헤몬팜마진!$B$7:$B$32,$C22,[1]헤몬팜마진!$R$7:$R$32) -> 8851 | Y22: =AI22*P22 -> 1765795 | Z22: =AA22*1.1 -> 1270512.1 | AA22: 1155011 | AC22: =(1072+1100)*Q22 -> 21720 | AD22: 0.1 | AE22: =3050*(P22) -> 582550 | AF22: =AD22+(AE22/V22) -> 0.209319 | AG22: =IFERROR(V22*AF22+3%,0) -> 1115440 | AH22: =V22/1.1*10%-((AI22*P22)+AG22+(AN22*P22)+(AL22*P22))*10% -> 195080.45 | AI22: =SUMIF([1]헤몬팜마진!$B$7:$B$32,$C22,[1]헤몬팜마진!$V$7:$V$32) -> 9245 | AJ22: =V22-(Y22+AG22+AH22+(AN22*P22)) -> 2252584.5 | AK22: =AJ22-Z22-AB22 -> 982072.42 | AL22: =SUMIF([1]헤몬팜마진!$B$7:$B$32,$C22,[1]헤몬팜마진!$T$7:$T$32) -> 65 | AM22: =SUMIF([1]헤몬팜마진!$B$7:$B$32,$C22,[1]헤몬팜마진!$U$7:$U$32) -> 330 | AO22: 371303 | AP22: 1993
A23: ACC-SHA-BRD-004-BK | C23: 일자면도기 | D23: =AK23/V23 -> 0.35098899 | E23: =AJ23/V23 -> 0.40986564 | F23: =(Z23+AB23)/V23 -> 0.058876652 | G23: =R23/AP23 -> 0 | H23: 1460 | I23: =N23*7 -> 140 | J23: =N23*14 -> 280 | K23: 325 | L23: 0 | N23: 20 | O23: 2 | P23: =O23-S23 -> 2 | T23: =W23*O23 -> 45400 | U23: =W23*S23 -> 0 | V23: =T23-U23 -> 45400 | W23: 22700 | X23: =SUMIF([1]헤몬팜마진!$B$7:$B$32,$C23,[1]헤몬팜마진!$R$7:$R$32) -> 7081 | Y23: =AI23*P23 -> 14754 | Z23: =AA23*1.1 -> 2673 | AA23: 2430 | AC23: =(1072+1100)*Q23 -> 0 | AD23: 0.1 | AE23: =2950*(P23) -> 5900 | AF23: =AD23+(AE23/V23) -> 0.22995595 | AG23: =IFERROR(V23*AF23+3%,0) -> 10440.03 | AH23: =V23/1.1*10%-((AI23*P23)+AG23+(AN23*P23)+(AL23*P23))*10% -> 1598.0697 | AI23: =SUMIF([1]헤몬팜마진!$B$7:$B$32,$C23,[1]헤몬팜마진!$V$7:$V$32) -> 7377 | AJ23: =V23-(Y23+AG23+AH23+(AN23*P23)) -> 18607.9 | AK23: =AJ23-Z23-AB23 -> 15934.9 | AL23: =SUMIF([1]헤몬팜마진!$B$7:$B$32,$C23,[1]헤몬팜마진!$T$7:$T$32) -> 49 | AM23: =SUMIF([1]헤몬팜마진!$B$7:$B$32,$C23,[1]헤몬팜마진!$U$7:$U$32) -> 248 | AO23: 13582 | AP23: 3
A24: ACC-TOL-DRI-012-BL | C24: 프라임 1개 | D24: =AK24/V24 -> #DIV/0! | E24: =AJ24/V24 -> #DIV/0! | F24: =(Z24+AB24)/V24 -> #DIV/0! | G24: =R24/AP24 -> 0 | H24: 0 | I24: =N24*7 -> 105 | J24: =N24*14 -> 210 | K24: 430 | L24: =40+3+3 -> 46 | N24: 15 | P24: =O24-S24 -> 0 | Q24: 1 | T24: =W24*O24 -> 0 | U24: =W24*S24 -> 0 | V24: =T24-U24 -> 0 | W24: 45800 | X24: =SUMIF([1]헤몬팜마진!$B$7:$B$32,$C24,[1]헤몬팜마진!$R$7:$R$32) -> 9990 | Y24: =AI24*P24 -> 0 | Z24: =AA24*1.1 -> 8209.3 | AA24: 7463 | AC24: =(1210+1100)*Q24 -> 2310 | AD24: 0.11 | AE24: =4150*(P24) -> 0 | AF24: =AD24+(AE24/V24) -> #DIV/0! | AG24: =IFERROR(V24*AF24+3%,0) -> 0 | AH24: =V24/1.1*10%-((AI24*P24)+AG24+(AN24*P24)+(AL24*P24))*10% -> 0 | AI24: =SUMIF([1]헤몬팜마진!$B$7:$B$32,$C24,[1]헤몬팜마진!$V$7:$V$32) -> 17332 | AJ24: =V24-(Y24+AG24+AH24+(AN24*P24)) -> 0 | AK24: =AJ24-Z24-AB24 -> -8209.3 | AL24: =SUMIF([1]헤몬팜마진!$B$7:$B$32,$C24,[1]헤몬팜마진!$T$7:$T$32) -> 162 | AM24: =SUMIF([1]헤몬팜마진!$B$7:$B$32,$C24,[1]헤몬팜마진!$U$7:$U$32) -> 827 | AO24: 13653 | AP24: 51
C25: 프라임 2개 | D25: =AK25/V25 -> -0.059834082 | E25: =AJ25/V25 -> 0.31462929 | F25: =(Z25+AB25)/V25 -> 0.37446337 | G25: =R25/AP25 -> 0.01510574 | H25: 0 | I25: =N25*7 -> 105 | J25: =N25*14 -> 210 | L25: =13+2 -> 15 | N25: 15 | O25: 7 | P25: =O25-S25 -> 7 | Q25: 1 | R25: 5 | T25: =W25*O25 -> 327600 | U25: =W25*S25 -> 0 | V25: =T25-U25 -> 327600 | W25: 46800 | X25: =SUMIF([1]헤몬팜마진!$B$7:$B$32,$C25,[1]헤몬팜마진!$R$7:$R$32) -> 9990 | Y25: =AI25*P25 -> 151424 | Z25: =AA25*1.1 -> 122674.2 | AA25: 111522 | AC25: =(1210+1100)*Q25 -> 2310 | AD25: 0.11 | AE25: =4150*(P25) -> 29050 | AF25: =AD25+(AE25/V25) -> 0.19867521 | AG25: =IFERROR(V25*AF25+3%,0) -> 65086.03 | AH25: =V25/1.1*10%-((AI25*P25)+AG25+(AN25*P25)+(AL25*P25))*10% -> 8017.4152 | AI25: =SUMIF([1]헤몬팜마진!$B$7:$B$32,$C25,[1]헤몬팜마진!$V$7:$V$32) -> 21632 | AJ25: =V25-(Y25+AG25+AH25+(AN25*P25)) -> 103072.55 | AK25: =AJ25-Z25-AB25 -> -19601.645 | AL25: =SUMIF([1]헤몬팜마진!$B$7:$B$32,$C25,[1]헤몬팜마진!$T$7:$T$32) -> 162 | AM25: =SUMIF([1]헤몬팜마진!$B$7:$B$32,$C25,[1]헤몬팜마진!$U$7:$U$32) -> 827 | AO25: 118599 | AP25: 331
A26: ACC-TOL-MOW-001-BL | C26: 다밴다 1개 | D26: =AK26/V26 -> 0.34805266 | E26: =AJ26/V26 -> 0.409454 | F26: =(Z26+AB26)/V26 -> 0.061401338 | G26: =R26/AP26 -> #DIV/0! | H26: 3504 | I26: =N26*7 -> 210 | J26: =N26*14 -> 420 | K26: 626 | L26: =30+13+6 -> 49 | N26: 30 | O26: 1 | P26: =O26-S26 -> 1 | T26: =W26*O26 -> 59800 | U26: =W26*S26 -> 0 | V26: =T26-U26 -> 59800 | W26: 59800 | X26: =SUMIF([1]헤몬팜마진!$B$7:$B$32,$C26,[1]헤몬팜마진!$R$7:$R$32) -> 13276 | Y26: =AI26*P26 -> 21956 | Z26: =AA26*1.1 -> 3671.8 | AA26: 3338 | AC26: =(1210+1100)*Q26 -> 0 | AD26: 0.108 | AE26: =4825*(P26) -> 4825 | AF26: =AD26+(AE26/V26) -> 0.18868562 | AG26: =IFERROR(V26*AF26+3%,0) -> 11283.43 | AH26: =V26/1.1*10%-((AI26*P26)+AG26+(AN26*P26)+(AL26*P26))*10% -> 2075.2206 | AI26: =SUMIF([1]헤몬팜마진!$B$7:$B$32,$C26,[1]헤몬팜마진!$V$7:$V$32) -> 21956 | AJ26: =V26-(Y26+AG26+AH26+(AN26*P26)) -> 24485.349 | AK26: =AJ26-Z26-AB26 -> 20813.549 | AL26: =SUMIF([1]헤몬팜마진!$B$7:$B$32,$C26,[1]헤몬팜마진!$T$7:$T$32) -> 372 | AM26: =SUMIF([1]헤몬팜마진!$B$7:$B$32,$C26,[1]헤몬팜마진!$U$7:$U$32) -> 1896
A27: ACC-TOL-MOW-001-BL | C27: 다벤다 2개 | D27: =AK27/V27 -> -0.030322146 | E27: =AJ27/V27 -> 0.41153799 | F27: =(Z27+AB27)/V27 -> 0.44186013 | G27: =R27/AP27 -> 0 | H27: 0 | I27: =N27*7 -> 210 | J27: =N27*14 -> 420 | L27: =4+11+18+38+129 -> 200 | N27: 30 | O27: 1 | P27: =O27-S27 -> 1 | T27: =W27*O27 -> 69780 | U27: =W27*S27 -> 0 | V27: =T27-U27 -> 69780 | W27: 69780 | X27: =SUMIF([1]헤몬팜마진!$B$7:$B$32,$C27,[1]헤몬팜마진!$R$7:$R$32) -> 13276 | Y27: =AI27*P27 -> 26257 | Z27: =AA27*1.1 -> 30833 | AA27: 28030 | AC27: =(1210+1100)*Q27 -> 0 | AD27: 0.108 | AE27: =4825*(P27) -> 4825 | AF27: =AD27+(AE27/V27) -> 0.17714589 | AG27: =IFERROR(V27*AF27+3%,0) -> 12361.27 | AH27: =V27/1.1*10%-((AI27*P27)+AG27+(AN27*P27)+(AL27*P27))*10% -> 2444.6094 | AI27: =SUMIF([1]헤몬팜마진!$B$7:$B$32,$C27,[1]헤몬팜마진!$V$7:$V$32) -> 26257 | AJ27: =V27-(Y27+AG27+AH27+(AN27*P27)) -> 28717.121 | AK27: =AJ27-Z27-AB27 -> -2115.8794 | AL27: =SUMIF([1]헤몬팜마진!$B$7:$B$32,$C27,[1]헤몬팜마진!$T$7:$T$32) -> 372 | AM27: =SUMIF([1]헤몬팜마진!$B$7:$B$32,$C27,[1]헤몬팜마진!$U$7:$U$32) -> 1896 | AO27: 29096 | AP27: 43
A28: ACC-CHA-CAR-002-BK | C28: 시거잭 | D28: =AK28/V28 -> 0.020195291 | E28: =AJ28/V28 -> 0.39082627 | F28: =(Z28+AB28)/V28 -> 0.37063098 | G28: =R28/AP28 -> 0.10687023 | H28: 500 | I28: =N28*7 -> 105 | J28: =N28*14 -> 210 | K28: 577 | L28: 211 | N28: 15 | O28: 14 | P28: =O28-S28 -> 14 | Q28: 1 | R28: 14 | T28: =W28*O28 -> 225680 | U28: =W28*S28 -> 0 | V28: =T28-U28 -> 225680 | W28: 16120 | X28: =SUMIF([1]헤몬팜마진!$B$7:$B$32,$C28,[1]헤몬팜마진!$R$7:$R$32) -> 5089 | Y28: =AI28*P28 -> 71764 | Z28: =AA28*1.1 -> 83644 | AA28: 76040 | AC28: =(1210+1100)*Q28 -> 2310 | AD28: 0.078 | AE28: =2900*(P28) -> 40600 | AF28: =AD28+(AE28/V28) -> 0.25790074 | AG28: =IFERROR(V28*AF28+3%,0) -> 58203.07 | AH28: =V28/1.1*10%-((AI28*P28)+AG28+(AN28*P28)+(AL28*P28))*10% -> 7511.2566 | AI28: =SUMIF([1]헤몬팜마진!$B$7:$B$32,$C28,[1]헤몬팜마진!$V$7:$V$32) -> 5126 | AJ28: =V28-(Y28+AG28+AH28+(AN28*P28)) -> 88201.673 | AK28: =AJ28-Z28-AB28 -> 4557.6734 | AL28: =SUMIF([1]헤몬팜마진!$B$7:$B$32,$C28,[1]헤몬팜마진!$T$7:$T$32) -> 6 | AM28: =SUMIF([1]헤몬팜마진!$B$7:$B$32,$C28,[1]헤몬팜마진!$U$7:$U$32) -> 31 | AO28: 65392 | AP28: 131
A29: ACC-TOL-WAS-002-BK | C29: 뉴 고압세척기 배터리 1개 | D29: =AK29/V29 -> 0.10140427 | E29: =AJ29/V29 -> 0.40132701 | F29: =(Z29+AB29)/V29 -> 0.29992274 | G29: =R29/AP29 -> 0.034482759 | H29: 0 | I29: =N29*7 -> 140 | J29: =N29*14 -> 280 | K29: 343 | L29: =97+42+48+31+19+10 -> 247 | N29: 20 | O29: 8 | P29: =O29-S29 -> 8 | R29: 5 | T29: =W29*O29 -> 318400 | U29: =W29*S29 -> 0 | V29: =T29-U29 -> 318400 | W29: 39800 | X29: =SUMIF([1]헤몬팜마진!$B$7:$B$32,$C29,[1]헤몬팜마진!$R$7:$R$32) -> 7855 | Y29: =AI29*P29 -> 121120 | Z29: =AA29*1.1 -> 95495.4 | AA29: 86814 | AC29: =(1210+1100)*Q29 -> 0 | AD29: 0.08 | AE29: =4150*(P29) -> 33200 | AF29: =AD29+(AE29/V29) -> 0.18427136 | AG29: =IFERROR(V29*AF29+3%,0) -> 58672.03 | AH29: =V29/1.1*10%-((AI29*P29)+AG29+(AN29*P29)+(AL29*P29))*10% -> 10825.452 | AI29: =SUMIF([1]헤몬팜마진!$B$7:$B$32,$C29,[1]헤몬팜마진!$V$7:$V$32) -> 15140 | AJ29: =V29-(Y29+AG29+AH29+(AN29*P29)) -> 127782.52 | AK29: =AJ29-Z29-AB29 -> 32287.118 | AL29: =SUMIF([1]헤몬팜마진!$B$7:$B$32,$C29,[1]헤몬팜마진!$T$7:$T$32) -> 176 | AM29: =SUMIF([1]헤몬팜마진!$B$7:$B$32,$C29,[1]헤몬팜마진!$U$7:$U$32) -> 900 | AO29: 61804 | AP29: 145
C30: 뉴 고압세척기 | D30: =AK30/V30 -> 0.2665057 | E30: =AJ30/V30 -> 0.39158775 | F30: =(Z30+AB30)/V30 -> 0.12508205 | G30: =R30/AP30 -> 0.074626866 | I30: =N30*7 -> 105 | J30: =N30*14 -> 210 | L30: =74+42+48+18+8+2 -> 192 | N30: 15 | O30: 5 | P30: =O30-S30 -> 5 | R30: 5 | T30: =W30*O30 -> 214500 | U30: =W30*S30 -> 0 | V30: =T30-U30 -> 214500 | W30: 42900 | X30: =SUMIF([1]헤몬팜마진!$B$7:$B$32,$C30,[1]헤몬팜마진!$R$7:$R$32) -> 7855 | Y30: =AI30*P30 -> 97205 | Z30: =AA30*1.1 -> 26830.1 | AA30: 24391 | AC30: =(1210+1100)*Q30 -> 0 | AD30: 0.078 | AE30: =1900*(P30) -> 9500 | AF30: =AD30+(AE30/V30) -> 0.12228904 | AG30: =IFERROR(V30*AF30+3%,0) -> 26231.03 | AH30: =V30/1.1*10%-((AI30*P30)+AG30+(AN30*P30)+(AL30*P30))*10% -> 7068.397 | AI30: =SUMIF([1]헤몬팜마진!$B$7:$B$32,$C30,[1]헤몬팜마진!$V$7:$V$32) -> 19441 | AJ30: =V30-(Y30+AG30+AH30+(AN30*P30)) -> 83995.573 | AK30: =AJ30-Z30-AB30 -> 57165.473 | AL30: =SUMIF([1]헤몬팜마진!$B$7:$B$32,$C30,[1]헤몬팜마진!$T$7:$T$32) -> 176 | AM30: =SUMIF([1]헤몬팜마진!$B$7:$B$32,$C30,[1]헤몬팜마진!$U$7:$U$32) -> 900 | AO30: 17841 | AP30: 67
A31: ACC-MOS-RAC-004 | C31: 모기지옥 | D31: =AK31/V31 -> 0.1145534 | E31: =AJ31/V31 -> 0.36300752 | F31: =(Z31+AB31)/V31 -> 0.24845413 | G31: =R31/AP31 -> 0.090909091 | H31: 1750 | I31: =N31*7 -> 350 | J31: =N31*14 -> 700 | K31: 1449 | L31: 1217 | N31: 50 | O31: 26 | P31: =O31-S31 -> 26 | Q31: 1 | R31: 12 | T31: =W31*O31 -> 499200 | U31: =W31*S31 -> 0 | V31: =T31-U31 -> 499200 | W31: 19200 | X31: =SUMIF([1]헤몬팜마진!$B$7:$B$32,$C31,[1]헤몬팜마진!$R$7:$R$32) -> 6373 | Y31: =AI31*P31 -> 176046 | Z31: =AA31*1.1 -> 124028.3 | AA31: =101407+11346 -> 112753 | AC31: =(1210+1100)*Q31 -> 2310 | AD31: 0.08 | AE31: =3350*(P31) -> 87100 | AF31: =AD31+(AE31/V31) -> 0.25447917 | AG31: =IFERROR(V31*AF31+3%,0) -> 127036.03 | AH31: =V31/1.1*10%-((AI31*P31)+AG31+(AN31*P31)+(AL31*P31))*10% -> 14904.615 | AI31: =SUMIF([1]헤몬팜마진!$B$7:$B$32,$C31,[1]헤몬팜마진!$V$7:$V$32) -> 6771 | AJ31: =V31-(Y31+AG31+AH31+(AN31*P31)) -> 181213.35 | AK31: =AJ31-Z31-AB31 -> 57185.055 | AL31: =SUMIF([1]헤몬팜마진!$B$7:$B$32,$C31,[1]헤몬팜마진!$T$7:$T$32) -> 65 | AM31: =SUMIF([1]헤몬팜마진!$B$7:$B$32,$C31,[1]헤몬팜마진!$U$7:$U$32) -> 333 | AO31: 32529 | AP31: 132
A32: ACC-TOL-SAW-008-BL | C32: 컷소 배터리 1개 | D32: =AK32/V32 -> 0.10573827 | E32: =AJ32/V32 -> 0.4162598 | F32: =(Z32+AB32)/V32 -> 0.31052152 | G32: =R32/AP32 -> 0.045454545 | H32: 0 | I32: =N32*7 -> 70 | J32: =N32*14 -> 140 | K32: 494 | L32: 0 | N32: 10 | O32: 9 | P32: =O32-S32 -> 9 | Q32: 1 | R32: 7 | T32: =W32*O32 -> 448110 | U32: =W32*S32 -> 0 | V32: =T32-U32 -> 448110 | W32: 49790 | X32: =SUMIF([1]헤몬팜마진!$B$7:$B$32,$C32,[1]헤몬팜마진!$R$7:$R$32) -> 12170 | Y32: =AI32*P32 -> 167184 | Z32: =AA32*1.1 -> 139147.8 | AA32: 126498 | AC32: =(1210+1100)*Q32 -> 2310 | AD32: 0.078 | AE32: =4825*(P32) -> 43425 | AF32: =AD32+(AE32/V32) -> 0.17490701 | AG32: =IFERROR(V32*AF32+3%,0) -> 78377.61 | AH32: =V32/1.1*10%-((AI32*P32)+AG32+(AN32*P32)+(AL32*P32))*10% -> 16018.212 | AI32: =SUMIF([1]헤몬팜마진!$B$7:$B$32,$C32,[1]헤몬팜마진!$V$7:$V$32) -> 18576 | AJ32: =V32-(Y32+AG32+AH32+(AN32*P32)) -> 186530.18 | AK32: =AJ32-Z32-AB32 -> 47382.378 | AL32: =SUMIF([1]헤몬팜마진!$B$7:$B$32,$C32,[1]헤몬팜마진!$T$7:$T$32) -> 181 | AM32: =SUMIF([1]헤몬팜마진!$B$7:$B$32,$C32,[1]헤몬팜마진!$U$7:$U$32) -> 926 | AO32: 33743 | AP32: 154
C33: 컷소 배터리 2개 | D33: =AK33/V33 -> 0.32303148 | E33: =AJ33/V33 -> 0.40846931 | F33: =(Z33+AB33)/V33 -> 0.085437831 | G33: =R33/AP33 -> 0.034682081 | H33: 0 | I33: =N33*7 -> 70 | J33: =N33*14 -> 140 | L33: 1 | N33: 10 | O33: 12 | P33: =O33-S33 -> 12 | Q33: 1 | R33: 6 | T33: =W33*O33 -> 694560 | U33: =W33*S33 -> 0 | V33: =T33-U33 -> 694560 | W33: 57880 | X33: =SUMIF([1]헤몬팜마진!$B$7:$B$32,$C33,[1]헤몬팜마진!$R$7:$R$32) -> 12170 | Y33: =AI33*P33 -> 274512 | Z33: =AA33*1.1 -> 59341.7 | AA33: 53947 | AC33: =(1210+1100)*Q33 -> 2310 | AD33: 0.078 | AE33: =4825*(P33) -> 57900 | AF33: =AD33+(AE33/V33) -> 0.16136213 | AG33: =IFERROR(V33*AF33+3%,0) -> 112075.71 | AH33: =V33/1.1*10%-((AI33*P33)+AG33+(AN33*P33)+(AL33*P33))*10% -> 24265.847 | AI33: =SUMIF([1]헤몬팜마진!$B$7:$B$32,$C33,[1]헤몬팜마진!$V$7:$V$32) -> 22876 | AJ33: =V33-(Y33+AG33+AH33+(AN33*P33)) -> 283706.44 | AK33: =AJ33-Z33-AB33 -> 224364.74 | AL33: =SUMIF([1]헤몬팜마진!$B$7:$B$32,$C33,[1]헤몬팜마진!$T$7:$T$32) -> 181 | AM33: =SUMIF([1]헤몬팜마진!$B$7:$B$32,$C33,[1]헤몬팜마진!$U$7:$U$32) -> 926 | AO33: 32496 | AP33: 173
A34: ACC-BLE-POR-001 | C34: 믹서기 | D34: =AK34/V34 -> 0.32737121 | E34: =AJ34/V34 -> 0.49827708 | F34: =(Z34+AB34)/V34 -> 0.17090587 | G34: =R34/AP34 -> 0.010666667 | H34: 2000 | I34: =N34*7 -> 700 | J34: =N34*14 -> 1400 | K34: 2373 | L34: 3 | N34: 100 | O34: 17 | P34: =O34-S34 -> 17 | Q34: 6 | R34: 4 | T34: =W34*O34 -> 301920 | U34: =W34*S34 -> 0 | V34: =T34-U34 -> 301920 | W34: 17760 | X34: =SUMIF([1]헤몬팜마진!$B$7:$B$32,$C34,[1]헤몬팜마진!$R$7:$R$32) -> 3983 | Y34: =AI34*P34 -> 82229 | Z34: =AA34*1.1 -> 51599.9 | AA34: =26708+20201 -> 46909 | AC34: =(1210+1100)*Q34 -> 13860 | AD34: 0.078 | AE34: =1900*(P34) -> 32300 | AF34: =AD34+(AE34/V34) -> 0.18498198 | AG34: =IFERROR(V34*AF34+3%,0) -> 55849.79 | AH34: =V34/1.1*10%-((AI34*P34)+AG34+(AN34*P34)+(AL34*P34))*10% -> 13401.394 | AI34: =SUMIF([1]헤몬팜마진!$B$7:$B$32,$C34,[1]헤몬팜마진!$V$7:$V$32) -> 4837 | AJ34: =V34-(Y34+AG34+AH34+(AN34*P34)) -> 150439.82 | AK34: =AJ34-Z34-AB34 -> 98839.916 | AL34: =SUMIF([1]헤몬팜마진!$B$7:$B$32,$C34,[1]헤몬팜마진!$T$7:$T$32) -> 140 | AM34: =SUMIF([1]헤몬팜마진!$B$7:$B$32,$C34,[1]헤몬팜마진!$U$7:$U$32) -> 714 | AO34: 68389 | AP34: 375
A35: ACC-CAR-PUM-001-BK | C35: 공기압 주입기 | D35: =AK35/V35 -> 0.43888159 | E35: =AJ35/V35 -> 0.43888159 | F35: =(Z35+AB35)/V35 -> 0 | G35: =R35/AP35 -> #DIV/0! | H35: 0 | I35: =N35*7 -> 350 | J35: =N35*14 -> 700 | K35: 87 | L35: 0 | N35: 50 | O35: -3 | P35: =O35-S35 -> -3 | Q35: 3 | T35: =W35*O35 -> -74400 | U35: =W35*S35 -> 0 | V35: =T35-U35 -> -74400 | W35: 24800 | X35: =SUMIF([1]헤몬팜마진!$B$7:$B$32,$C35,[1]헤몬팜마진!$R$7:$R$32) -> 8408 | Y35: =AI35*P35 -> -25740 | Z35: =AA35*1.1 -> 0 | AC35: =(1210+1100)*Q35 -> 6930 | AD35: 0.1 | AE35: =1900*(P35) -> -5700 | AF35: =AD35+(AE35/V35) -> 0.1766129 | AG35: =IFERROR(V35*AF35+3%,0) -> -13139.97 | AH35: =V35/1.1*10%-((AI35*P35)+AG35+(AN35*P35)+(AL35*P35))*10% -> -2867.2394 | AI35: =SUMIF([1]헤몬팜마진!$B$7:$B$32,$C35,[1]헤몬팜마진!$V$7:$V$32) -> 8580 | AJ35: =V35-(Y35+AG35+AH35+(AN35*P35)) -> -32652.791 | AK35: =AJ35-Z35-AB35 -> -32652.791 | AL35: =SUMIF([1]헤몬팜마진!$B$7:$B$32,$C35,[1]헤몬팜마진!$T$7:$T$32) -> 28 | AM35: =SUMIF([1]헤몬팜마진!$B$7:$B$32,$C35,[1]헤몬팜마진!$U$7:$U$32) -> 143
B36: 오픈이어 (신제품) | C36: 골전도이어폰 | D36: =AK36/V36 -> -0.43035807 | E36: =AJ36/V36 -> 0.37867669 | F36: =(Z36+AB36)/V36 -> 0.80903476 | G36: =R36/AP36 -> 0.033195021 | H36: 700 | I36: =N36*7 -> 210 | J36: =N36*14 -> 420 | K36: 954 | L36: 2 | N36: 30 | O36: 27 | P36: =O36-S36 -> 17 | Q36: 2 | R36: 16 | S36: 10 | T36: =W36*O36 -> 534600 | U36: =W36*S36 -> 198000 | V36: =T36-U36 -> 336600 | W36: 19800 | X36: =SUMIF([1]헤몬팜마진!$B$7:$B$32,$C36,[1]헤몬팜마진!$R$7:$R$32) -> 6638 | Y36: =AI36*P36 -> 113662 | Z36: =AA36*1.1 -> 167476.1 | AA36: 152251 | AB36: =((20900*0.015)+(20900*0.19)+2100+2200+1900)*10 -> 104845 | AC36: =(1210+1100)*Q36 -> 4620 | AD36: 0.08 | AE36: =3400*(P36) -> 57800 | AF36: =AD36+(AE36/V36) -> 0.25171717 | AG36: =IFERROR(V36*AF36+3%,0) -> 84728.03 | AH36: =V36/1.1*10%-((AI36*P36)+AG36+(AN36*P36)+(AL36*P36))*10% -> 10747.397 | AI36: =SUMIF([1]헤몬팜마진!$B$7:$B$32,$C36,[1]헤몬팜마진!$V$7:$V$32) -> 6686 | AJ36: =V36-(Y36+AG36+AH36+(AN36*P36)) -> 127462.57 | AK36: =AJ36-Z36-AB36 -> -144858.53 | AL36: =SUMIF([1]헤몬팜마진!$B$7:$B$32,$C36,[1]헤몬팜마진!$T$7:$T$32) -> 8 | AM36: =SUMIF([1]헤몬팜마진!$B$7:$B$32,$C36,[1]헤몬팜마진!$U$7:$U$32) -> 40 | AO36: 359020 | AP36: 482
A37: ACC-SHA-PET-002-WH | B37: 멀티클리퍼 (신제품) | C37: 강아지바리깡 | D37: =AK37/V37 -> 0.27162505 | E37: =AJ37/V37 -> 0.43443625 | F37: =(Z37+AB37)/V37 -> 0.1628112 | G37: =R37/AP37 -> 0.14705882 | H37: 2000 | I37: =N37*7 -> 280 | J37: =N37*14 -> 560 | K37: 1048 | L37: =311+240+1 -> 552 | N37: 40 | O37: 29 | P37: =O37-S37 -> 29 | Q37: 6 | R37: 20 | T37: =W37*O37 -> 718910 | U37: =W37*S37 -> 0 | V37: =T37-U37 -> 718910 | W37: 24790 | X37: =SUMIF([1]헤몬팜마진!$B$7:$B$32,$C37,[1]헤몬팜마진!$R$7:$R$32) -> 6859 | Y37: =AI37*P37 -> 210366 | Z37: =AA37*1.1 -> 117046.6 | AA37: 106406 | AC37: =(1210+1100)*Q37 -> 13860 | AD37: 0.108 | AE37: =3150*(P37) -> 91350 | AF37: =AD37+(AE37/V37) -> 0.23506737 | AG37: =IFERROR(V37*AF37+3%,0) -> 168992.31 | AH37: =V37/1.1*10%-((AI37*P37)+AG37+(AN37*P37)+(AL37*P37))*10% -> 27231.124 | AI37: =SUMIF([1]헤몬팜마진!$B$7:$B$32,$C37,[1]헤몬팜마진!$V$7:$V$32) -> 7254 | AJ37: =V37-(Y37+AG37+AH37+(AN37*P37)) -> 312320.57 | AK37: =AJ37-Z37-AB37 -> 195273.97 | AL37: =SUMIF([1]헤몬팜마진!$B$7:$B$32,$C37,[1]헤몬팜마진!$T$7:$T$32) -> 65 | AM37: =SUMIF([1]헤몬팜마진!$B$7:$B$32,$C37,[1]헤몬팜마진!$U$7:$U$32) -> 330 | AO37: 38190 | AP37: 136
B38: 신제품 | C38: 강아지바리깡 2개 | D38: =AK38/V38 -> #DIV/0! | E38: =AJ38/V38 -> #DIV/0! | F38: =(Z38+AB38)/V38 -> #DIV/0! | G38: =R38/AP38 -> 0 | H38: 0 | I38: =N38*7 -> 105 | J38: =N38*14 -> 210 | L38: =22+3 -> 25 | N38: 15 | O38: 0 | P38: =O38-S38 -> 0 | T38: =W38*O38 -> 0 | U38: =W38*S38 -> 0 | V38: =T38-U38 -> 0 | W38: 39800 | X38: =SUMIF([1]헤몬팜마진!$B$7:$B$32,$C38,[1]헤몬팜마진!$R$7:$R$32) -> 13719 | Y38: =AI38*P38 -> 0 | Z38: =AA38*1.1 -> 47648.7 | AA38: 43317 | AC38: =(1210+1100)*Q38 -> 0 | AD38: 0.108 | AE38: =3550*(P38) -> 0 | AF38: =AD38+(AE38/V38) -> #DIV/0! | AG38: =IFERROR(V38*AF38+3%,0) -> 0 | AH38: =V38/1.1*10%-((AI38*P38)+AG38+(AN38*P38)+(AL38*P38))*10% -> 0 | AI38: =SUMIF([1]헤몬팜마진!$B$7:$B$32,$C38,[1]헤몬팜마진!$V$7:$V$32) -> 14113 | AJ38: =V38-(Y38+AG38+AH38+(AN38*P38)) -> 0 | AK38: =AJ38-Z38-AB38 -> -47648.7 | AL38: =SUMIF([1]헤몬팜마진!$B$7:$B$32,$C38,[1]헤몬팜마진!$T$7:$T$32) -> 65 | AM38: =SUMIF([1]헤몬팜마진!$B$7:$B$32,$C38,[1]헤몬팜마진!$U$7:$U$32) -> 330 | AO38: 45068 | AP38: 101
D39: =AK39/V39 -> 0.1556276 | E39: =AJ39/V39 -> 0.41371349 | F39: =(Z39+AB39)/V39 -> 0.2580859 | O39: =SUM(O22:O38) -> 346 | P39: =SUM(P22:P38) -> 336 | Q39: =SUM(Q22:Q38) -> 33 | R39: =SUM(R22:R38) -> 237 | S39: =SUM(S22:S38) -> 10 | T39: =SUM(T22:T38) -> 9712960 | U39: =SUM(U22:U38) -> 198000 | V39: =SUM(V22:V38) -> 9514960 | X39: =SUM(X22:X38) -> 153583 | Y39: =SUM(Y22:Y38) -> 3268534 | Z39: =SUM(Z22:Z38) -> 2350832 | AA39: =SUM(AA22:AA38) -> 2137120 | AB39: =SUM(AB22:AB38) -> 104845 | AC39: =SUM(AC22:AC38) -> 74850 | AD39: 0.09 | AE39: =SUM(AE22:AE38) -> 1074625 | AF39: =AD39+(AE39/V39) -> 0.20294057 | AG39: =SUM(AG22:AG38) -> 1971636.4 | AH39: =SUM(AH22:AH38) -> 338322.22 | AI39: =SUM(AI22:AI38) -> 233199 | AJ39: =V39-(Y39+AG39+AH39+(AN39*P39)) -> 3936467.3 | AK39: =AJ39-Z39-AB39 -> 1480790.3 | AO39: =SUM(AO22:AO23) -> 384885 | AP39: =SUM(AP22:AP23) -> 1996
C41: 45947 | D41: 이윤율 | E41: 마진율 | F41: 광고비율 | G41: 전환율 | H41: 발주남은수량 | I41: 창고안전 | J41: 쿠팡안전 | K41: 창고재고 | L41: 쿠팡재고 | M41: 미포장분 | N41: 목표판매량 | O41: 판매수 | P41: 순판매개수 | Q41: 취소개수 | R41: 광고전환 | S41: 가구매 | T41: 매출 | U41: 가구매금액 | V41: 순매출 | W41: 판매가 | X41: 입고가 | Y41: 입고판매가 | Z41: 광고비1.1 | AA41: 광고비 | AB41: 가구매비용 | AC41: 반품회수비 | AD41: 수수료 | AE41: 택배비 | AF41: 판매수수료 | AG41: 수수료 | AH41: 부가세 | AI41: 도매가 | AJ41: 판매마진 | AK41: 순이익 | AL41: 1개당 한국 운임 물류비(KRW) | AM41: 1개당 물류비 (KRW) | AN41: 부자재값 | AO41: 노출수 | AP41: 클릭수
A42: ACC-SHA-BRD-001-BK | C42: 쉐이버 | D42: =AK42/V42 -> 0.16826857 | E42: =AJ42/V42 -> 0.42271098 | F42: =(Z42+AB42)/V42 -> 0.2544424 | G42: =R42/AP42 -> 0.072410632 | H42: 7410 | I42: =N42*7 -> 1400 | J42: =N42*14 -> 2800 | K42: 76 | L42: =1906+1320 -> 3226 | N42: 200 | O42: 195 | P42: =O42-S42 -> 195 | Q42: 14 | R42: 158 | T42: =W42*O42 -> 5440500 | U42: =W42*S42 -> 0 | V42: =T42-U42 -> 5440500 | W42: 27900 | X42: =SUMIF([1]헤몬팜마진!$B$7:$B$32,$C42,[1]헤몬팜마진!$R$7:$R$32) -> 8851 | Y42: =AI42*P42 -> 1802775 | Z42: =AA42*1.1 -> 1384293.9 | AA42: 1258449 | AC42: =(1072+1100)*Q42 -> 30408 | AD42: 0.1 | AE42: =3050*(P42) -> 594750 | AF42: =AD42+(AE42/V42) -> 0.209319 | AG42: =IFERROR(V42*AF42+3%,0) -> 1138800 | AH42: =V42/1.1*10%-((AI42*P42)+AG42+(AN42*P42)+(AL42*P42))*10% -> 199165.91 | AI42: =SUMIF([1]헤몬팜마진!$B$7:$B$32,$C42,[1]헤몬팜마진!$V$7:$V$32) -> 9245 | AJ42: =V42-(Y42+AG42+AH42+(AN42*P42)) -> 2299759.1 | AK42: =AJ42-Z42-AB42 -> 915465.16 | AL42: =SUMIF([1]헤몬팜마진!$B$7:$B$32,$C42,[1]헤몬팜마진!$T$7:$T$32) -> 65 | AM42: =SUMIF([1]헤몬팜마진!$B$7:$B$32,$C42,[1]헤몬팜마진!$U$7:$U$32) -> 330 | AO42: 405479 | AP42: 2182
...
