Workbook

Sheet 헤몬스토어
K1: 헤몬 마진계산기 (2025-08-08 개정본)
K3: 1. 중국환률(AA)와 미국환률(AB)로 인해 비용차이가 많이 발생할 수 있으니 1달 평균으로 사용하기 바람. 2. 2개 구성으로 파는 제품은 물류비와 같은 부분은 X2를 해야하니 계산에 참고하기 바람 3. 사은품 증정되거나 물건이 각각 들어와서 합포장 하는 경우 물류비와 원가를 따로 계산하여 도매가에 포함시켜야 함.(물류비 계산 정확히 하기 위함) | AE3: 중국환률 (CNY) | AF3: 미국환률 (USD)
AE4: 192.41 | AF4: 1385
A5: 자동 | C5: 자동 | D5: 수동 | G5: 자동 | N5: 수동 | Q5: 자동 | V5: 수동 | Z5: 자동 | AE5: 관세율
A6: No | B6: 상품명 | C6: 단위기준 | D6: 넓이 | E6: 폭 | F6: 높이 | G6: 합산 | H6: 개별 박스 CBM | I6: 1CBM 적재가능수량 | J6: 1개당 중국 운임물류비(USD) | K6: 1개당 한국 운임 물류비(KRW) | L6: 1개당 물류비 (KRW) | M6: 원가대비 물류비 비율 | N6: 부자재값 (BOX) | O6: 관세율 | P6: 순수 중국원가 | Q6: 수수료포함 중국원가 | R6: 한국원가 | S6: 관세 | T6: 물류비 | U6: 도매가 | V6: 판매가 택배비 포함 | W6: 마켓수수료 | Y6: N배송 입출고비용 | Z6: 총 수수료(%) | AA6: 총 수수료 (원) | AB6: 부가세 | AC6: 판매마진 | AD6: 제품순이익% | AE6: 제품명(영어) | AF6: 제품명(한국) | AG6: %
B7: 클린스톰 | C7: c m | D7: 23 | E7: 6 | F7: 6 | G7: =PRODUCT(D7*E7*F7) -> 828 | H7: =G7/1000000 -> 0.000828 | I7: =1/H7 -> 1207.7295 | J7: =80/I7 -> 0.06624 | K7: =27000/I7 -> 22.356 | L7: =(J7*$AF$4)+K7 -> 114.0984 | M7: =T7/R7 -> 0.026581169 | N7: 176 | O7: =SUMIF($AE$6:$AG$30,$A7,$AG$6:$AG$30) -> 0 | P7: 23.2 | Q7: =P7*1.15 -> 26.68 | R7: =Q7*$AE$4 -> 5133.4988 | S7: =R7*O7 -> 0 | T7: =L7+K7 -> 136.4544 | U7: =R7+S7+T7 -> 5269.9532 | V7: 19900 | W7: 0.0813 | Y7: 3003 | Z7: =W7+(Y7/V7) -> 0.23220452 | AA7: =V7*Z7 -> 4620.87 | AB7: =(V7)/1.1*10%-(R7+AA7+K7+S7+N7)*10% -> 813.81843 | AC7: =V7-(U7+AA7+AB7) -> 9195.3584 | AD7: =AC7/V7 -> 0.46207831 | AE7: SCREWDRIVER | AG7: 0.08
B8: 클린스톰 1+1 | K8: =K7*2 -> 44.712 | L8: =L7*2 -> 228.1968 | N8: 176 | P8: =P7*2 -> 46.4 | Q8: =P8*1.15 -> 53.36 | R8: =Q8*$AE$4 -> 10266.998 | T8: =L8+K8 -> 272.9088 | U8: =U7*2 -> 10539.906 | V8: 38300 | W8: 0.0813 | Y8: 3003 | Z8: =W8+(Y8/V8) -> 0.15970731 | AA8: =V8*Z8 -> 6116.79 | AB8: =(V8)/1.1*10%-(R8+AA8+K8+S8+N8)*10% -> 1821.3682 | AC8: =V8-(U8+AA8+AB8) -> 19821.935 | AD8: =AC8/V8 -> 0.517544
B9: 쉐이버 | C9: c m | D9: 23 | E9: 13 | F9: 8 | G9: =PRODUCT(D9*E9*F9) -> 2392 | H9: =G9/1000000 -> 0.002392 | I9: =1/H9 -> 418.0602 | J9: =80/I9 -> 0.19136 | K9: =27000/I9 -> 64.584 | L9: =(J9*$AF$4)+K9 -> 329.6176 | M9: =T9/R9 -> 0.044538226 | N9: 176 | O9: =SUMIF($AE$6:$AG$30,$A9,$AG$6:$AG$30) -> 0 | P9: 40 | Q9: =P9*1.15 -> 46 | R9: =Q9*$AE$4 -> 8850.86 | S9: =R9*O9 -> 0 | T9: =L9+K9 -> 394.2016 | U9: =R9+S9+T9 -> 9245.0616 | V9: 29800 | W9: 0.0813 | Y9: 3003 | Z9: =W9+(Y9/V9) -> 0.18207181 | AA9: =V9*Z9 -> 5425.74 | AB9: =(V9)/1.1*10%-(R9+AA9+K9+S9+N9)*10% -> 1257.3725 | AC9: =V9-(U9+AA9+AB9) -> 13871.826 | AD9: =AC9/V9 -> 0.46549751 | AE9: DOLL | AG9: 0.021
B10: 워터스톰 | C10: c m | D10: 23 | E10: 9 | F10: 7 | G10: =PRODUCT(D10*E10*F10) -> 1449 | H10: =G10/1000000 -> 0.001449 | I10: =1/H10 -> 690.13112 | J10: =80/I10 -> 0.11592 | K10: =27000/I10 -> 39.123 | L10: =(J10*$AF$4)+K10 -> 199.6722 | M10: =T10/R10 -> 0.030834156 | N10: 176 | O10: =SUMIF($AE$6:$AG$30,$A10,$AG$6:$AG$30) -> 0 | P10: 35 | Q10: =P10*1.15 -> 40.25 | R10: =Q10*$AE$4 -> 7744.5025 | S10: =R10*O10 -> 0 | T10: =L10+K10 -> 238.7952 | U10: =R10+S10+T10 -> 7983.2977 | V10: 29800 | W10: 0.0813 | Y10: 3003 | Z10: =W10+(Y10/V10) -> 0.18207181 | AA10: =V10*Z10 -> 5425.74 | AB10: =(V10)/1.1*10%-(R10+AA10+K10+S10+N10)*10% -> 1370.5544 | AC10: =V10-(U10+AA10+AB10) -> 15020.408 | AD10: =AC10/V10 -> 0.50404053 | AE10: SILICONE BRACELET | AG10: 0.017
B11: 테이블에어 | C11: c m | D11: 23 | E11: 15 | F11: 12 | G11: =PRODUCT(D11*E11*F11) -> 4140 | H11: =G11/1000000 -> 0.00414 | I11: =1/H11 -> 241.54589 | J11: =80/I11 -> 0.3312 | K11: =27000/I11 -> 111.78 | L11: =(J11*$AF$4)+K11 -> 570.492 | M11: =T11/R11 -> 0.11859291 | N11: 176 | O11: =SUMIF($AE$6:$AG$30,$A11,$AG$6:$AG$30) -> 0 | P11: 26 | Q11: =P11*1.15 -> 29.9 | R11: =Q11*$AE$4 -> 5753.059 | S11: =R11*O11 -> 0 | T11: =L11+K11 -> 682.272 | U11: =R11+S11+T11 -> 6435.331 | V11: 23900 | W11: 0.0813 | Y11: 3003 | Z11: =W11+(Y11/V11) -> 0.20694854 | AA11: =V11*Z11 -> 4946.07 | AB11: =(V11)/1.1*10%-(R11+AA11+K11+S11+N11)*10% -> 1074.0364 | AC11: =V11-(U11+AA11+AB11) -> 11444.563 | AD11: =AC11/V11 -> 0.47885199 | AE11: COURIER BAG | AG11: 0.017
B12: 전동칫솔 | C12: c m | D12: 25 | E12: 7 | F12: 3 | G12: =PRODUCT(D12*E12*F12) -> 525 | H12: =G12/1000000 -> 0.000525 | I12: =1/H12 -> 1904.7619 | J12: =80/I12 -> 0.042 | K12: =27000/I12 -> 14.175 | L12: =(J12*$AF$4)+K12 -> 72.345 | M12: =T12/R12 -> 0.017000559 | N12: 176 | O12: =SUMIF($AE$6:$AG$30,$A12,$AG$6:$AG$30) -> 0 | P12: 23 | Q12: =P12*1.15 -> 26.45 | R12: =Q12*$AE$4 -> 5089.2445 | S12: =R12*O12 -> 0 | T12: =L12+K12 -> 86.52 | U12: =R12+S12+T12 -> 5175.7645 | V12: 21900 | W12: 0.0813 | Y12: 3003 | Z12: =W12+(Y12/V12) -> 0.21842329 | AA12: =V12*Z12 -> 4783.47 | AB12: =(V12)/1.1*10%-(R12+AA12+K12+S12+N12)*10% -> 984.62014 | AC12: =V12-(U12+AA12+AB12) -> 10956.145 | AD12: =AC12/V12 -> 0.50028061 | AE12: CRYOSPHERE | AG12: 0.017
B13: 애풍이 | C13: c m | D13: 21 | E13: 11 | F13: 5 | G13: =PRODUCT(D13*E13*F13) -> 1155 | H13: =G13/1000000 -> 0.001155 | I13: =1/H13 -> 865.80087 | J13: =80/I13 -> 0.0924 | K13: =27000/I13 -> 31.185 | L13: =(J13*$AF$4)+K13 -> 159.159 | M13: =T13/R13 -> 0.061444877 | N13: 176 | O13: =SUMIF($AE$6:$AG$30,$A13,$AG$6:$AG$30) -> 0 | P13: 14 | Q13: =P13*1.15 -> 16.1 | R13: =Q13*$AE$4 -> 3097.801 | S13: =R13*O13 -> 0 | T13: =L13+K13 -> 190.344 | U13: =R13+S13+T13 -> 3288.145 | V13: 14900 | W13: 0.0813 | Y13: 3003 | Z13: =W13+(Y13/V13) -> 0.28284362 | AA13: =V13*Z13 -> 4214.37 | AB13: =(V13)/1.1*10%-(R13+AA13+K13+S13+N13)*10% -> 602.60985 | AC13: =V13-(U13+AA13+AB13) -> 6794.8751 | AD13: =AC13/V13 -> 0.45603189 | AE13: SCISSORES | AG13: 0.021
B14: 에그포그 | C14: c m | D14: 18 | E14: 13 | F14: 13 | G14: =PRODUCT(D14*E14*F14) -> 3042 | H14: =G14/1000000 -> 0.003042 | I14: =1/H14 -> 328.7311 | J14: =80/I14 -> 0.24336 | K14: =27000/I14 -> 82.134 | L14: =(J14*$AF$4)+K14 -> 419.1876 | M14: =T14/R14 -> 0.090625607 | N14: 176 | O14: =SUMIF($AE$6:$AG$30,$A14,$AG$6:$AG$30) -> 0 | P14: 25 | Q14: =P14*1.15 -> 28.75 | R14: =Q14*$AE$4 -> 5531.7875 | S14: =R14*O14 -> 0 | T14: =L14+K14 -> 501.3216 | U14: =R14+S14+T14 -> 6033.1091 | V14: 23900 | W14: 0.0813 | Y14: 3003 | Z14: =W14+(Y14/V14) -> 0.20694854 | AA14: =V14*Z14 -> 4946.07 | AB14: =(V14)/1.1*10%-(R14+AA14+K14+S14+N14)*10% -> 1099.1281 | AC14: =V14-(U14+AA14+AB14) -> 11821.693 | AD14: =AC14/V14 -> 0.4946315 | AE14: PILLOWS | AG14: 0.021
B15: 쿨링팬 | C15: c m | D15: 16 | E15: 6 | F15: 4 | G15: =PRODUCT(D15*E15*F15) -> 384 | H15: =G15/1000000 -> 0.000384 | I15: =1/H15 -> 2604.1667 | J15: =80/I15 -> 0.03072 | K15: =27000/I15 -> 10.368 | L15: =(J15*$AF$4)+K15 -> 52.9152 | M15: =T15/R15 -> 0.009861999 | N15: 176 | O15: =SUMIF($AE$6:$AG$30,$A15,$AG$6:$AG$30) -> 0 | P15: 29 | Q15: =P15*1.15 -> 33.35 | R15: =Q15*$AE$4 -> 6416.8735 | S15: =R15*O15 -> 0 | T15: =L15+K15 -> 63.2832 | U15: =R15+S15+T15 -> 6480.1567 | V15: 19900 | W15: 0.0813 | Y15: 3003 | Z15: =W15+(Y15/V15) -> 0.23220452 | AA15: =V15*Z15 -> 4620.87 | AB15: =(V15)/1.1*10%-(R15+AA15+K15+S15+N15)*10% -> 686.67976 | AC15: =V15-(U15+AA15+AB15) -> 8112.2935 | AD15: =AC15/V15 -> 0.40765294 | AE15: BIT | AG15: 0.08
B16: 쿨링팬 1+1 | U16: =U15*2 -> 12960.313 | V16: 37700 | W16: 0.0813 | Y16: 3003 | Z16: =W16+(Y16/V16) -> 0.16095517 | AA16: =V16*Z16 -> 6068.01 | AB16: =(V16)/1.1*10%-(R16+AA16+K16+S16+N16)*10% -> 2820.4717 | AC16: =V16-(U16+AA16+AB16) -> 15851.205 | AD16: =AC16/V16 -> 0.42045636
B17: 버그트랩 (화이트) | C17: c m | D17: 22 | E17: 32 | F17: 5 | G17: =PRODUCT(D17*E17*F17) -> 3520 | H17: =G17/1000000 -> 0.00352 | I17: =1/H17 -> 284.09091 | J17: =80/I17 -> 0.2816 | K17: =27000/I17 -> 95.04 | L17: =(J17*$AF$4)+K17 -> 485.056 | M17: =T17/R17 -> 0.13798148 | N17: 319 | O17: =SUMIF($AE$6:$AG$30,$A17,$AG$6:$AG$30) -> 0 | P17: 19 | Q17: =P17*1.15 -> 21.85 | R17: =Q17*$AE$4 -> 4204.1585 | S17: =R17*O17 -> 0 | T17: =L17+K17 -> 580.096 | U17: =R17+S17+T17 -> 4784.2545 | V17: 19900 | W17: 0.0813 | Y17: 3146 | Z17: =W17+(Y17/V17) -> 0.23939045 | AA17: =V17*Z17 -> 4763.87 | AB17: =(V17)/1.1*10%-(R17+AA17+K17+S17+N17)*10% -> 870.88406 | AC17: =V17-(U17+AA17+AB17) -> 9480.9914 | AD17: =AC17/V17 -> 0.47643173 | AE17: BAG | AG17: 0.021
B18: 버그트랩 (블랙) | C18: c m | D18: 22 | E18: 32 | F18: 5 | G18: =PRODUCT(D18*E18*F18) -> 3520 | H18: =G18/1000000 -> 0.00352 | I18: =1/H18 -> 284.09091 | J18: =80/I18 -> 0.2816 | K18: =27000/I18 -> 95.04 | L18: =(J18*$AF$4)+K18 -> 485.056 | M18: =T18/R18 -> 0.13798148 | N18: 319 | O18: =SUMIF($AE$6:$AG$30,$A18,$AG$6:$AG$30) -> 0 | P18: 19 | Q18: =P18*1.15 -> 21.85 | R18: =Q18*$AE$4 -> 4204.1585 | S18: =R18*O18 -> 0 | T18: =L18+K18 -> 580.096 | U18: =R18+S18+T18 -> 4784.2545 | V18: 19900 | W18: 0.0813 | Y18: 3146 | Z18: =W18+(Y18/V18) -> 0.23939045 | AA18: =V18*Z18 -> 4763.87 | AB18: =(V18)/1.1*10%-(R18+AA18+K18+S18+N18)*10% -> 870.88406 | AC18: =V18-(U18+AA18+AB18) -> 9480.9914 | AD18: =AC18/V18 -> 0.47643173 | AE18: BAG | AG18: 0.021
B19: 버그트랩 1+1 | N19: 319 | O19: =SUMIF($AE$6:$AG$30,$A19,$AG$6:$AG$30) -> 0 | P19: 19 | Q19: =P19*1.15 -> 21.85 | R19: =Q19*$AE$4 -> 4204.1585 | S19: =R19*O19 -> 0 | T19: =L19+K19 -> 0 | U19: =U18*2 -> 9568.509 | V19: 38800 | W19: 0.0813 | Y19: 3146 | Z19: =W19+(Y19/V19) -> 0.16238247 | AA19: =V19*Z19 -> 6300.44 | AB19: =(V19)/1.1*10%-(R19+AA19+K19+S19+N19)*10% -> 2444.9129 | AC19: =V19-(U19+AA19+AB19) -> 20486.138 | AD19: =AC19/V19 -> 0.52799325
B20: 모기패치 스티커 | C20: c m | D20: 13 | E20: 8 | F20: 0.1 | G20: =PRODUCT(D20*E20*F20) -> 10.4 | H20: =G20/1000000 -> 1.04e-05 | I20: =1/H20 -> 96153.846 | J20: =80/I20 -> 0.000832 | K20: =27000/I20 -> 0.2808 | L20: =(J20*$AF$4)+K20 -> 1.43312 | M20: =T20/R20 -> 0.015491557 | O20: =SUMIF($AE$6:$AG$30,$A20,$AG$6:$AG$30) -> 0 | P20: 0.5 | Q20: =P20*1.15 -> 0.575 | R20: =Q20*$AE$4 -> 110.63575 | S20: =R20*O20 -> 0 | T20: =L20+K20 -> 1.71392 | U20: =R20+S20+T20 -> 112.34967 | V20: 6000 | W20: 0.0813 | Z20: =W20+(Y20/V20) -> 0.0813 | AA20: =V20*Z20 -> 487.8 | AB20: =(V20)/1.1*10%-(R20+AA20+K20+S20+N20)*10% -> 485.58289 | AC20: =V20-(U20+AA20+AB20) -> 4914.2674 | AD20: =AC20/V20 -> 0.81904457
B21: 폴드스윙 | C21: c m | D21: 23 | E21: 24 | F21: 5 | G21: =PRODUCT(D21*E21*F21) -> 2760 | H21: =G21/1000000 -> 0.00276 | I21: =1/H21 -> 362.31884 | J21: =80/I21 -> 0.2208 | K21: =27000/I21 -> 74.52 | L21: =(J21*$AF$4)+K21 -> 380.328 | M21: =T21/R21 -> 0.12688953 | N21: 286 | O21: =SUMIF($AE$6:$AG$30,$A21,$AG$6:$AG$30) -> 0 | P21: 16.2 | Q21: =P21*1.15 -> 18.63 | R21: =Q21*$AE$4 -> 3584.5983 | S21: =R21*O21 -> 0 | T21: =L21+K21 -> 454.848 | U21: =R21+S21+T21 -> 4039.4463 | V21: 19900 | W21: 0.0813 | Y21: 3113 | Z21: =W21+(Y21/V21) -> 0.23773216 | AA21: =V21*Z21 -> 4730.87 | AB21: =(V21)/1.1*10%-(R21+AA21+K21+S21+N21)*10% -> 941.49208 | AC21: =V21-(U21+AA21+AB21) -> 10188.192 | AD21: =AC21/V21 -> 0.51196943 | AE21: CAR CUSHION | AG21: 0.017
B22: 폴드스윙 1+1 | P22: =P21*2 -> 32.4 | Q22: =P22*1.15 -> 37.26 | U22: =U21*2 -> 8078.8926 | V22: 36700 | W22: 0.0813 | Y22: 3113 | Z22: =W22+(Y22/V22) -> 0.16612289 | AA22: =V22*Z22 -> 6096.71 | AB22: =(V22)/1.1*10%-(R22+AA22+K22+S22+N22)*10% -> 2726.6926 | AC22: =V22-(U22+AA22+AB22) -> 19797.705 | AD22: =AC22/V22 -> 0.539447
B23: 모기패치 스티커 | C23: c m | D23: 13 | E23: 8 | F23: 0.1 | G23: =PRODUCT(D23*E23*F23) -> 10.4 | H23: =G23/1000000 -> 1.04e-05 | I23: =1/H23 -> 96153.846 | J23: =80/I23 -> 0.000832 | K23: =27000/I23 -> 0.2808 | L23: =(J23*$AF$4)+K23 -> 1.43312 | M23: =T23/R23 -> 0.015491557 | O23: =SUMIF($AE$6:$AG$30,$A23,$AG$6:$AG$30) -> 0 | P23: 0.5 | Q23: =P23*1.15 -> 0.575 | R23: =Q23*$AE$4 -> 110.63575 | S23: =R23*O23 -> 0 | T23: =L23+K23 -> 1.71392 | U23: =R23+S23+T23 -> 112.34967 | V23: 6000 | W23: 0.0813 | Z23: =W23+(Y23/V23) -> 0.0813 | AA23: =V23*Z23 -> 487.8 | AB23: =(V23)/1.1*10%-(R23+AA23+K23+S23+N23)*10% -> 485.58289 | AC23: =V23-(U23+AA23+AB23) -> 4914.2674 | AD23: =AC23/V23 -> 0.81904457
B24: 넥쿨러 1+1 | C24: c m | D24: 18 | E24: 18 | F24: 3 | G24: =PRODUCT(D24*E24*F24) -> 972 | H24: =G24/1000000 -> 0.000972 | I24: =1/H24 -> 1028.8066 | J24: =80/I24 -> 0.07776 | K24: =27000/I24 -> 26.244 | L24: =(J24*$AF$4)+K24 -> 133.9416 | M24: =T24/R24 -> 0.12065539 | N24: 176 | O24: 0.017 | P24: 6 | Q24: =P24*1.15 -> 6.9 | R24: =Q24*$AE$4 -> 1327.629 | S24: =R24*O24 -> 22.569693 | T24: =L24+K24 -> 160.1856 | U24: =(R24+S24+T24)*2+(U26*2) -> 3464.7372 | V24: 12900 | W24: 0.0813 | Y24: 3003 | Z24: =W24+(Y24/V24) -> 0.3140907 | AA24: =V24*Z24 -> 4051.77 | AB24: =(V24)/1.1*10%-(R24+AA24+K24+S24+N24)*10% -> 612.306 | AC24: =V24-(U24+AA24+AB24) -> 4771.1868 | AD24: =AC24/V24 -> 0.36985944 | AE24: ELECTRIC SAW | AG24: 0.021
B25: 넥쿨러 | C25: c m | D25: 18 | E25: 18 | F25: 3 | G25: =PRODUCT(D25*E25*F25) -> 972 | H25: =G25/1000000 -> 0.000972 | I25: =1/H25 -> 1028.8066 | J25: =80/I25 -> 0.07776 | K25: =27000/I25 -> 26.244 | L25: =(J25*$AF$4)+K25 -> 133.9416 | M25: =T25/R25 -> 0.12065539 | N25: 176 | O25: 0.017 | P25: 6 | Q25: =P25*1.15 -> 6.9 | R25: =Q25*$AE$4 -> 1327.629 | S25: =R25*O25 -> 22.569693 | T25: =L25+K25 -> 160.1856 | U25: =R25+S25+T25+U26 -> 1732.3686 | V25: 12900 | W25: 0.0813 | Y25: 3003 | Z25: =W25+(Y25/V25) -> 0.3140907 | AA25: =V25*Z25 -> 4051.77 | AB25: =(V25)/1.1*10%-(R25+AA25+K25+S25+N25)*10% -> 612.306 | AC25: =V25-(U25+AA25+AB25) -> 6503.5554 | AD25: =AC25/V25 -> 0.50415158
B26: 쿨스카프 | C26: c m | D26: 12 | E26: 22 | F26: 0.1 | G26: =PRODUCT(D26*E26*F26) -> 26.4 | H26: =G26/1000000 -> 2.64e-05 | I26: =1/H26 -> 37878.788 | J26: =80/I26 -> 0.002112 | K26: =27000/I26 -> 0.7128 | L26: =(J26*$AF$4)+K26 -> 3.63792 | M26: =T26/R26 -> 0.0032213819 | O26: =SUMIF($AE$6:$AG$30,$A26,$AG$6:$AG$30) -> 0 | P26: 1 | Q26: =P26*1.15 -> 1.15 | R26: =Q26*$AE$4 -> 221.2715 | S26: =R26*O26 -> 0 | T26: =K26 -> 0.7128 | U26: =R26+S26+T26 -> 221.9843 | W26: 0.0813 | Z26: =W26+(Y26/V26) -> #DIV/0! | AA26: =V26*Z26 -> #DIV/0! | AB26: =(V26)/1.1*10%-(R26+AA26+K26+S26+N26)*10% -> #DIV/0! | AC26: =V26-(U26+AA26+AB26) -> #DIV/0! | AD26: =AC26/V26 -> #DIV/0!
B27: 모기지옥 | C27: c m | D27: 20 | E27: 11 | F27: 11 | G27: =PRODUCT(D27*E27*F27) -> 2420 | H27: =G27/1000000 -> 0.00242 | I27: =1/H27 -> 413.22314 | J27: =80/I27 -> 0.1936 | K27: =27000/I27 -> 65.34 | L27: =(J27*$AF$4)+K27 -> 333.476 | M27: =T27/R27 -> 0.062582745 | N27: 176 | O27: =SUMIF($AE$6:$AG$30,$A27,$AG$6:$AG$30) -> 0 | P27: 28.8 | Q27: =P27*1.15 -> 33.12 | R27: =Q27*$AE$4 -> 6372.6192 | S27: =R27*O27 -> 0 | T27: =L27+K27 -> 398.816 | U27: =R27+S27+T27 -> 6771.4352 | V27: 23900 | W27: 0.0813 | Y27: 3003 | Z27: =W27+(Y27/V27) -> 0.20694854 | AA27: =V27*Z27 -> 4946.07 | AB27: =(V27)/1.1*10%-(R27+AA27+K27+S27+N27)*10% -> 1016.7244 | AC27: =V27-(U27+AA27+AB27) -> 11165.77 | AD27: =AC27/V27 -> 0.46718705 | AE27: ANGLE GRINDER | AG27: 0.08
B28: 모기지옥 무선 | C28: c m | D28: 20 | E28: 11 | F28: 11 | G28: =PRODUCT(D28*E28*F28) -> 2420 | H28: =G28/1000000 -> 0.00242 | I28: =1/H28 -> 413.22314 | J28: =80/I28 -> 0.1936 | K28: =27000/I28 -> 65.34 | L28: =(J28*$AF$4)+K28 -> 333.476 | M28: =T28/R28 -> 0.052242987 | N28: 176 | O28: =SUMIF($AE$6:$AG$30,$A28,$AG$6:$AG$30) -> 0 | P28: 34.5 | Q28: =P28*1.15 -> 39.675 | R28: =Q28*$AE$4 -> 7633.8667 | S28: =R28*O28 -> 0 | T28: =L28+K28 -> 398.816 | U28: =R28+S28+T28 -> 8032.6827 | V28: 33900 | W28: 0.0813 | Y28: 3003 | Z28: =W28+(Y28/V28) -> 0.16988407 | AA28: =V28*Z28 -> 5759.07 | AB28: =(V28)/1.1*10%-(R28+AA28+K28+S28+N28)*10% -> 1718.3905 | AC28: =V28-(U28+AA28+AB28) -> 18389.857 | AD28: =AC28/V28 -> 0.54247365

Sheet 헤몬라이프
K1: 헤몬 마진계산기 (2025-08-08 개정본)
K3: 1. 중국환률(AA)와 미국환률(AB)로 인해 비용차이가 많이 발생할 수 있으니 1달 평균으로 사용하기 바람. 2. 2개 구성으로 파는 제품은 물류비와 같은 부분은 X2를 해야하니 계산에 참고하기 바람 3. 사은품 증정되거나 물건이 각각 들어와서 합포장 하는 경우 물류비와 원가를 따로 계산하여 도매가에 포함시켜야 함.(물류비 계산 정확히 하기 위함) | AE3: 중국환률 (CNY) | AF3: 미국환률 (USD)
AE4: 192.41 | AF4: 1385
A5: 자동 | C5: 자동 | D5: 수동 | G5: 자동 | N5: 수동 | Q5: 자동 | V5: 수동 | Z5: 자동 | AE5: 관세율
A6: No | B6: 상품명 | C6: 단위기준 | D6: 넓이 | E6: 폭 | F6: 높이 | G6: 합산 | H6: 개별 박스 CBM | I6: 1CBM 적재가능수량 | J6: 1개당 중국 운임물류비(USD) | K6: 1개당 한국 운임 물류비(KRW) | L6: 1개당 물류비 (KRW) | M6: 원가대비 물류비 비율 | N6: 부자재값 (BOX) | O6: 관세율 | P6: 순수 중국원가 | Q6: 수수료포함 중국원가 | R6: 한국원가 | S6: 관세 | T6: 물류비 | U6: 도매가 | V6: 판매가 택배비 포함 | W6: 마켓수수료 | Y6: N배송 입출고비용 | Z6: 총 수수료(%) | AA6: 총 수수료 (원) | AB6: 부가세 | AC6: 판매마진 | AD6: 제품순이익% | AE6: 제품명(영어) | AF6: 제품명(한국) | AG6: %
A7: 9122381432 | B7: 다벤다 예초기 3.0 배터리1개 | C7: c m | D7: 10 | E7: 86 | F7: 16 | G7: =PRODUCT(D7*E7*F7) -> 13760 | H7: =G7/1000000 -> 0.01376 | I7: =1/H7 -> 72.674419 | J7: =80/I7 -> 1.1008 | K7: =27000/I7 -> 371.52 | L7: =(J7*$AF$4)+K7 -> 1896.128 | M7: =T7/R7 -> 0.20914818 | N7: 400 | O7: =SUMIF($AE$6:$AG$34,$A7,$AG$6:$AG$34) -> 0 | P7: 49 | Q7: =P7*1.15 -> 56.35 | R7: =Q7*$AE$4 -> 10842.303 | S7: =R7*O7 -> 0 | T7: =L7+K7 -> 2267.648 | U7: =R7+S7+T7+U8+U9+U10+U11+U12+U13+U14+U16+U19 -> 28670.93 | V7: 99000 | W7: 0.0663 | Z7: =W7+(Y7/V7) -> 0.0663 | AA7: =V7*Z7 -> 6563.7 | AB7: =(V7)/1.1*10%-(U7+AA7+K7+S7)*10% -> 5439.385 | AC7: =V7-(U7+AA7+AB7) -> 58325.985 | AD7: =AC7/V7 -> 0.58915136 | AE7: SCREWDRIVER | AG7: 0.08
B8: 고글 | C8: c m | D8: 1 | E8: 20 | F8: 1 | G8: =PRODUCT(D8*E8*F8) -> 20 | H8: =G8/1000000 -> 2e-05 | I8: =1/H8 -> 50000 | J8: =80/I8 -> 0.0016 | K8: =27000/I8 -> 0.54 | L8: =(J8*$AF$4)+K8 -> 2.756 | M8: =T8/R8 -> 0.024826213 | O8: =SUMIF($AE$6:$AG$34,$A8,$AG$6:$AG$34) -> 0 | P8: 0.6 | Q8: =P8*1.15 -> 0.69 | R8: =Q8*$AE$4 -> 132.7629 | S8: 0 | T8: =L8+K8 -> 3.296 | U8: =R8+S8+T8 -> 136.0589 | Y8: 4587 | AB8: =(V8)/1.1*10%-(U8+AA8+K8+S8)*10% -> -13.65989 | AC8: =V8-(U8+AA8+AB8) -> -122.39901
B9: 예초 모자 | C9: c m | D9: 1 | E9: 20 | F9: 1 | G9: =PRODUCT(D9*E9*F9) -> 20 | H9: =G9/1000000 -> 2e-05 | I9: =1/H9 -> 50000 | J9: =80/I9 -> 0.0016 | K9: =27000/I9 -> 0.54 | L9: =(J9*$AF$4)+K9 -> 2.756 | M9: =T9/R9 -> 0.016550808 | O9: =SUMIF($AE$6:$AG$34,$A9,$AG$6:$AG$34) -> 0 | P9: 0.9 | Q9: =P9*1.15 -> 1.035 | R9: =Q9*$AE$4 -> 199.14435 | S9: 0 | T9: =L9+K9 -> 3.296 | U9: =R9+S9+T9 -> 202.44035 | AB9: =(V9)/1.1*10%-(U9+AA9+K9+S9)*10% -> -20.298035 | AC9: =V9-(U9+AA9+AB9) -> -182.14231
B10: 장갑 | C10: c m | D10: 1 | E10: 20 | F10: 1 | G10: =PRODUCT(D10*E10*F10) -> 20 | H10: =G10/1000000 -> 2e-05 | I10: =1/H10 -> 50000 | J10: =80/I10 -> 0.0016 | K10: =27000/I10 -> 0.54 | L10: =(J10*$AF$4)+K10 -> 2.756 | M10: =T10/R10 -> 0.012952807 | O10: =SUMIF($AE$6:$AG$34,$A10,$AG$6:$AG$34) -> 0 | P10: 1.15 | Q10: =P10*1.15 -> 1.3225 | R10: =Q10*$AE$4 -> 254.46222 | S10: 0 | T10: =L10+K10 -> 3.296 | U10: =R10+S10+T10 -> 257.75822 | AB10: =(V10)/1.1*10%-(U10+AA10+K10+S10)*10% -> -25.829823 | AC10: =V10-(U10+AA10+AB10) -> -231.9284
B11: 가방 | C11: c m | D11: 1 | E11: 20 | F11: 1 | G11: =PRODUCT(D11*E11*F11) -> 20 | H11: =G11/1000000 -> 2e-05 | I11: =1/H11 -> 50000 | J11: =80/I11 -> 0.0016 | K11: =27000/I11 -> 0.54 | L11: =(J11*$AF$4)+K11 -> 2.756 | M11: =T11/R11 -> 0.014895728 | O11: =SUMIF($AE$6:$AG$34,$A11,$AG$6:$AG$34) -> 0 | P11: 1 | Q11: =P11*1.15 -> 1.15 | R11: =Q11*$AE$4 -> 221.2715 | S11: 0 | T11: =L11+K11 -> 3.296 | U11: =R11+S11+T11 -> 224.5675 | AB11: =(V11)/1.1*10%-(U11+AA11+K11+S11)*10% -> -22.51075 | AC11: =V11-(U11+AA11+AB11) -> -202.05675
B12: 예초기 이도날 | C12: c m | D12: 3 | E12: 18 | F12: 1 | G12: =PRODUCT(D12*E12*F12) -> 54 | H12: =G12/1000000 -> 5.4e-05 | I12: =1/H12 -> 18518.519 | J12: =80/I12 -> 0.00432 | K12: =27000/I12 -> 1.458 | L12: =(J12*$AF$4)+K12 -> 7.4412 | M12: =T12/R12 -> 0.0080436929 | O12: =SUMIF($AE$6:$AG$34,$A12,$AG$6:$AG$34) -> 0 | P12: 5 | Q12: =P12*1.15 -> 5.75 | R12: =Q12*$AE$4 -> 1106.3575 | S12: 0 | T12: =L12+K12 -> 8.8992 | U12: =R12+S12+T12 -> 1115.2567 | AB12: =(V12)/1.1*10%-(U12+AA12+K12+S12)*10% -> -111.67147 | AC12: =V12-(U12+AA12+AB12) -> -1003.5852
B13: 예초기 원형날 | C13: c m | D13: 15 | E13: 15 | F13: 1 | G13: =PRODUCT(D13*E13*F13) -> 225 | H13: =G13/1000000 -> 0.000225 | I13: =1/H13 -> 4444.4444 | J13: =80/I13 -> 0.018 | K13: =27000/I13 -> 6.075 | L13: =(J13*$AF$4)+K13 -> 31.005 | M13: =T13/R13 -> 0.033515387 | O13: =SUMIF($AE$6:$AG$34,$A13,$AG$6:$AG$34) -> 0 | P13: 5 | Q13: =P13*1.15 -> 5.75 | R13: =Q13*$AE$4 -> 1106.3575 | S13: 0 | T13: =L13+K13 -> 37.08 | U13: =R13+S13+T13 -> 1143.4375 | AB13: =(V13)/1.1*10%-(U13+AA13+K13+S13)*10% -> -114.95125 | AC13: =V13-(U13+AA13+AB13) -> -1028.4862
B14: 예초기 커버 | C14: c m | D14: 15 | E14: 13 | F14: 25 | G14: =PRODUCT(D14*E14*F14) -> 4875 | H14: =G14/1000000 -> 0.004875 | I14: =1/H14 -> 205.12821 | J14: =80/I14 -> 0.39 | K14: =27000/I14 -> 131.625 | L14: =(J14*$AF$4)+K14 -> 671.775 | M14: =T14/R14 -> 0.72616672 | O14: =SUMIF($AE$6:$AG$34,$A14,$AG$6:$AG$34) -> 0 | P14: 5 | Q14: =P14*1.15 -> 5.75 | R14: =Q14*$AE$4 -> 1106.3575 | S14: 0 | T14: =L14+K14 -> 803.4 | U14: =R14+S14+T14 -> 1909.7575 | AB14: =(V14)/1.1*10%-(U14+AA14+K14+S14)*10% -> -204.13825 | AC14: =V14-(U14+AA14+AB14) -> -1705.6193
B15: 예초기 어댑터 | C15: c m | D15: 7 | E15: 10 | F15: 5 | G15: =PRODUCT(D15*E15*F15) -> 350 | H15: =G15/1000000 -> 0.00035 | I15: =1/H15 -> 2857.1429 | J15: =80/I15 -> 0.028 | K15: =27000/I15 -> 9.45 | L15: =(J15*$AF$4)+K15 -> 48.23 | M15: =T15/R15 -> 0.052135047 | O15: =SUMIF($AE$6:$AG$34,$A15,$AG$6:$AG$34) -> 0 | P15: 5 | Q15: =P15*1.15 -> 5.75 | R15: =Q15*$AE$4 -> 1106.3575 | S15: 0 | T15: =L15+K15 -> 57.68 | U15: =R15+S15+T15 -> 1164.0375 | V15: 14900 | W15: 0.0813 | Y15: =2827+N15 -> 2827 | Z15: =W15+(Y15/V15) -> 0.27103154 | AA15: =V15*Z15 -> 4038.37 | AB15: =(V15)/1.1*10%-(U15+AA15+K15+S15)*10% -> 833.3597 | AC15: =V15-(U15+AA15+AB15) -> 8864.2328 | AD15: =AC15/V15 -> 0.59491495
B16: 어댑터kc X | C16: c m | D16: 3 | E16: 8 | F16: 3 | G16: 72 | H16: 7.2e-05 | I16: 13888.889 | J16: 0.00576 | K16: 1.944 | L16: 9.9216 | M16: 0.0019523527 | P16: 4.5 | Q16: =P16*1.15 -> 5.175 | R16: =Q16*$AE$4 -> 995.72175 | S16: 0 | T16: =L16+K16 -> 11.8656 | U16: =R16+S16+T16 -> 1007.5873 | W16: 0.0813
A17: 9160468624 | B17: 배터리1.5(kc) | C17: c m | D17: 5 | E17: 10 | F17: 6 | G17: =PRODUCT(D17*E17*F17) -> 300 | H17: =G17/1000000 -> 0.0003 | I17: =1/H17 -> 3333.3333 | J17: =80/I17 -> 0.024 | K17: =27000/I17 -> 8.1 | L17: =(J17*$AF$4)+K17 -> 41.34 | M17: =T17/R17 -> 0.011759785 | O17: 0.021 | P17: 19 | Q17: =P17*1.15 -> 21.85 | R17: =Q17*$AE$4 -> 4204.1585 | S17: 0 | T17: =L17+K17 -> 49.44 | U17: =R17+S17+T17 -> 4253.5985 | V17: 29000 | W17: 0.0813 | Y17: =N17+2827 -> 2827 | Z17: =W17+(Y17/V17) -> 0.17878276 | AA17: =V17*Z17 -> 5184.7 | AB17: =(V17)/1.1*10%-(U17+AA17+K17+S17)*10% -> 1691.7238 | AC17: =V17-(U17+AA17+AB17) -> 17869.978 | AD17: =AC17/V17 -> 0.61620613
A18: 9489814582 | B18: 배터리2.0kc) | C18: c m | D18: 5 | E18: 10 | F18: 6 | G18: =PRODUCT(D18*E18*F18) -> 300 | H18: =G18/1000000 -> 0.0003 | I18: =1/H18 -> 3333.3333 | J18: =80/I18 -> 0.024 | K18: =27000/I18 -> 8.1 | L18: =(J18*$AF$4)+K18 -> 41.34 | M18: =T18/R18 -> 0.008593689 | O18: 0.021 | P18: 26 | Q18: =P18*1.15 -> 29.9 | R18: =Q18*$AE$4 -> 5753.059 | S18: 0 | T18: =L18+K18 -> 49.44 | U18: =R18+S18+T18 -> 5802.499 | V18: 39000 | W18: 0.0813 | Y18: =2827+N18 -> 2827 | Z18: =W18+(Y18/V18) -> 0.15378718 | AA18: =V18*Z18 -> 5997.7 | AB18: =(V18)/1.1*10%-(U18+AA18+K18+S18)*10% -> 2364.6246 | AC18: =V18-(U18+AA18+AB18) -> 24835.176 | AD18: =AC18/V18 -> 0.63679939
A19: 9489836034 | B19: 배터리3.0kc) | C19: c m | D19: 5 | E19: 10 | F19: 6 | G19: =PRODUCT(D19*E19*F19) -> 300 | H19: =G19/1000000 -> 0.0003 | I19: =1/H19 -> 3333.3333 | J19: =80/I19 -> 0.024 | K19: =27000/I19 -> 8.1 | L19: =(J19*$AF$4)+K19 -> 41.34 | M19: =T19/R19 -> 0.0051961841 | O19: 0.021 | P19: 43 | Q19: =P19*1.15 -> 49.45 | R19: =Q19*$AE$4 -> 9514.6745 | S19: 0 | T19: =L19+K19 -> 49.44 | U19: =R19+S19+T19 -> 9564.1145 | V19: 56900 | W19: 0.0813 | Y19: =2827+N19 -> 2827 | Z19: =W19+(Y19/V19) -> 0.13098366 | AA19: =V19*Z19 -> 7452.97 | AB19: =(V19)/1.1*10%-(U19+AA19+K19+S19)*10% -> 3470.2088 | AC19: =V19-(U19+AA19+AB19) -> 36412.707 | AD19: =AC19/V19 -> 0.63994212
A20: 11314918765 | B20: 레이저레벨기 | C20: c m | D20: 35 | E20: 44 | F20: 13 | G20: =PRODUCT(D20*E20*F20) -> 20020 | H20: =G20/1000000 -> 0.02002 | I20: =1/H20 -> 49.95005 | J20: =80/I20 -> 1.6016 | K20: =27000/I20 -> 540.54 | L20: =(J20*$AF$4)+K20 -> 2758.756 | M20: =T20/R20 -> 0.093191396 | N20: 1078 | O20: 0.08 | P20: 160 | Q20: =P20*1.15 -> 184 | R20: =Q20*$AE$4 -> 35403.44 | S20: =R20*O20 -> 2832.2752 | T20: =L20+K20 -> 3299.296 | U20: =R20+S20+T20 -> 41535.011 | V20: 99000 | W20: 0.0813 | Y20: =3443+N20 -> 4521 | Z20: =W20+(Y20/V20) -> 0.12696667 | AA20: =V20*Z20 -> 12569.7 | AB20: =(V20)/1.1*10%-(U20+AA20+K20+S20)*10% -> 3252.2474 | AC20: =V20-(U20+AA20+AB20) -> 41643.041 | AD20: =AC20/V20 -> 0.42063678
A21: 11174612423 | B21: 헤몬 그라인더 | C21: c m | D21: 29 | E21: 40 | F21: 19 | G21: =PRODUCT(D21*E21*F21) -> 22040 | H21: =G21/1000000 -> 0.02204 | I21: =1/H21 -> 45.372051 | J21: =80/I21 -> 1.7632 | K21: =27000/I21 -> 595.08 | L21: =(J21*$AF$4)+K21 -> 3037.112 | M21: =T21/R21 -> 0.12250069 | N21: 561 | O21: 0.08 | P21: 134 | Q21: =P21*1.15 -> 154.1 | R21: =Q21*$AE$4 -> 29650.381 | S21: =R21*O21 -> 2372.0305 | T21: =L21+K21 -> 3632.192 | U21: =R21+S21+T21+U17 -> 39908.202 | V21: 86800 | W21: 0.0813 | Y21: =3443+N21 -> 4004 | Z21: =W21+(Y21/V21) -> 0.12742903 | AA21: =V21*Z21 -> 11060.84 | AB21: =(V21)/1.1*10%-(U21+AA21+K21+S21)*10% -> 2497.2938 | AC21: =V21-(U21+AA21+AB21) -> 33333.664 | AD21: =AC21/V21 -> 0.38402839
A22: 9455030267 | B22: 다쪼아 터보 올인원 | C22: c m | D22: 32 | E22: 40 | F22: 8 | G22: =PRODUCT(D22*E22*F22) -> 10240 | H22: =G22/1000000 -> 0.01024 | I22: =1/H22 -> 97.65625 | J22: =80/I22 -> 0.8192 | K22: =27000/I22 -> 276.48 | L22: =(J22*$AF$4)+K22 -> 1411.072 | M22: =T22/R22 -> 0.073332813 | N22: 561 | O22: 0.08 | P22: 104 | Q22: =P22*1.15 -> 119.6 | R22: =Q22*$AE$4 -> 23012.236 | S22: =R22*O22 -> 1840.9789 | T22: =L22+K22 -> 1687.552 | U22: =R22+S22+T22+공용!V24 -> 40978.623 | V22: 79800 | W22: 0.0813 | Y22: =3443+N22 -> 4004 | Z22: =W22+(Y22/V22) -> 0.13147544 | AA22: =V22*Z22 -> 10491.74 | AB22: =(V22)/1.1*10%-(U22+AA22+K22+S22)*10% -> 1895.7633 | AC22: =V22-(U22+AA22+AB22) -> 26433.874 | AD22: =AC22/V22 -> 0.33125155
A23: 10592182445 | B23: 다쪼아 더원 전동드릴 | C23: c m | D23: 21 | E23: 22 | F23: 8 | G23: =PRODUCT(D23*E23*F23) -> 3696 | H23: =G23/1000000 -> 0.003696 | I23: =1/H23 -> 270.56277 | J23: =80/I23 -> 0.29568 | K23: =27000/I23 -> 99.792 | L23: =(J23*$AF$4)+K23 -> 509.3088 | M23: =T23/R23 -> 0.036703073 | N23: 286 | O23: 0.08 | P23: 75 | Q23: =P23*1.15 -> 86.25 | R23: =Q23*$AE$4 -> 16595.362 | S23: =R23*O23 -> 1327.629 | T23: =L23+K23 -> 609.1008 | U23: =R23+S23+T23 -> 18532.092 | V23: 53800 | W23: 0.0813 | Y23: =2827+N23 -> 3113 | Z23: =W23+(Y23/V23) -> 0.13916245 | AA23: =V23*Z23 -> 7486.94 | AB23: =(V23)/1.1*10%-(U23+AA23+K23+S23)*10% -> 2146.2638 | AC23: =V23-(U23+AA23+AB23) -> 25634.704 | AD23: =AC23/V23 -> 0.47648149
B24: 터크원 | C24: c m | D24: 21 | E24: 22 | F24: 8 | G24: =PRODUCT(D24*E24*F24) -> 3696 | H24: =G24/1000000 -> 0.003696 | I24: =1/H24 -> 270.56277 | J24: =80/I24 -> 0.29568 | K24: =27000/I24 -> 99.792 | L24: =(J24*$AF$4)+K24 -> 509.3088 | M24: =T24/R24 -> 0.078649442 | O24: 0.08 | P24: 35 | Q24: =P24*1.15 -> 40.25 | R24: =Q24*$AE$4 -> 7744.5025 | S24: =R24*O24 -> 619.5602 | T24: =L24+K24 -> 609.1008 | U24: =R24+S24+T24 -> 8973.1635 | V24: 44900 | W24: 0.0813 | Y24: =2827+N24 -> 2827 | Z24: =W24+(Y24/V24) -> 0.14426214 | AA24: =V24*Z24 -> 6477.37 | AB24: =(V24)/1.1*10%-(U24+AA24+K24+S24)*10% -> 2464.8296 | AC24: =V24-(U24+AA24+AB24) -> 26984.637 | AD24: =AC24/V24 -> 0.60099414
B25: 대형 송풍기 | C25: c m | D25: 25 | E25: 49 | F25: 25 | G25: =PRODUCT(D25*E25*F25) -> 30625 | H25: =G25/1000000 -> 0.030625 | I25: =1/H25 -> 32.653061 | J25: =80/I25 -> 2.45 | K25: =27000/I25 -> 826.875 | L25: =(J25*$AG$4)+K25 -> 826.875 | M25: =T25/R25 -> 0.085415429 | N25: 1144 | O25: =SUMIF($AE$6:$AG$34,$A25,$AG$6:$AG$34) -> 0 | P25: 87.5 | Q25: =P25*1.15 -> 100.625 | R25: =Q25*$AE$4 -> 19361.256 | S25: =R25*O25 -> 0 | T25: =L25+K25 -> 1653.75 | U25: =R25+S25+T25 -> 21015.006 | V25: 84800 | W25: 0.0813 | Y25: =2827+N25 -> 3971 | Z25: =W25+(Y25/V25) -> 0.12812783 | AA25: =V25*Z25 -> 10865.24 | AB25: =(V25)/1.1*10%-(U25+AA25+K25+S25)*10% -> 4438.3788 | AC25: =V25-(U25+AA25+AB25) -> 48481.375 | AD25: =AC25/V25 -> 0.57171433

Sheet 헤누스
L1: 헤몬 마진계산기 (2025-08-08 개정본)
L3: 1. 중국환률(AA)와 미국환률(AB)로 인해 비용차이가 많이 발생할 수 있으니 1달 평균으로 사용하기 바람. 2. 2개 구성으로 파는 제품은 물류비와 같은 부분은 X2를 해야하니 계산에 참고하기 바람 3. 사은품 증정되거나 물건이 각각 들어와서 합포장 하는 경우 물류비와 원가를 따로 계산하여 도매가에 포함시켜야 함.(물류비 계산 정확히 하기 위함) | AE3: 중국환률 (CNY) | AF3: 미국환률 (USD)
AE4: 192.41 | AF4: 1385
A5: 자동 | C5: 자동 | D5: 수동 | G5: 자동 | N5: 수동 | Q5: 자동 | V5: 수동 | Z5: 자동 | AE5: 관세율
A6: No | B6: 상품명 | C6: 단위기준 | D6: 넓이 | E6: 폭 | F6: 높이 | G6: 합산 | H6: 개별 박스 CBM | I6: 1CBM 적재가능수량 | J6: 1개당 중국 운임물류비(USD) | K6: 1개당 한국 운임 물류비(KRW) | L6: 1개당 물류비 (KRW) | M6: 원가대비 물류비 비율 | N6: 부자재값 (BOX) | O6: 관세율 | P6: 순수 중국원가 | Q6: 수수료포함 중국원가 | R6: 한국원가 | S6: 관세 | T6: 물류비 | U6: 도매가 | V6: 판매가 택배비 포함 | W6: 마켓수수료 | Y6: N배송 입출고비용 | Z6: 총 수수료(%) | AA6: 총 수수료 (원) | AB6: 부가세 | AC6: 판매마진 | AD6: 제품순이익% | AE6: 제품명(영어) | AF6: 제품명(한국) | AG6: %
B7: 시거잭 | C7: c m | D7: 15 | E7: 5 | F7: 3 | G7: =PRODUCT(D7*E7*F7) -> 225 | H7: =G7/1000000 -> 0.000225 | I7: =1/H7 -> 4444.4444 | J7: =80/I7 -> 0.018 | K7: =27000/I7 -> 6.075 | L7: =(J7*$AF$4)+K7 -> 31.005 | M7: =T7/R7 -> 0.0072231438 | N7: 176 | O7: =SUMIF($AE$6:$AG$30,$A7,$AG$6:$AG$30) -> 0 | P7: 23.2 | Q7: =P7*1.15 -> 26.68 | R7: =Q7*$AE$4 -> 5133.4988 | S7: =R7*O7 -> 0 | T7: =L7+K7 -> 37.08 | U7: =R7+S7+T7 -> 5170.5788 | V7: 19900 | W7: 0.0813 | Y7: =2827+N7 -> 3003 | Z7: =W7+(Y7/V7) -> 0.23220452 | AA7: =V7*Z7 -> 4620.87 | AB7: =(V7)/1.1*10%-(AA7+K7+N7+U7)*10% -> 811.73853 | AC7: =V7-(U7+AA7+AB7+N7) -> 9120.8127 | AD7: =AC7/V7 -> 0.4583323 | AE7: SCREWDRIVER | AG7: 0.08
B8: 블리츠 | C8: c m | D8: 19 | E8: 21 | F8: 6 | G8: =PRODUCT(D8*E8*F8) -> 2394 | H8: =G8/1000000 -> 0.002394 | I8: =1/H8 -> 417.71094 | J8: =80/I8 -> 0.19152 | K8: =27000/I8 -> 64.638 | L8: 231 | M8: =T8/R8 -> 0.038173918 | N8: =176+198+350 -> 724 | O8: =SUMIF($AE$6:$AG$30,$A8,$AG$6:$AG$30) -> 0 | P8: 35 | Q8: =P8*1.15 -> 40.25 | R8: =Q8*$AE$4 -> 7744.5025 | S8: =R8*O8 -> 0 | T8: =L8+K8 -> 295.638 | U8: =R8+S8+T8 -> 8040.1405 | V8: 24900 | W8: 0.0813 | Y8: =2827+N8 -> 3551 | Z8: =W8+(Y8/V8) -> 0.22391044 | AA8: =V8*Z8 -> 5575.37 | AB8: =(V8)/1.1*10%-(AA8+K8+N8+U8)*10% -> 823.22151 | AC8: =V8-(U8+AA8+AB8+N8) -> 9737.268 | AD8: =AC8/V8 -> 0.39105494
B9: 블리츠 1+1 | N9: =176+198+350 -> 724 | P9: 70 | Q9: =P9*1.15 -> 80.5 | U9: =U8*2 -> 16080.281 | V9: 44000 | W9: 0.0813 | Y9: =2827+N9 -> 3551 | Z9: =W9+(Y9/V9) -> 0.16200455 | AA9: =V9*Z9 -> 7128.2 | AB9: =(V9)/1.1*10%-(AA9+K9+N9+U9)*10% -> 1606.7519 | AC9: =V9-(U9+AA9+AB9+N9) -> 18460.767 | AD9: =AC9/V9 -> 0.41956289
B10: 필터추가 1개 | C10: c m | D10: 5 | E10: 5 | F10: 3 | G10: =PRODUCT(D10*E10*F10) -> 75 | H10: =G10/1000000 -> 7.5e-05 | I10: =1/H10 -> 13333.333 | J10: =80/I10 -> 0.006 | K10: =27000/I10 -> 2.025 | L10: 231 | M10: =T10/R10 -> 0.526559 | P10: 2 | Q10: =P10*1.15 -> 2.3 | R10: =Q10*$AE$4 -> 442.543 | S10: =R10*O10 -> 0 | T10: =L10+K10 -> 233.025 | U10: =R10+S10+T10 -> 675.568 | V10: 5000 | W10: 0.0813 | Z10: =W10+(Y10/V10) -> 0.0813 | AA10: =V10*Z10 -> 406.5 | AB10: =(V10)/1.1*10%-(AA10+K10+N10+U10)*10% -> 346.13615 | AC10: =V10-(U10+AA10+AB10+N10) -> 3571.7958 | AD10: =AC10/V10 -> 0.71435917
B11: 필터추가 2개 | C11: c m | D11: 5 | E11: 5 | F11: 3 | G11: =PRODUCT(D11*E11*F11) -> 75 | H11: =G11/1000000 -> 7.5e-05 | I11: =1/H11 -> 13333.333 | J11: =80/I11 -> 0.006 | K11: =27000/I11 -> 2.025 | L11: 231 | M11: =T11/R11 -> 0.2632795 | P11: 4 | Q11: =P11*1.15 -> 4.6 | R11: =Q11*$AE$4 -> 885.086 | S11: =R11*O11 -> 0 | T11: =L11+K11 -> 233.025 | U11: =R11+S11+T11 -> 1118.111 | V11: 9000 | W11: 0.0813 | Z11: =W11+(Y11/V11) -> 0.0813 | AA11: =V11*Z11 -> 731.7 | AB11: =(V11)/1.1*10%-(AA11+K11+N11+U11)*10% -> 632.99822 | AC11: =V11-(U11+AA11+AB11+N11) -> 6517.1908 | AD11: =AC11/V11 -> 0.72413231
B12: 필터추가 3개 | C12: c m | D12: 5 | E12: 5 | F12: 3 | G12: =PRODUCT(D12*E12*F12) -> 75 | H12: =G12/1000000 -> 7.5e-05 | I12: =1/H12 -> 13333.333 | J12: =80/I12 -> 0.006 | K12: =27000/I12 -> 2.025 | L12: 231 | M12: =T12/R12 -> 0.17551967 | P12: 6 | Q12: =P12*1.15 -> 6.9 | R12: =Q12*$AE$4 -> 1327.629 | S12: =R12*O12 -> 0 | T12: =L12+K12 -> 233.025 | U12: =R12+S12+T12 -> 1560.654 | V12: 13000 | W12: 0.0813 | Z12: =W12+(Y12/V12) -> 0.0813 | AA12: =V12*Z12 -> 1056.9 | AB12: =(V12)/1.1*10%-(AA12+K12+N12+U12)*10% -> 919.86028 | AC12: =V12-(U12+AA12+AB12+N12) -> 9462.5857 | AD12: =AC12/V12 -> 0.72789121
B13: 원큐 | C13: c m | D13: 26 | E13: 10 | F13: 6 | G13: =PRODUCT(D13*E13*F13) -> 1560 | H13: =G13/1000000 -> 0.00156 | I13: =1/H13 -> 641.02564 | J13: =80/I13 -> 0.1248 | K13: =27000/I13 -> 42.12 | L13: =(J13*$AF$4)+K13 -> 214.968 | M13: =T13/R13 -> 0.033196193 | N13: 198 | O13: =SUMIF($AE$6:$AG$30,$A13,$AG$6:$AG$30) -> 0 | P13: 35 | Q13: =P13*1.15 -> 40.25 | R13: =Q13*$AE$4 -> 7744.5025 | S13: =R13*O13 -> 0 | T13: =L13+K13 -> 257.088 | U13: =R13+S13+T13 -> 8001.5905 | V13: 27900 | W13: 0.0813 | Y13: =2827+N13 -> 3025 | Z13: =W13+(Y13/V13) -> 0.18972294 | AA13: =V13*Z13 -> 5293.27 | AB13: =(V13)/1.1*10%-(AA13+K13+N13+U13)*10% -> 1182.8656 | AC13: =V13-(U13+AA13+AB13+N13+X13) -> 13224.274 | AD13: =AC13/V13 -> 0.47398831
B15: 라이트 고압세척기 | C15: c m | D15: 22 | E15: 27 | F15: 11 | G15: =PRODUCT(D15*E15*F15) -> 6534 | H15: =G15/1000000 -> 0.006534 | I15: =1/H15 -> 153.04561 | J15: =80/I15 -> 0.52272 | K15: =27000/I15 -> 176.418 | L15: =(J15*$AF$4)+K15 -> 900.3852 | M15: =T15/R15 -> 0.074868219 | N15: 286 | O15: =SUMIF($AE$6:$AG$30,$A15,$AG$6:$AG$30) -> 0 | P15: 65 | Q15: =P15*1.15 -> 74.75 | R15: =Q15*$AE$4 -> 14382.647 | S15: =R15*O15 -> 0 | T15: =L15+K15 -> 1076.8032 | U15: =R15+S15+T15+(공용!V7*2) -> 24060.542 | V15: 64800 | W15: 0.0813 | Y15: =2827+N15 -> 3113 | Z15: =W15+(Y15/V15) -> 0.12934012 | AA15: =V15*Z15 -> 8381.24 | AB15: =(V15)/1.1*10%-(AA15+K15+N15+U15)*10% -> 2600.4891 | AC15: =V15-(U15+AA15+AB15+N15) -> 29471.729 | AD15: =AC15/V15 -> 0.45481063
B17: 광택기 | C17: c m | D17: 17 | E17: 30 | F17: 19 | G17: =PRODUCT(D17*E17*F17) -> 9690 | H17: =G17/1000000 -> 0.00969 | I17: =1/H17 -> 103.19917 | J17: =80/I17 -> 0.7752 | K17: =27000/I17 -> 261.63 | L17: =(J17*$AF$4)+K17 -> 1335.282 | M17: =T17/R17 -> 0.096226401 | N17: 242 | O17: =SUMIF($AE$6:$AG$30,$A17,$AG$6:$AG$30) -> 0 | P17: 75 | Q17: =P17*1.15 -> 86.25 | R17: =Q17*$AE$4 -> 16595.362 | S17: =R17*O17 -> 0 | T17: =L17+K17 -> 1596.912 | U17: =R17+S17+T17+(공용!V7*2) -> 26793.366 | V17: 65800 | W17: 0.0813 | Y17: =2827+N17 -> 3069 | Z17: =W17+(Y17/V17) -> 0.12794134 | AA17: =V17*Z17 -> 8418.54 | AB17: =(V17)/1.1*10%-(AA17+K17+N17+U17)*10% -> 2410.2646 | AC17: =V17-(U17+AA17+AB17+N17) -> 27935.829 | AD17: =AC17/V17 -> 0.42455668
B19: 불고다떙겨 | C19: c m | D19: 12 | E19: 21 | F19: 8 | G19: =PRODUCT(D19*E19*F19) -> 2016 | H19: =G19/1000000 -> 0.002016 | I19: =1/H19 -> 496.03175 | J19: =80/I19 -> 0.16128 | K19: =27000/I19 -> 54.432 | L19: =(J19*$AF$4)+K19 -> 277.8048 | M19: =T19/R19 -> 0.055610717 | N19: 176 | O19: 0 | P19: 27 | Q19: =P19*1.15 -> 31.05 | R19: =Q19*$AE$4 -> 5974.3305 | S19: =R19*O19 -> 0 | T19: =L19+K19 -> 332.2368 | U19: =R19+S19+T19 -> 6306.5673 | V19: 20900 | W19: 0.0813 | Y19: =2827+N19 -> 3003 | Z19: =W19+(Y19/V19) -> 0.22498421 | AA19: =V19*Z19 -> 4702.17 | AB19: =(V19)/1.1*10%-(AA19+K19+N19+U19)*10% -> 776.08307 | AC19: =V19-(U19+AA19+AB19+N19) -> 8939.1796 | AD19: =AC19/V19 -> 0.42771194
U20: =U19*2 -> 12613.135 | V20: 40400
B21: 파워쎈 | C21: c m | D21: 36.8 | E21: 13.6 | F21: 13.4 | G21: =PRODUCT(D21*E21*F21) -> 6706.432 | H21: =G21/1000000 -> 0.006706432 | I21: =1/H21 -> 149.11059 | J21: =80/I21 -> 0.53651456 | K21: =27000/I21 -> 181.07366 | L21: =(J21*$AF$4)+K21 -> 924.14633 | M21: =T21/R21 -> 0.1019359 | N21: 176 | O21: 0 | P21: 49 | Q21: =P21*1.15 -> 56.35 | R21: =Q21*$AE$4 -> 10842.303 | S21: =R21*O21 -> 0 | T21: =L21+K21 -> 1105.22 | U21: =R21+S21+T21+헤몬라이프!U11 -> 12172.091 | V21: 36900 | W21: 0.0813 | Y21: =2827+N21 -> 3003 | Z21: =W21+(Y21/V21) -> 0.16268211 | AA21: =V21*Z21 -> 6002.97 | AB21: =(V21)/1.1*10%-(AA21+K21+N21+U21)*10% -> 1501.332 | AC21: =V21-(U21+AA21+AB21+N21) -> 17047.607 | AD21: =AC21/V21 -> 0.46199477
A22: 9644727520 | B22: SODIC 맥세이프 | C22: c m | D22: 8 | E22: 7 | F22: 7 | G22: =PRODUCT(D22*E22*F22) -> 392 | H22: =G22/1000000 -> 0.000392 | I22: =1/H22 -> 2551.0204 | J22: =80/I22 -> 0.03136 | K22: =27000/I22 -> 10.584 | L22: =(J22*$AF$4)+K22 -> 54.0176 | M22: =T22/R22 -> 0.014241769 | N22: 176 | O22: 0 | P22: 20.5 | Q22: =P22*1.15 -> 23.575 | R22: =Q22*$AE$4 -> 4536.0657 | S22: =R22*O22 -> 0 | T22: =L22+K22 -> 64.6016 | U22: =R22+S22+T22 -> 4600.6673 | V22: 22900 | W22: 0.0813 | Y22: =2827+N22 -> 3003 | Z22: =W22+(Y22/V22) -> 0.21243537 | AA22: =V22*Z22 -> 4864.77 | AB22: =(V22)/1.1*10%-(AA22+K22+N22+U22)*10% -> 1116.616 | AC22: =V22-(U22+AA22+AB22+N22) -> 12141.947 | AD22: =AC22/V22 -> 0.53021601
B24: 터보건 배터리 2개 | C24: c m | D24: 25 | E24: 10 | F24: 25 | G24: =PRODUCT(D24*E24*F24) -> 6250 | H24: =G24/1000000 -> 0.00625 | I24: =1/H24 -> 160 | J24: =80/I24 -> 0.5 | K24: =27000/I24 -> 168.75 | L24: =(J24*$AF$4)+K24 -> 861.25 | M24: =T24/R24 -> 0.24499552 | N24: 176 | O24: 0 | P24: 19 | Q24: =P24*1.15 -> 21.85 | R24: =Q24*$AE$4 -> 4204.1585 | S24: =R24*O24 -> 0 | T24: =L24+K24 -> 1030 | U24: =R24+S24+T24+공용!V12+(공용!V7*2) -> 14832.916 | V24: 49800 | W24: 0.0813 | Y24: =2827+N24 -> 3003 | Z24: =W24+(Y24/V24) -> 0.1416012 | AA24: =V24*Z24 -> 7051.74 | AB24: =(V24)/1.1*10%-(AA24+K24+N24+U24)*10% -> 2304.3321 | AC24: =V24-(U24+AA24+AB24+N24) -> 25435.012 | AD24: =AC24/V24 -> 0.51074321

Sheet 헤이슨
A1: 헤몬 마진계산기 (2025-08-08 개정본)
A3: 1. 중국환률(AA)와 미국환률(AB)로 인해 비용차이가 많이 발생할 수 있으니 1달 평균으로 사용하기 바람. 2. 2개 구성으로 파는 제품은 물류비와 같은 부분은 X2를 해야하니 계산에 참고하기 바람 3. 사은품 증정되거나 물건이 각각 들어와서 합포장 하는 경우 물류비와 원가를 따로 계산하여 도매가에 포함시켜야 함.(물류비 계산 정확히 하기 위함) | AE3: 중국환률 (CNY) | AF3: 미국환률 (USD)
AE4: 192.41 | AF4: 1385
A5: 자동 | C5: 자동 | D5: 수동 | G5: 자동 | N5: 수동 | Q5: 자동 | V5: 수동 | Z5: 자동 | AE5: 관세율
A6: No | B6: 상품명 | C6: 단위기준 | D6: 넓이 | E6: 폭 | F6: 높이 | G6: 합산 | H6: 개별 박스 CBM | I6: 1CBM 적재가능수량 | J6: 1개당 중국 운임물류비(USD) | K6: 1개당 한국 운임 물류비(KRW) | L6: 1개당 물류비 (KRW) | M6: 원가대비 물류비 비율 | N6: 부자재값 (BOX) | O6: 관세율 | P6: 순수 중국원가 | Q6: 수수료포함 중국원가 | R6: 한국원가 | S6: 관세 | T6: 물류비 | U6: 도매가 | V6: 판매가 택배비 포함 | W6: 마켓수수료 | Y6: N배송 입출고비용 | Z6: 총 수수료(%) | AA6: 총 수수료 (원) | AB6: 부가세 | AC6: 판매마진 | AD6: 제품순이익% | AE6: 제품명(영어) | AF6: 제품명(한국) | AG6: %
B7: 파워쎈S | C7: c m | D7: 15 | E7: 34 | F7: 14 | G7: =PRODUCT(D7*E7*F7) -> 7140 | H7: =G7/1000000 -> 0.00714 | I7: =1/H7 -> 140.05602 | J7: =80/I7 -> 0.5712 | K7: =27000/I7 -> 192.78 | L7: =(J7*$AF$4)+K7 -> 983.892 | M7: =T7/R7 -> 0.096686814 | N7: 363 | O7: =SUMIF($AE$6:$AG$23,$A7,$AG$6:$AG$23) -> 0 | P7: 55 | Q7: =P7*1.15 -> 63.25 | R7: =Q7*$AE$4 -> 12169.932 | S7: =R7*O7 -> 0 | T7: =L7+K7 -> 1176.672 | U7: =R7+S7+T7 -> 13346.604 | V7: 32900 | W7: 0.0813 | Y7: =2827+N7 -> 3190 | Z7: =W7+(Y7/V7) -> 0.17826049 | AA7: =V7*Z7 -> 5864.77 | AB7: =(V7)/1.1*10%-(R7+AA7+K7+S7+N7+X7)*10% -> 1131.8608 | AC7: =V7-(U7+AA7+AB7+N7) -> 12193.765 | AD7: =AC7/V7 -> 0.37063114 | AE7: SCREWDRIVER | AG7: 0.08
B8: 파워쎈S 필터 | C8: c m | G8: =PRODUCT(D8*E8*F8) -> 0 | H8: =G8/1000000 -> 0 | I8: =1/H8 -> #DIV/0! | J8: =80/I8 -> #DIV/0! | K8: =27000/I8 -> #DIV/0! | L8: =(J8*$AF$4)+K8 -> #DIV/0! | M8: =T8/R8 -> #DIV/0! | O8: =SUMIF($AE$6:$AG$23,$A8,$AG$6:$AG$23) -> 0 | P8: 2 | Q8: =P8*1.15 -> 2.3 | R8: =Q8*$AE$4 -> 442.543 | S8: =R8*O8 -> 0 | T8: =L8+K8 -> #DIV/0! | U8: =R8+S8+T8 -> #DIV/0! | W8: 0.0813 | Z8: =W8+(Y8/V8) -> #DIV/0! | AA8: =V8*Z8 -> #DIV/0! | AB8: =(V8)/1.1*10%-(R8+AA8+K8+S8+N8+X8)*10% -> #DIV/0! | AC8: =V8-(U8+AA8+AB8+N8) -> #DIV/0! | AD8: =AC8/V8 -> #DIV/0!
B9: 싸이클론X | C9: c m | D9: 16 | E9: 42 | F9: 12 | G9: =PRODUCT(D9*E9*F9) -> 8064 | H9: =G9/1000000 -> 0.008064 | I9: =1/H9 -> 124.00794 | J9: =80/I9 -> 0.64512 | K9: =27000/I9 -> 217.728 | L9: =(J9*$AF$4)+K9 -> 1111.2192 | M9: =T9/R9 -> 0.14299899 | N9: 561 | O9: =SUMIF($AE$6:$AG$23,$A9,$AG$6:$AG$23) -> 0 | P9: 42 | Q9: =P9*1.15 -> 48.3 | R9: =Q9*$AE$4 -> 9293.403 | S9: =R9*O9 -> 0 | T9: =L9+K9 -> 1328.9472 | U9: =R9+S9+T9 -> 10622.35 | V9: 29800 | W9: 0.0813 | Y9: =2827+N9 -> 3388 | Z9: =W9+(Y9/V9) -> 0.19499128 | AA9: =V9*Z9 -> 5810.74 | AB9: =(V9)/1.1*10%-(R9+AA9+K9+S9+N9+X9)*10% -> 1120.8038 | AC9: =V9-(U9+AA9+AB9+N9) -> 11685.106 | AD9: =AC9/V9 -> 0.39211765
AD10: =AC10/V10 -> #DIV/0!
AD11: =AC11/V11 -> #DIV/0!
AD12: =AC12/V12 -> #DIV/0!
AD13: =AC13/V13 -> #DIV/0!
AD14: =AC14/V14 -> #DIV/0!
AD15: =AC15/V15 -> #DIV/0!
AD16: =AC16/V16 -> #DIV/0!
AD17: =AC17/V17 -> #DIV/0!

Sheet 헤이버
A1: 헤몬 마진계산기 (2025-08-08 개정본)
A3: 1. 중국환률(AA)와 미국환률(AB)로 인해 비용차이가 많이 발생할 수 있으니 1달 평균으로 사용하기 바람. 2. 2개 구성으로 파는 제품은 물류비와 같은 부분은 X2를 해야하니 계산에 참고하기 바람 3. 사은품 증정되거나 물건이 각각 들어와서 합포장 하는 경우 물류비와 원가를 따로 계산하여 도매가에 포함시켜야 함.(물류비 계산 정확히 하기 위함) | AE3: 중국환률 (CNY) | AF3: 미국환률 (USD)
AE4: 192.41 | AF4: 1385
A5: 자동 | C5: 자동 | D5: 수동 | G5: 자동 | N5: 수동 | Q5: 자동 | V5: 수동 | Z5: 자동 | AE5: 관세율
A6: No | B6: 상품명 | C6: 단위기준 | D6: 넓이 | E6: 폭 | F6: 높이 | G6: 합산 | H6: 개별 박스 CBM | I6: 1CBM 적재가능수량 | J6: 1개당 중국 운임물류비(USD) | K6: 1개당 한국 운임 물류비(KRW) | L6: 1개당 물류비 (KRW) | M6: 원가대비 물류비 비율 | N6: 부자재값 (BOX) | O6: 관세율 | P6: 순수 중국원가 | Q6: 수수료포함 중국원가 | R6: 한국원가 | S6: 관세 | T6: 물류비 | U6: 도매가 | V6: 판매가 택배비 포함 | W6: 마켓수수료 | Y6: N배송 입출고비용 | Z6: 총 수수료(%) | AA6: 총 수수료 (원) | AB6: 부가세 | AC6: 판매마진 | AD6: 제품순이익% | AE6: 제품명(영어) | AF6: 제품명(한국) | AG6: %
B7: 바리깡 (블랙) | C7: c m | D7: 22 | E7: 13 | F7: 5 | G7: =PRODUCT(D7*E7*F7) -> 1430 | H7: =G7/1000000 -> 0.00143 | I7: =1/H7 -> 699.3007 | J7: =80/I7 -> 0.1144 | K7: =27000/I7 -> 38.61 | L7: =(J7*$AF$4)+K7 -> 197.054 | M7: =T7/R7 -> 0.066565283 | N7: 176 | O7: =SUMIF($AE$6:$AG$24,$A7,$AG$6:$AG$24) -> 0 | P7: 16 | Q7: =P7*1.15 -> 18.4 | R7: =Q7*$AE$4 -> 3540.344 | S7: =R7*O7 -> 0 | T7: =L7+K7 -> 235.664 | U7: =R7+S7+T7 -> 3776.008 | V7: 19900 | W7: 0.0813 | Y7: =2827+N7 -> 3003 | Z7: =W7+(Y7/V7) -> 0.23220452 | AA7: =V7*Z7 -> 4620.87 | AB7: =(V7)/1.1*10%-(R7+AA7+K7+S7+N7+X7)*10% -> 971.50851 | AC7: =V7-(U7+AA7+AB7+N7) -> 10355.613 | AD7: =AC7/V7 -> 0.52038259 | AE7: SCREWDRIVER | AG7: 0.08
B8: 바리깡 (실버) | C8: c m | D8: 22 | E8: 13 | F8: 5 | G8: =PRODUCT(D8*E8*F8) -> 1430 | H8: =G8/1000000 -> 0.00143 | I8: =1/H8 -> 699.3007 | J8: =80/I8 -> 0.1144 | K8: =27000/I8 -> 38.61 | L8: =(J8*$AF$4)+K8 -> 197.054 | M8: =T8/R8 -> 0.066565283 | N8: 176 | O8: =SUMIF($AE$6:$AG$24,$A8,$AG$6:$AG$24) -> 0 | P8: 16 | Q8: =P8*1.15 -> 18.4 | R8: =Q8*$AE$4 -> 3540.344 | S8: =R8*O8 -> 0 | T8: =L8+K8 -> 235.664 | U8: =R8+S8+T8 -> 3776.008 | V8: 19900 | W8: 0.0813 | Y8: =2827+N8 -> 3003 | Z8: =W8+(Y8/V8) -> 0.23220452 | AA8: =V8*Z8 -> 4620.87 | AB8: =(V8)/1.1*10%-(R8+AA8+K8+S8+N8+X8)*10% -> 971.50851 | AC8: =V8-(U8+AA8+AB8+N8) -> 10355.613 | AD8: =AC8/V8 -> 0.52038259 | AE8: SCREWDRIVER | AG8: 0.08
B9: 에픽쉐이브 | C9: c m | D9: 21 | E9: 10 | F9: 8 | G9: =PRODUCT(D9*E9*F9) -> 1680 | H9: =G9/1000000 -> 0.00168 | I9: =1/H9 -> 595.2381 | J9: =80/I9 -> 0.1344 | K9: =27000/I9 -> 45.36 | L9: =(J9*$AF$4)+K9 -> 231.504 | M9: =T9/R9 -> 0.059582911 | N9: 176 | O9: =SUMIF($AE$6:$AG$24,$A9,$AG$6:$AG$24) -> 0 | P9: 21 | Q9: =P9*1.15 -> 24.15 | R9: =Q9*$AE$4 -> 4646.7015 | S9: =R9*O9 -> 0 | T9: =L9+K9 -> 276.864 | U9: =R9+S9+T9 -> 4923.5655 | V9: 23900 | W9: 0.0813 | Y9: =2827+N9 -> 3003 | Z9: =W9+(Y9/V9) -> 0.20694854 | AA9: =V9*Z9 -> 4946.07 | AB9: =(V9)/1.1*10%-(R9+AA9+K9+S9+N9+X9)*10% -> 1191.3141 | AC9: =V9-(U9+AA9+AB9+N9) -> 12663.05 | AD9: =AC9/V9 -> 0.52983474
B10: 일자면도기 | C10: c m | D10: 15 | E10: 20 | F10: 6 | G10: =PRODUCT(D10*E10*F10) -> 1800 | H10: =G10/1000000 -> 0.0018 | I10: =1/H10 -> 555.55556 | J10: =80/I10 -> 0.144 | K10: =27000/I10 -> 48.6 | L10: =(J10*$AF$4)+K10 -> 248.04 | M10: =T10/R10 -> 0.041894234 | N10: 176 | O10: =SUMIF($AE$6:$AG$24,$A10,$AG$6:$AG$24) -> 0 | P10: 32 | Q10: =P10*1.15 -> 36.8 | R10: =Q10*$AE$4 -> 7080.688 | S10: =R10*O10 -> 0 | T10: =L10+K10 -> 296.64 | U10: =R10+S10+T10 -> 7377.328 | V10: 26900 | W10: 0.0813 | Y10: =2827+N10 -> 3003 | Z10: =W10+(Y10/V10) -> 0.19293569 | AA10: =V10*Z10 -> 5189.97 | AB10: =(V10)/1.1*10%-(R10+AA10+K10+S10+N10+X10)*10% -> 1195.9287 | AC10: =V10-(U10+AA10+AB10+N10) -> 12960.773 | AD10: =AC10/V10 -> 0.48181313

Sheet 헤이즈
A1: 헤몬 마진계산기 (2025-08-08 개정본)
A3: 1. 중국환률(AA)와 미국환률(AB)로 인해 비용차이가 많이 발생할 수 있으니 1달 평균으로 사용하기 바람. 2. 2개 구성으로 파는 제품은 물류비와 같은 부분은 X2를 해야하니 계산에 참고하기 바람 3. 사은품 증정되거나 물건이 각각 들어와서 합포장 하는 경우 물류비와 원가를 따로 계산하여 도매가에 포함시켜야 함.(물류비 계산 정확히 하기 위함) | AE3: 중국환률 (CNY) | AF3: 미국환률 (USD)
AE4: 192.41 | AF4: 1385
A5: 자동 | C5: 자동 | D5: 수동 | G5: 자동 | N5: 수동 | Q5: 자동 | V5: 수동 | Z5: 자동 | AE5: 관세율
A6: No | B6: 상품명 | C6: 단위기준 | D6: 넓이 | E6: 폭 | F6: 높이 | G6: 합산 | H6: 개별 박스 CBM | I6: 1CBM 적재가능수량 | J6: 1개당 중국 운임물류비(USD) | K6: 1개당 한국 운임 물류비(KRW) | L6: 1개당 물류비 (KRW) | M6: 원가대비 물류비 비율 | N6: 부자재값 (BOX) | O6: 관세율 | P6: 순수 중국원가 | Q6: 수수료포함 중국원가 | R6: 한국원가 | S6: 관세 | T6: 물류비 | U6: 도매가 | V6: 판매가 택배비 포함 | W6: 마켓수수료 | Y6: N배송 입출고비용 | Z6: 총 수수료(%) | AA6: 총 수수료 (원) | AB6: 부가세 | AC6: 판매마진 | AD6: 제품순이익% | AE6: 제품명(영어) | AF6: 제품명(한국) | AG6: %
A7: SCREWDRIVER | AE7: SCREWDRIVER | AG7: 0.08

Sheet 헬릭스케어
A1: 헤몬 마진계산기 (2025-08-08 개정본)
A3: 1. 중국환률(AA)와 미국환률(AB)로 인해 비용차이가 많이 발생할 수 있으니 1달 평균으로 사용하기 바람. 2. 2개 구성으로 파는 제품은 물류비와 같은 부분은 X2를 해야하니 계산에 참고하기 바람 3. 사은품 증정되거나 물건이 각각 들어와서 합포장 하는 경우 물류비와 원가를 따로 계산하여 도매가에 포함시켜야 함.(물류비 계산 정확히 하기 위함) | AE3: 중국환률 (CNY) | AF3: 미국환률 (USD)
AE4: 192.41 | AF4: 1385
A5: 자동 | C5: 자동 | D5: 수동 | G5: 자동 | N5: 수동 | Q5: 자동 | V5: 수동 | Z5: 자동 | AE5: 관세율
A6: No | B6: 상품명 | C6: 단위기준 | D6: 넓이 | E6: 폭 | F6: 높이 | G6: 합산 | H6: 개별 박스 CBM | I6: 1CBM 적재가능수량 | J6: 1개당 중국 운임물류비(USD) | K6: 1개당 한국 운임 물류비(KRW) | L6: 1개당 물류비 (KRW) | M6: 원가대비 물류비 비율 | N6: 부자재값 (BOX) | O6: 관세율 | P6: 순수 중국원가 | Q6: 수수료포함 중국원가 | R6: 한국원가 | S6: 관세 | T6: 물류비 | U6: 도매가 | V6: 판매가 택배비 포함 | W6: 마켓수수료 | Y6: N배송 입출고비용 | Z6: 총 수수료(%) | AA6: 총 수수료 (원) | AB6: 부가세 | AC6: 판매마진 | AD6: 제품순이익% | AE6: 제품명(영어) | AF6: 제품명(한국) | AG6: %
B7: 자세교정밴드 | C7: c m | D7: 22 | E7: 32 | F7: 2 | G7: =PRODUCT(D7*E7*F7) -> 1408 | H7: =G7/1000000 -> 0.001408 | I7: =1/H7 -> 710.22727 | J7: =80/I7 -> 0.11264 | K7: =27000/I7 -> 38.016 | L7: =(J7*$AF$4)+K7 -> 194.0224 | M7: =T7/R7 -> 0.041946369 | N7: 319 | O7: =SUMIF($AE$6:$AG$23,$A7,$AG$6:$AG$23) -> 0 | P7: 25 | Q7: =P7*1.15 -> 28.75 | R7: =Q7*$AE$4 -> 5531.7875 | S7: =R7*O7 -> 0 | T7: =L7+K7 -> 232.0384 | U7: =R7+S7+T7 -> 5763.8259 | V7: 19900 | W7: 0.0813 | Y7: =2827+N7 -> 3146 | Z7: =W7+(Y7/V7) -> 0.23939045 | AA7: =V7*Z7 -> 4763.87 | AB7: =(V7)/1.1*10%-(R7+AA7+K7+S7+N7+X7)*10% -> 743.82356 | AC7: =V7-(U7+AA7+AB7+N7) -> 8309.4805 | AD7: =AC7/V7 -> 0.41756184 | AE7: SCREWDRIVER | AG7: 0.08
B8: 타이트닝 | C8: c m | D8: 34 | E8: 24 | F8: 2 | G8: =PRODUCT(D8*E8*F8) -> 1632 | H8: =G8/1000000 -> 0.001632 | I8: =1/H8 -> 612.7451 | J8: =80/I8 -> 0.13056 | K8: =27000/I8 -> 44.064 | L8: =(J8*$AF$4)+K8 -> 224.8896 | M8: =T8/R8 -> 0.048619655 | N8: 352 | O8: =SUMIF($AE$6:$AG$23,$A8,$AG$6:$AG$23) -> 0 | P8: 25 | Q8: =P8*1.15 -> 28.75 | R8: =Q8*$AE$4 -> 5531.7875 | S8: =R8*O8 -> 0 | T8: =L8+K8 -> 268.9536 | U8: =R8+S8+T8 -> 5800.7411 | V8: 24900 | W8: 0.0813 | Y8: =2827+N8 -> 3179 | Z8: =W8+(Y8/V8) -> 0.20897068 | AA8: =V8*Z8 -> 5203.37 | AB8: =(V8)/1.1*10%-(R8+AA8+K8+S8+N8+X8)*10% -> 1150.5142 | AC8: =V8-(U8+AA8+AB8+N8) -> 12393.375 | AD8: =AC8/V8 -> 0.49772589
B9: 허리보호대 | C9: c m | D9: 15 | E9: 18 | F9: 2 | G9: =PRODUCT(D9*E9*F9) -> 540 | H9: =G9/1000000 -> 0.00054 | I9: =1/H9 -> 1851.8519 | J9: =80/I9 -> 0.0432 | K9: =27000/I9 -> 14.58 | L9: =(J9*$AF$4)+K9 -> 74.412 | M9: =T9/R9 -> 0.080436929 | N9: 176 | O9: =SUMIF($AE$6:$AG$27,$A9,$AG$6:$AG$27) -> 0 | P9: 5 | Q9: =P9*1.15 -> 5.75 | R9: =Q9*$AE$4 -> 1106.3575 | S9: =R9*O9 -> 0 | T9: =L9+K9 -> 88.992 | U9: =R9+S9+T9 -> 1195.3495 | V9: 17800 | W9: 0.0813 | Y9: =2827+N9 -> 3003 | Z9: =W9+(Y9/V9) -> 0.25000787 | AA9: =V9*Z9 -> 4450.14 | AB9: =(V9)/1.1*10%-(R9+AA9+K9+S9+N9+X9)*10% -> 1043.4741 | AC9: =V9-(U9+AA9+AB9+N9) -> 10935.036 | AD9: =AC9/V9 -> 0.61432789

Sheet 우다다
A1: 헤몬 마진계산기 (2025-08-08 개정본)
A3: 1. 중국환률(AA)와 미국환률(AB)로 인해 비용차이가 많이 발생할 수 있으니 1달 평균으로 사용하기 바람. 2. 2개 구성으로 파는 제품은 물류비와 같은 부분은 X2를 해야하니 계산에 참고하기 바람 3. 사은품 증정되거나 물건이 각각 들어와서 합포장 하는 경우 물류비와 원가를 따로 계산하여 도매가에 포함시켜야 함.(물류비 계산 정확히 하기 위함) | AE3: 중국환률 (CNY) | AF3: 미국환률 (USD)
AE4: 192.41 | AF4: 1385
A5: 자동 | C5: 자동 | D5: 수동 | G5: 자동 | N5: 수동 | Q5: 자동 | V5: 수동 | Z5: 자동 | AE5: 관세율
A6: No | B6: 상품명 | C6: 단위기준 | D6: 넓이 | E6: 폭 | F6: 높이 | G6: 합산 | H6: 개별 박스 CBM | I6: 1CBM 적재가능수량 | J6: 1개당 중국 운임물류비(USD) | K6: 1개당 한국 운임 물류비(KRW) | L6: 1개당 물류비 (KRW) | M6: 원가대비 물류비 비율 | N6: 부자재값 (BOX) | O6: 관세율 | P6: 순수 중국원가 | Q6: 수수료포함 중국원가 | R6: 한국원가 | S6: 관세 | T6: 물류비 | U6: 도매가 | V6: 판매가 택배비 포함 | W6: 마켓수수료 | Y6: N배송 입출고비용 | Z6: 총 수수료(%) | AA6: 총 수수료 (원) | AB6: 부가세 | AC6: 판매마진 | AD6: 제품순이익% | AE6: 제품명(영어) | AF6: 제품명(한국) | AG6: %
A7: 없음 | B7: 애견 바리깡 | C7: c m | D7: 20 | E7: 14 | F7: 5 | G7: =PRODUCT(D7*E7*F7) -> 1400 | H7: =G7/1000000 -> 0.0014 | I7: =1/H7 -> 714.28571 | J7: =80/I7 -> 0.112 | K7: =27000/I7 -> 37.8 | L7: =(J7*$AF$4)+K7 -> 192.92 | M7: =T7/R7 -> 0.065168808 | N7: 176 | O7: =SUMIF($AE$6:$AG$23,$A7,$AG$6:$AG$23) -> 0 | P7: 16 | Q7: =P7*1.15 -> 18.4 | R7: =Q7*$AE$4 -> 3540.344 | S7: =R7*O7 -> 0 | T7: =L7+K7 -> 230.72 | U7: =R7+S7+T7 -> 3771.064 | V7: 26900 | W7: 0.0813 | Y7: 2827 | Z7: =W7+(Y7/V7) -> 0.18639294 | AA7: =V7*Z7 -> 5013.97 | AB7: =(V7)/1.1*10%-(R7+AA7+K7+S7+N7+X7)*10% -> 1568.6431 | AC7: =V7-(U7+AA7+AB7+N7) -> 16370.323 | AD7: =AC7/V7 -> 0.60856219 | AE7: SCREWDRIVER | AG7: 0.08
B8: 바리깡 가위 세트 | C8: c m | D8: 23 | E8: 13 | F8: 8 | G8: =PRODUCT(D8*E8*F8) -> 2392 | H8: =G8/1000000 -> 0.002392 | I8: =1/H8 -> 418.0602 | J8: =80/I8 -> 0.19136 | K8: =27000/I8 -> 64.584 | L8: =(J8*$AF$4)+K8 -> 329.6176 | M8: =T8/R8 -> 0.059384301 | N8: 176 | O8: =SUMIF($AE$6:$AG$23,$A8,$AG$6:$AG$23) -> 0 | P8: 30 | Q8: =P8*1.15 -> 34.5 | R8: =Q8*$AE$4 -> 6638.145 | S8: =R8*O8 -> 0 | T8: =L8+K8 -> 394.2016 | U8: =R8+S8+T8 -> 7032.3466 | V8: 29800 | W8: 0.0813 | Y8: 2827 | Z8: =W8+(Y8/V8) -> 0.17616577 | AA8: =V8*Z8 -> 5249.74 | AB8: =(V8)/1.1*10%-(R8+AA8+K8+S8+N8+X8)*10% -> 1496.244 | AC8: =V8-(U8+AA8+AB8+N8) -> 15845.669 | AD8: =AC8/V8 -> 0.53173387
B9: 미니 클리퍼 | C9: c m | D9: 19 | E9: 7 | F9: 4 | G9: =PRODUCT(D9*E9*F9) -> 532 | H9: =G9/1000000 -> 0.000532 | I9: =1/H9 -> 1879.6992 | J9: =80/I9 -> 0.04256 | K9: =27000/I9 -> 14.364 | L9: =(J9*$AF$4)+K9 -> 73.3096 | M9: =T9/R9 -> 0.023307433 | N9: 176 | O9: =SUMIF($AE$6:$AG$23,$A9,$AG$6:$AG$23) -> 0 | P9: 17 | Q9: =P9*1.15 -> 19.55 | R9: =Q9*$AE$4 -> 3761.6155 | S9: =R9*O9 -> 0 | T9: =L9+K9 -> 87.6736 | U9: =R9+S9+T9 -> 3849.2891 | V9: 16800 | W9: 0.0813 | Y9: 2827 | Z9: =W9+(Y9/V9) -> 0.24957381 | AA9: =V9*Z9 -> 4192.84 | AB9: =(V9)/1.1*10%-(R9+AA9+K9+S9+N9+X9)*10% -> 712.79078 | AC9: =V9-(U9+AA9+AB9+N9) -> 7869.0801 | AD9: =AC9/V9 -> 0.46839763

Sheet 휴비
A1: 헤몬 마진계산기 (2025-08-08 개정본)
A3: 1. 중국환률(AA)와 미국환률(AB)로 인해 비용차이가 많이 발생할 수 있으니 1달 평균으로 사용하기 바람. 2. 2개 구성으로 파는 제품은 물류비와 같은 부분은 X2를 해야하니 계산에 참고하기 바람 3. 사은품 증정되거나 물건이 각각 들어와서 합포장 하는 경우 물류비와 원가를 따로 계산하여 도매가에 포함시켜야 함.(물류비 계산 정확히 하기 위함) | AE3: 중국환률 (CNY) | AF3: 미국환률 (USD)
AE4: 192.41 | AF4: 1385
A5: 자동 | C5: 자동 | D5: 수동 | G5: 자동 | N5: 수동 | Q5: 자동 | V5: 수동 | Z5: 자동 | AE5: 관세율
A6: No | B6: 상품명 | C6: 단위기준 | D6: 넓이 | E6: 폭 | F6: 높이 | G6: 합산 | H6: 개별 박스 CBM | I6: 1CBM 적재가능수량 | J6: 1개당 중국 운임물류비(USD) | K6: 1개당 한국 운임 물류비(KRW) | L6: 1개당 물류비 (KRW) | M6: 원가대비 물류비 비율 | N6: 부자재값 (BOX) | O6: 관세율 | P6: 순수 중국원가 | Q6: 수수료포함 중국원가 | R6: 한국원가 | S6: 관세 | T6: 물류비 | U6: 도매가 | V6: 판매가 택배비 포함 | W6: 마켓수수료 | Y6: N배송 입출고비용 | Z6: 총 수수료(%) | AA6: 총 수수료 (원) | AB6: 부가세 | AC6: 판매마진 | AD6: 제품순이익% | AE6: 제품명(영어) | AF6: 제품명(한국) | AG6: %
A7: 없음 | B7: 클린스톰 | C7: c m | D7: 23 | E7: 6 | F7: 6 | G7: =PRODUCT(D7*E7*F7) -> 828 | H7: =G7/1000000 -> 0.000828 | I7: =1/H7 -> 1207.7295 | J7: =80/I7 -> 0.06624 | K7: =27000/I7 -> 22.356 | L7: =(J7*$AF$4)+K7 -> 114.0984 | M7: =T7/R7 -> 0.026581169 | N7: 176 | O7: =SUMIF($AE$6:$AG$23,$A7,$AG$6:$AG$23) -> 0 | P7: 23.2 | Q7: =P7*1.15 -> 26.68 | R7: =Q7*$AE$4 -> 5133.4988 | S7: =R7*O7 -> 0 | T7: =L7+K7 -> 136.4544 | U7: =R7+S7+T7 -> 5269.9532 | V7: 19900 | W7: 0.0813 | Y7: 2827 | Z7: =W7+(Y7/V7) -> 0.2233603 | AA7: =V7*Z7 -> 4444.87 | AB7: =(V7)/1.1*10%-(R7+AA7+K7+S7+N7+X7)*10% -> 831.41843 | AC7: =V7-(U7+AA7+AB7+N7+X7) -> 9177.7584 | AD7: =AC8/V8 -> #DIV/0! | AE7: SCREWDRIVER | AG7: 0.08

Sheet 휴멜
A1: 헤몬 마진계산기 (2025-08-08 개정본)
A3: 1. 중국환률(AA)와 미국환률(AB)로 인해 비용차이가 많이 발생할 수 있으니 1달 평균으로 사용하기 바람. 2. 2개 구성으로 파는 제품은 물류비와 같은 부분은 X2를 해야하니 계산에 참고하기 바람 3. 사은품 증정되거나 물건이 각각 들어와서 합포장 하는 경우 물류비와 원가를 따로 계산하여 도매가에 포함시켜야 함.(물류비 계산 정확히 하기 위함) | AE3: 중국환률 (CNY) | AF3: 미국환률 (USD)
AE4: 192.41 | AF4: 1385
A5: 자동 | C5: 자동 | D5: 수동 | G5: 자동 | N5: 수동 | Q5: 자동 | V5: 수동 | Z5: 자동 | AE5: 관세율
A6: No | B6: 상품명 | C6: 단위기준 | D6: 넓이 | E6: 폭 | F6: 높이 | G6: 합산 | H6: 개별 박스 CBM | I6: 1CBM 적재가능수량 | J6: 1개당 중국 운임물류비(USD) | K6: 1개당 한국 운임 물류비(KRW) | L6: 1개당 물류비 (KRW) | M6: 원가대비 물류비 비율 | N6: 부자재값 (BOX) | O6: 관세율 | P6: 순수 중국원가 | Q6: 수수료포함 중국원가 | R6: 한국원가 | S6: 관세 | T6: 물류비 | U6: 도매가 | V6: 판매가 택배비 포함 | W6: 마켓수수료 | Y6: N배송 입출고비용 | Z6: 총 수수료(%) | AA6: 총 수수료 (원) | AB6: 부가세 | AC6: 판매마진 | AD6: 제품순이익% | AE6: 제품명(영어) | AF6: 제품명(한국) | AG6: %
B7: 쥬시믹서 | C7: c m | D7: c m | E7: 30 | F7: 9 | G7: 9 | H7: =PRODUCT(E7*F7*G7) -> 2430 | I7: =H7/1000000 -> 0.00243 | V7: 28900 | W7: 0.0663 | Z7: 3050 | AA7: =X7+(Z7/W7) -> 46003.017 | AB7: =W7*AA7 -> 3050 | AC7: =(W7)/1.1*10%-(R7+AB7+K7+S7+N7+Y7)*10% -> -304.99397 | AD7: =W7-(V7+Y7+AB7+AC7+N7) -> -31644.94 | AE7: =AD7/W7 -> -477299.24 | AF7: =AE7/X7 -> #DIV/0! | AG7: ELECTRIC WRENCH | AI7: 0.08

Sheet 한진 계산기
L1: 헤몬 마진계산기 (2025-08-08 개정본)
L3: 1. 중국환률(AA)와 미국환률(AB)로 인해 비용차이가 많이 발생할 수 있으니 1달 평균으로 사용하기 바람. 2. 2개 구성으로 파는 제품은 물류비와 같은 부분은 X2를 해야하니 계산에 참고하기 바람 3. 사은품 증정되거나 물건이 각각 들어와서 합포장 하는 경우 물류비와 원가를 따로 계산하여 도매가에 포함시켜야 함.(물류비 계산 정확히 하기 위함) | AE3: 중국환률 (CNY) | AF3: 미국환률 (USD)
AE4: 192.41 | AF4: 1385
A5: 자동 | C5: 자동 | D5: 수동 | G5: 자동 | N5: 수동 | Q5: 자동 | V5: 수동 | Z5: 자동 | AE5: 관세율
A6: No | B6: 상품명 | C6: 단위기준 | D6: 넓이 | E6: 폭 | F6: 높이 | G6: 합산 | H6: 개별 박스 CBM | I6: 1CBM 적재가능수량 | J6: 1개당 중국 운임물류비(USD) | K6: 1개당 한국 운임 물류비(KRW) | L6: 1개당 물류비 (KRW) | M6: 원가대비 물류비 비율 | N6: 부자재값 (BOX) | O6: 관세율 | P6: 순수 중국원가 | Q6: 수수료포함 중국원가 | R6: 한국원가 | S6: 관세 | T6: 물류비 | U6: 도매가 | V6: 판매가 택배비 포함 | W6: 마켓수수료 | X6: 한진택배비 | Y6: N배송 입출고비용 | Z6: 총 수수료(%) | AA6: 총 수수료 (원) | AB6: 부가세 | AC6: 판매마진 | AD6: 제품순이익% | AE6: 제품명(영어) | AF6: 제품명(한국) | AG6: %
B7: 파워스톰 | C7: c m | D7: 22 | E7: 7 | F7: 6 | G7: =PRODUCT(D7*E7*F7) -> 924 | H7: =G7/1000000 -> 0.000924 | I7: =1/H7 -> 1082.2511 | J7: =80/I7 -> 0.07392 | K7: =27000/I7 -> 24.948 | L7: =(J7*$AF$4)+K7 -> 127.3272 | M7: =T7/R7 -> 0.032770601 | O7: =SUMIF($AE$6:$AG$42,$A7,$AG$6:$AG$42) -> 0 | P7: 21 | Q7: =P7*1.15 -> 24.15 | R7: =Q7*$AE$4 -> 4646.7015 | S7: =R7*O7 -> 0 | T7: =L7+K7 -> 152.2752 | U7: =R7+S7+T7 -> 4798.9767 | V7: 22900 | W7: 0.0663 | X7: 1800 | Z7: =W7+(X7/V7) -> 0.14490262 | AA7: =V7*Z7 -> 3318.27 | AB7: =(V7)/1.1*10%-(AA7+K7+S7+N7+U7)*10% -> 1267.5987 | AC7: =V7-(U7+AA7+AB7+N7) -> 13515.155 | AD7: =AC7/V7 -> 0.59018142 | AE7: MOSQUITO REPELLENT WRISTBAND | AG7: 0.07
B8: 이지믹서 | C8: c m | D8: 22 | E8: 9 | F8: 9 | G8: =PRODUCT(D8*E8*F8) -> 1782 | H8: =G8/1000000 -> 0.001782 | I8: =1/H8 -> 561.16723 | J8: =80/I8 -> 0.14256 | K8: =27000/I8 -> 48.114 | L8: =(J8*$AF$4)+K8 -> 245.5596 | M8: =T8/R8 -> 0.042000295 | O8: =SUMIF(헤몬스토어!$AE$6:$AG$30,$A8,헤몬스토어!$AG$6:$AG$30) -> 0 | P8: 31.6 | Q8: =P8*1.15 -> 36.34 | R8: =Q8*헤몬스토어!$AE$4 -> 6992.1794 | S8: =R8*O8 -> 0 | T8: =L8+K8 -> 293.6736 | U8: =R8+S8+T8 -> 7285.853 | V8: 25900 | W8: 0.0663 | X8: 1800 | Z8: =W8+(X8/V8) -> 0.13579807 | AA8: =V8*Z8 -> 3517.17 | AB8: =(V8)/1.1*10%-(AA8+K8+S8+N8+U8)*10% -> 1269.4318 | AC8: =V8-(U8+AA8+AB8+N8) -> 13827.545 | AD8: =AC8/V8 -> 0.53388206 | AE8: FAN | AG8: 0.08
B9: 쿨방석 | C9: c m | D9: 38 | E9: 40 | F9: 2 | G9: =PRODUCT(D9*E9*F9) -> 3040 | H9: =G9/1000000 -> 0.00304 | I9: =1/H9 -> 328.94737 | J9: =80/I9 -> 0.2432 | K9: =27000/I9 -> 82.08 | L9: =(J9*$AF$4)+K9 -> 418.912 | M9: =T9/R9 -> 0.16172504 | O9: =SUMIF(헤몬스토어!$AE$6:$AG$30,$A9,헤몬스토어!$AG$6:$AG$30) -> 0 | P9: 14 | Q9: =P9*1.15 -> 16.1 | R9: =Q9*헤몬스토어!$AE$4 -> 3097.801 | S9: =R9*O9 -> 0 | T9: =L9+K9 -> 500.992 | U9: =R9+S9+T9 -> 3598.793 | V9: 8900 | W9: 0.0663 | X9: 1800 | Z9: =W9+(X9/V9) -> 0.26854719 | AA9: =V9*Z9 -> 2390.07 | AB9: =(V9)/1.1*10%-(AA9+K9+S9+N9+U9)*10% -> 201.99661 | AC9: =V9-(U9+AA9+AB9+N9) -> 2709.1404 | AD9: =AC9/V9 -> 0.3043978 | AE9: ELECTRIC WRENCH | AG9: 0.08
B10: 쿨방석 1+1 | P10: 28 | Q10: =P10*1.15 -> 32.2 | U10: =U9*2 -> 7197.586 | V10: 16900 | W10: 0.0663 | X10: 1800 | Z10: =W10+(X10/V10) -> 0.17280888 | AA10: =V10*Z10 -> 2920.47 | AB10: =(V10)/1.1*10%-(AA10+K10+S10+N10+U10)*10% -> 524.55804 | AC10: =V10-(U10+AA10+AB10+N10) -> 6257.386 | AD10: =AC10/V10 -> 0.37025952 | AE10: ELECTRIC WRENCH | AG10: 0.08
B11: 넥앤숄더 | C11: c m | D11: 16 | E11: 24 | F11: 17 | G11: =PRODUCT(D11*E11*F11) -> 6528 | H11: =G11/1000000 -> 0.006528 | I11: =1/H11 -> 153.18627 | J11: =80/I11 -> 0.52224 | K11: =27000/I11 -> 176.256 | L11: =(J11*$AF$4)+K11 -> 899.5584 | M11: =T11/R11 -> 0.08529764 | O11: =SUMIF(헤몬스토어!$AE$6:$AG$30,$A11,헤몬스토어!$AG$6:$AG$30) -> 0 | P11: 57 | Q11: =P11*1.15 -> 65.55 | R11: =Q11*헤몬스토어!$AE$4 -> 12612.475 | S11: =R11*O11 -> 0 | T11: =L11+K11 -> 1075.8144 | U11: =R11+S11+T11 -> 13688.29 | V11: 39000 | W11: 0.0663 | X11: 1800 | Z11: =W11+(X11/V11) -> 0.11245385 | AA11: =V11*Z11 -> 4385.7 | AB11: =(V11)/1.1*10%-(AA11+K11+S11+N11+U11)*10% -> 1720.43 | AC11: =V11-(U11+AA11+AB11+N11) -> 19205.58 | AD11: =AC11/V11 -> 0.49245077 | AE11: ELECTRIC WRENCH | AG11: 0.08
B12: 건전지 모기채 | C12: c m | D12: 53 | E12: 22 | F12: 4 | G12: =PRODUCT(D12*E12*F12) -> 4664 | H12: =G12/1000000 -> 0.004664 | I12: =1/H12 -> 214.40823 | J12: =80/I12 -> 0.37312 | K12: =27000/I12 -> 125.928 | L12: =(J12*$AF$4)+K12 -> 642.6992 | M12: =T12/R12 -> 0.45706364 | O12: =SUMIF(헤몬스토어!$AE$6:$AG$30,$A12,헤몬스토어!$AG$6:$AG$30) -> 0 | P12: 7.6 | Q12: =P12*1.15 -> 8.74 | R12: =Q12*헤몬스토어!$AE$4 -> 1681.6634 | S12: =R12*O12 -> 0 | T12: =L12+K12 -> 768.6272 | U12: =R12+S12+T12 -> 2450.2906 | V12: 8900 | W12: 0.0663 | X12: 1800 | Z12: =W12+(X12/V12) -> 0.26854719 | AA12: =V12*Z12 -> 2390.07 | AB12: =(V12)/1.1*10%-(AA12+K12+S12+N12+U12)*10% -> 312.46205 | AC12: =V12-(U12+AA12+AB12+N12) -> 3747.1774 | AD12: =AC12/V12 -> 0.42103116 | AE12: CHARGER ACCESSORIES | AG12: 0.021
B13: 건전지 모기채 1+1 | C13: c m | O13: =SUMIF(헤몬스토어!$AE$6:$AG$30,$A13,헤몬스토어!$AG$6:$AG$30) -> 0 | P13: 15.2 | Q13: =P13*1.15 -> 17.48 | U13: =U12*2 -> 4900.5812 | V13: 16800 | W13: 0.0663 | X13: 1800 | Z13: =W13+(X13/V13) -> 0.17344286 | AA13: =V13*Z13 -> 2913.84 | AB13: =(V13)/1.1*10%-(AA13+K13+S13+N13+U13)*10% -> 745.83061 | AC13: =V13-(U13+AA13+AB13+N13) -> 8239.7482 | AD13: =AC13/V13 -> 0.4904612
B14: 국민포충기 퍼플 1개 | C14: c m | D14: 11 | E14: 32 | F14: 11 | G14: =PRODUCT(D14*E14*F14) -> 3872 | H14: =G14/1000000 -> 0.003872 | I14: =1/H14 -> 258.26446 | J14: =80/I14 -> 0.30976 | K14: =27000/I14 -> 104.544 | L14: =(J14*$AF$4)+K14 -> 533.5616 | M14: =T14/R14 -> 0.22183176 | O14: =SUMIF(헤몬스토어!$AE$6:$AG$30,$A14,헤몬스토어!$AG$6:$AG$30) -> 0 | P14: 13 | Q14: =P14*1.15 -> 14.95 | R14: =Q14*헤몬스토어!$AE$4 -> 2876.5295 | S14: =R14*O14 -> 0 | T14: =L14+K14 -> 638.1056 | U14: =R14+S14+T14 -> 3514.6351 | V14: 14900 | W14: 0.0663 | X14: 1800 | Z14: =W14+(X14/V14) -> 0.18710537 | AA14: =V14*Z14 -> 2787.87 | AB14: =(V14)/1.1*10%-(AA14+K14+S14+N14+U14)*10% -> 713.84054 | AC14: =V14-(U14+AA14+AB14+N14) -> 7883.6544 | AD14: =AC14/V14 -> 0.52910432
B15: 국민포충기 퍼플 1+1 | T15: =T14*2-S14 -> 1276.2112 | U15: =U14*2-T14 -> 6391.1646 | V15: 27700 | W15: 0.0663 | Z15: =W15+(X15/V15) -> 0.0663 | AA15: =V15*Z15 -> 1836.51 | AB15: =(V15)/1.1*10%-(AA15+K15+S15+N15+U15)*10% -> 1695.4144 | AC15: =V15-(U15+AA15+AB15+N15) -> 17776.911 | AD15: =AC15/V15 -> 0.64176574
